Workbook

Sheet Read me
A1: Predictions for 2026-09-27
A3: Runners | B3: 221
A4: Races | B4: 23
A5: Meetings | B5: 3
A7: The model | B7: pair500
A8: Features | B8: 968
A9: Trained through | B9: 2026-09-22
A10: Boosting rounds | B10: 11000
A11: Target | B11: logit_norm_prob
A12: Feature code hash | B12: f879b10c8369467a
A14: How to read it
A15: Predicted BSP | B15: The model's forecast of the Betfair Starting Price, from pre-race information only. The prices in each race make a book of exactly 100%.
A16: Win probability | B16: 1 / predicted BSP: the model's chance for the horse, normalised within the race.
A17: Model rank | B17: 1 = the model's shortest price in the race (highlighted green).
A18: Card odds (HRB) | B18: The odds printed on the horseracebase card when it was fetched: a bookmaker forecast, not the Betfair morning price the early-price rule was tested against.
A19: Card odds vs model | B19: Card odds / predicted BSP - 1. Positive: the card is longer than the model.
A21: The early-price rule
A22: Margin (log) | B22: 0.2
A23: Rule: back at Betfair ≥ | B23: Predicted BSP × e^margin: at 0.2, a Betfair price at least 1.22 times the model's (the model at least 22% shorter). The rule was fixed before it was first tested (reports/clv_betfair_2026q1.md): back at Betfair's morning volume-weighted price, where at least £100 has been matched in the morning, and close the position at BSP (lay at BSP to level the book). It is a trade on the price, not a bet held to the result. The margin (blue) is the one input: change it to see the prices at another threshold.
A25: Note | B25: The best model measured: the pair at leaves of 500 (the extra-trees and Huber fits of the 968 at the slow recipe, train-bfsp runs 48 and 49, averaged), priced here by predict-now run 23 on the card fetched at 11:37 UTC (221 runners in 23 races; non-runners declared by then are out, and each race's book is 100% of those left). Out of sample (27 Sep 2025 to 31 Mar 2026) it prices the window at 0.3995 mean log error, the best yet (the 615 serving today: 0.4359). There the early-price rule returned +10.44% per trade and the top pick, backed at the morning price and traded out at BSP, +1.63%. Both are trades closed at BSP: backing the top pick at BSP and holding it to the result has not been shown profitable. It is not the served model: the 06:00 email priced today with the 615. Both members pass verify and this dry run was clean.

Sheet Top picks
A1: Time | B1: Course | C1: Race | D1: Runners | E1: Top pick | F1: Jockey | G1: Trainer | H1: Predicted BSP | I1: Win probability | J1: Second choice | K1: Second's BSP | L1: Second's probability | M1: Probability gap | N1: Card odds (HRB) | O1: Rule: back at Betfair ≥
A2: 1:19 | B2: Ffos Las | C2: Alex And Salvo Welcome You To The Bridge Handicap | D2: 11 | E2: Sub Thirteen | F2: Hutchinson, Callum | G2: Scott, J | H2: 3.0244583 | I2: 0.33063772 | J2: Macarone | K2: 4.3312252 | L2: 0.23088155 | M2: =IF(AND(ISNUMBER(I2),ISNUMBER(L2)),I2-L2,"") -> 0.099756161 | N2: 3.25 | O2: =IF(AND(ISNUMBER(H2),H2>0),H2*EXP('Read me'!$B$22),"") -> 3.6940818
A3: 1:25 | B3: Curragh | C3: Army Equitation Centenary Irish European Breeders Fund Maiden | D3: 13 | E3: Raging Bull (IRE) | F3: Moore, Ryan | G3: OBrien, A P | H3: 1.7510775 | I3: 0.57107694 | J3: Yellow Sky (IRE) | K3: 7.4272181 | L3: 0.13463991 | M3: =IF(AND(ISNUMBER(I3),ISNUMBER(L3)),I3-L3,"") -> 0.43643702 | N3: 1.7272727 | O3: =IF(AND(ISNUMBER(H3),H3>0),H3*EXP('Read me'!$B$22),"") -> 2.1387709
A4: 1:37 | B4: Epsom | C4: Betfred Turbo Boost Nursery | D4: 8 | E4: Regal Tiger | F4: Murphy, Oisin | G4: Palmer, Hugo | H4: 4.5975127 | I4: 0.21750892 | J4: Give Hand (IRE) | K4: 5.8202093 | L4: 0.17181513 | M4: =IF(AND(ISNUMBER(I4),ISNUMBER(L4)),I4-L4,"") -> 0.045693789 | N4: 5.5 | O4: =IF(AND(ISNUMBER(H4),H4>0),H4*EXP('Read me'!$B$22),"") -> 5.6154147
A5: 1:49 | B5: Ffos Las | C5: Bridge, The Home Of The Carvery Nursery | D5: 8 | E5: Rhodes Runner (IRE) | F5: Clutterbuck, Rhys | G5: Beckett, R M | H5: 4.9613223 | I5: 0.20155917 | J5: Perigord Noir (IRE) | K5: 5.5643037 | L5: 0.17971701 | M5: =IF(AND(ISNUMBER(I5),ISNUMBER(L5)),I5-L5,"") -> 0.021842164 | N5: 3.75 | O5: =IF(AND(ISNUMBER(H5),H5>0),H5*EXP('Read me'!$B$22),"") -> 6.0597727
A6: 2:00 | B6: Curragh | C6: Izuzu Ireland Irish European Breeders Fund Maiden | D6: 9 | E6: Kingdom Of Camelot (FR) | F6: Moore, Ryan | G6: OBrien, A P | H6: 2.7097568 | I6: 0.36903681 | J6: Cluster | K6: 4.0075054 | L6: 0.24953179 | M6: =IF(AND(ISNUMBER(I6),ISNUMBER(L6)),I6-L6,"") -> 0.11950502 | N6: 1.9090909 | O6: =IF(AND(ISNUMBER(H6),H6>0),H6*EXP('Read me'!$B$22),"") -> 3.3097044
A7: 2:12 | B7: Epsom | C7: Betfred Derby Wild Card EBF Conditions Stakes (GBB/GBBPlus Race) | D7: 5 | E7: Rose Moon (GER) | F7: Ryan, Rossa | G7: Beckett, R M | H7: 3.3125625 | I7: 0.3018811 | J7: Al Wathba (FR) | K7: 3.524514 | L7: 0.28372706 | M7: =IF(AND(ISNUMBER(I7),ISNUMBER(L7)),I7-L7,"") -> 0.018154037 | N7: 2.375 | O7: =IF(AND(ISNUMBER(H7),H7>0),H7*EXP('Read me'!$B$22),"") -> 4.0459729
A8: 2:24 | B8: Ffos Las | C8: Bridge, Family Run And Proud Handicap | D8: 4 | E8: Call Time (IRE) | F8: Wonnacott, Millie | G8: Moore, J S | H8: 1.8816813 | I8: 0.53143963 | J8: Some Nightmare (IRE) | K8: 3.7883785 | L8: 0.26396518 | M8: =IF(AND(ISNUMBER(I8),ISNUMBER(L8)),I8-L8,"") -> 0.26747446 | N8: 1.6153846 | O8: =IF(AND(ISNUMBER(H8),H8>0),H8*EXP('Read me'!$B$22),"") -> 2.2982907
A9: 2:35 | B9: Curragh | C9: Qatar Racing And Equestrian Club Renaissance Stakes (Group 3) | D9: 8 | E9: Soul Love | F9: Jamin, Pierre-Louis | G9: Burke, K R | H9: 3.6569722 | I9: 0.27345026 | J9: Power Blue (IRE) | K9: 4.4795634 | L9: 0.22323604 | M9: =IF(AND(ISNUMBER(I9),ISNUMBER(L9)),I9-L9,"") -> 0.050214218 | N9: 3.75 | O9: =IF(AND(ISNUMBER(H9),H9>0),H9*EXP('Read me'!$B$22),"") -> 4.4666359
A10: 2:47 | B10: Epsom | C10: Hunt Family Fund Novice Stakes (Sponsored By Betfred) (GBB Race) | D10: 6 | E10: Maestro Del Mar (FR) | F10: Loughnane, Billy | G10: Mohammed, Ismail | H10: 3.4940533 | I10: 0.28620056 | J10: Rowlf | K10: 3.9386 | L10: 0.25389732 | M10: =IF(AND(ISNUMBER(I10),ISNUMBER(L10)),I10-L10,"") -> 0.032303238 | N10: 4 | O10: =IF(AND(ISNUMBER(H10),H10>0),H10*EXP('Read me'!$B$22),"") -> 4.2676463
A11: 2:59 | B11: Ffos Las | C11: Happy Birthday Alex, From The Bridge Handicap | D11: 5 | E11: Campeona | F11: Gilligan, Jack | G11: Prescott, Sir Mark | H11: 2.63875 | I11: 0.37896732 | J11: Carthusian (IRE) | K11: 3.7148957 | L11: 0.26918656 | M11: =IF(AND(ISNUMBER(I11),ISNUMBER(L11)),I11-L11,"") -> 0.10978076 | N11: 2.625 | O11: =IF(AND(ISNUMBER(H11),H11>0),H11*EXP('Read me'!$B$22),"") -> 3.2229765
A12: 3:10 | B12: Curragh | C12: Celebrating County Kildare And Lexington Twinning Maiden | D12: 12 | E12: Valentino Eclipse (IRE) | F12: Heffernan, J A | G12: Stack, J A | H12: 2.4347683 | I12: 0.4107167 | J12: A Good Yarn (IRE) | K12: 3.5987295 | L12: 0.27787584 | M12: =IF(AND(ISNUMBER(I12),ISNUMBER(L12)),I12-L12,"") -> 0.13284086 | N12: 1.7272727 | O12: =IF(AND(ISNUMBER(H12),H12>0),H12*EXP('Read me'!$B$22),"") -> 2.9738327
A13: 3:22 | B13: Epsom | C13: Betfred Nifty 50 Jump Jockeys Derby Handicap (Professional Jump Jockeys) (GBBPlus Race) | D13: 13 | E13: Seeking Charles (FR) | F13: Davies, James | G13: Usher, M D I | H13: 4.8890414 | I13: 0.20453907 | J13: Nibras Gold (IRE) | K13: 6.9023838 | L13: 0.14487748 | M13: =IF(AND(ISNUMBER(I13),ISNUMBER(L13)),I13-L13,"") -> 0.059661588 | N13: 4.5 | O13: =IF(AND(ISNUMBER(H13),H13>0),H13*EXP('Read me'!$B$22),"") -> 5.9714887
... A24: 5:30 | B24: Curragh | C24: Kwiff Supercharged Betting (Q.R.) Handicap | D24: 18 | E24: Chipsrdown (IRE) | F24: Ryan, Mr A P | G24: Slattery, Andrew | H24: 4.4584631 | I24: 0.22429254 | J24: Dark Summit | K24: 6.2954259 | L24: 0.15884549 | M24: =IF(AND(ISNUMBER(I24),ISNUMBER(L24)),I24-L24,"") -> 0.06544705 | N24: 4.3333333 | O24: =IF(AND(ISNUMBER(H24),H24>0),H24*EXP('Read me'!$B$22),"") -> 5.4455791

Sheet All runners
A1: Time | B1: Course | C1: Race | D1: Class | E1: Furlongs | F1: Going | G1: Runners | H1: Horse | I1: Jockey | J1: Trainer | K1: Draw | L1: OR | M1: Age | N1: Days since run | O1: Model rank | P1: Predicted BSP | Q1: Win probability | R1: Card odds (HRB) | S1: Card odds vs model | T1: Rule: back at Betfair ≥
A2: 1:19 | B2: Ffos Las | C2: Alex And Salvo Welcome You To The Bridge Handicap | D2: Class 6 | E2: 6 | F2: Good To Soft | G2: 11 | H2: Sub Thirteen | I2: Hutchinson, Callum | J2: Scott, J | K2: 9 | L2: 53 | M2: 5 | N2: 14 | O2: 1 | P2: 3.0244583 | Q2: 0.33063772 | R2: 3.25 | S2: =IF(AND(ISNUMBER(R2),R2>1,P2>0),R2/P2-1,"") -> 0.074572576 | T2: =IF(AND(ISNUMBER(P2),P2>0),P2*EXP('Read me'!$B$22),"") -> 3.6940818
A3: 1:19 | B3: Ffos Las | C3: Alex And Salvo Welcome You To The Bridge Handicap | D3: Class 6 | E3: 6 | F3: Good To Soft | G3: 11 | H3: Macarone | I3: Ffrench Davis, Ben | J3: Harris, Miss G | K3: 8 | L3: 52 | M3: 5 | N3: 15 | O3: 2 | P3: 4.3312252 | Q3: 0.23088155 | R3: 4 | S3: =IF(AND(ISNUMBER(R3),R3>1,P3>0),R3/P3-1,"") -> -0.07647378 | T3: =IF(AND(ISNUMBER(P3),P3>0),P3*EXP('Read me'!$B$22),"") -> 5.2901704
A4: 1:19 | B4: Ffos Las | C4: Alex And Salvo Welcome You To The Bridge Handicap | D4: Class 6 | E4: 6 | F4: Good To Soft | G4: 11 | H4: Blue Point Express (IRE) | I4: Marsh, Finley | J4: Wintle, A | K4: 7 | L4: 45 | M4: 4 | N4: 27 | O4: 3 | P4: 7.187645 | Q4: 0.13912763 | R4: 6 | S4: =IF(AND(ISNUMBER(R4),R4>1,P4>0),R4/P4-1,"") -> -0.16523424 | T4: =IF(AND(ISNUMBER(P4),P4>0),P4*EXP('Read me'!$B$22),"") -> 8.7790095
A5: 1:19 | B5: Ffos Las | C5: Alex And Salvo Welcome You To The Bridge Handicap | D5: Class 6 | E5: 6 | F5: Good To Soft | G5: 11 | H5: Up The Anti (IRE) | I5: Coppins, Myla | J5: Carroll, A W | K5: 6 | L5: 53 | M5: 4 | N5: 25 | O5: 4 | P5: 10.055959 | Q5: 0.099443529 | R5: 8 | S5: =IF(AND(ISNUMBER(R5),R5>1,P5>0),R5/P5-1,"") -> -0.20445177 | T5: =IF(AND(ISNUMBER(P5),P5>0),P5*EXP('Read me'!$B$22),"") -> 12.282375
A6: 1:19 | B6: Ffos Las | C6: Alex And Salvo Welcome You To The Bridge Handicap | D6: Class 6 | E6: 6 | F6: Good To Soft | G6: 11 | H6: Music And Song (IRE) | I6: Probert, David | J6: Flood, D | K6: 5 | L6: 45 | M6: 3 | N6: 5 | O6: 5 | P6: 15.63988 | Q6: 0.063939107 | R6: 10 | S6: =IF(AND(ISNUMBER(R6),R6>1,P6>0),R6/P6-1,"") -> -0.36060893 | T6: =IF(AND(ISNUMBER(P6),P6>0),P6*EXP('Read me'!$B$22),"") -> 19.102593
A7: 1:19 | B7: Ffos Las | C7: Alex And Salvo Welcome You To The Bridge Handicap | D7: Class 6 | E7: 6 | F7: Good To Soft | G7: 11 | H7: The Bear Of Saints (FR) | I7: Carson, William | J7: Oshea, J G M | K7: 4 | L7: 54 | M7: 4 | N7: 34 | O7: 6 | P7: 16.543067 | Q7: 0.060448284 | R7: 15 | S7: =IF(AND(ISNUMBER(R7),R7>1,P7>0),R7/P7-1,"") -> -0.093275736 | T7: =IF(AND(ISNUMBER(P7),P7>0),P7*EXP('Read me'!$B$22),"") -> 20.205747
A8: 1:19 | B8: Ffos Las | C8: Alex And Salvo Welcome You To The Bridge Handicap | D8: Class 6 | E8: 6 | F8: Good To Soft | G8: 11 | H8: Pacific Prince | I8: Coughlan, Laura | J8: Bennett, J A | K8: 11 | L8: 45 | M8: 5 | N8: 20 | O8: 7 | P8: 44.329774 | Q8: 0.022558202 | R8: 41 | S8: =IF(AND(ISNUMBER(R8),R8>1,P8>0),R8/P8-1,"") -> -0.075113712 | T8: =IF(AND(ISNUMBER(P8),P8>0),P8*EXP('Read me'!$B$22),"") -> 54.144508
A9: 1:19 | B9: Ffos Las | C9: Alex And Salvo Welcome You To The Bridge Handicap | D9: Class 6 | E9: 6 | F9: Good To Soft | G9: 11 | H9: Savvi Row | I9: Heard, Tyler | J9: Millman, B R | K9: 12 | L9: 45 | M9: 3 | N9: 15 | O9: 8 | P9: 59.529493 | Q9: 0.016798396 | R9: 34 | S9: =IF(AND(ISNUMBER(R9),R9>1,P9>0),R9/P9-1,"") -> -0.42885454 | T9: =IF(AND(ISNUMBER(P9),P9>0),P9*EXP('Read me'!$B$22),"") -> 72.709487
A10: 1:19 | B10: Ffos Las | C10: Alex And Salvo Welcome You To The Bridge Handicap | D10: Class 6 | E10: 6 | F10: Good To Soft | G10: 11 | H10: Shush A Minute | I10: Bradley, Paddy | J10: Ryan, J | K10: 1 | L10: 50 | M10: 3 | N10: 306 | O10: 9 | P10: 62.476468 | Q10: 0.016006026 | R10: 7 | S10: =IF(AND(ISNUMBER(R10),R10>1,P10>0),R10/P10-1,"") -> -0.88795782 | T10: =IF(AND(ISNUMBER(P10),P10>0),P10*EXP('Read me'!$B$22),"") -> 76.308931
A11: 1:19 | B11: Ffos Las | C11: Alex And Salvo Welcome You To The Bridge Handicap | D11: Class 6 | E11: 6 | F11: Good To Soft | G11: 11 | H11: Lochaber | I11: ONeill, K T | J11: Dixon, Scott | K11: 10 | L11: 45 | M11: 5 | N11: 14 | O11: 10 | P11: 63.912016 | Q11: 0.01564651 | R11: 51 | S11: =IF(AND(ISNUMBER(R11),R11>1,P11>0),R11/P11-1,"") -> -0.20202799 | T11: =IF(AND(ISNUMBER(P11),P11>0),P11*EXP('Read me'!$B$22),"") -> 78.062313
A12: 1:19 | B12: Ffos Las | C12: Alex And Salvo Welcome You To The Bridge Handicap | D12: Class 6 | E12: 6 | F12: Good To Soft | G12: 11 | H12: Miss Gold | I12: Sayette, B D L | J12: Flood, D | K12: 2 | L12: 45 | M12: 3 | N12: 46 | O12: 11 | P12: 221.57978 | Q12: 0.0045130472 | R12: 81 | S12: =IF(AND(ISNUMBER(R12),R12>1,P12>0),R12/P12-1,"") -> -0.63444318 | T12: =IF(AND(ISNUMBER(P12),P12>0),P12*EXP('Read me'!$B$22),"") -> 270.63815
A13: 1:25 | B13: Curragh | C13: Army Equitation Centenary Irish European Breeders Fund Maiden | E13: 7 | F13: Heavy | G13: 13 | H13: Raging Bull (IRE) | I13: Moore, Ryan | J13: OBrien, A P | K13: 6 | L13: 0 | M13: 2 | N13: 49 | O13: 1 | P13: 1.7510775 | Q13: 0.57107694 | R13: 1.7272727 | S13: =IF(AND(ISNUMBER(R13),R13>1,P13>0),R13/P13-1,"") -> -0.013594385 | T13: =IF(AND(ISNUMBER(P13),P13>0),P13*EXP('Read me'!$B$22),"") -> 2.1387709
A14: 1:25 | B14: Curragh | C14: Army Equitation Centenary Irish European Breeders Fund Maiden | E14: 7 | F14: Heavy | G14: 13 | H14: Yellow Sky (IRE) | I14: Coen, Ben M | J14: Murtagh, J P | K14: 12 | L14: 0 | M14: 2 | N14: 62 | O14: 2 | P14: 7.4272181 | Q14: 0.13463991 | R14: 12 | S14: =IF(AND(ISNUMBER(R14),R14>1,P14>0),R14/P14-1,"") -> 0.61567896 | T14: =IF(AND(ISNUMBER(P14),P14>0),P14*EXP('Read me'!$B$22),"") -> 9.0716247
A15: 1:25 | B15: Curragh | C15: Army Equitation Centenary Irish European Breeders Fund Maiden | E15: 7 | F15: Heavy | G15: 13 | H15: Maximilien Luce (IRE) | I15: Cleary, Jack | J15: OBrien, A P | K15: 1 | L15: 0 | M15: 2 | O15: 3 | P15: 13.08711 | Q15: 0.076411066 | R15: 7 | S15: =IF(AND(ISNUMBER(R15),R15>1,P15>0),R15/P15-1,"") -> -0.46512253 | T15: =IF(AND(ISNUMBER(P15),P15>0),P15*EXP('Read me'!$B$22),"") -> 15.984632
A16: 1:25 | B16: Curragh | C16: Army Equitation Centenary Irish European Breeders Fund Maiden | E16: 7 | F16: Heavy | G16: 13 | H16: Golden Idol (IRE) | I16: Lee, W J | J16: Bromhead, Henry De | K16: 9 | L16: 0 | M16: 2 | O16: 4 | P16: 13.310346 | Q16: 0.075129527 | R16: 5.5 | S16: =IF(AND(ISNUMBER(R16),R16>1,P16>0),R16/P16-1,"") -> -0.5867876 | T16: =IF(AND(ISNUMBER(P16),P16>0),P16*EXP('Read me'!$B$22),"") -> 16.257293
A17: 1:25 | B17: Curragh | C17: Army Equitation Centenary Irish European Breeders Fund Maiden | E17: 7 | F17: Heavy | G17: 13 | H17: Normanton (IRE) | I17: McAteer, L T | J17: Marnane, David | K17: 16 | L17: 0 | M17: 2 | O17: 5 | P17: 26.949884 | Q17: 0.037105911 | R17: 15 | S17: =IF(AND(ISNUMBER(R17),R17>1,P17>0),R17/P17-1,"") -> -0.44341133 | T17: =IF(AND(ISNUMBER(P17),P17>0),P17*EXP('Read me'!$B$22),"") -> 32.916663
A18: 1:25 | B18: Curragh | C18: Army Equitation Centenary Irish European Breeders Fund Maiden | E18: 7 | F18: Heavy | G18: 13 | H18: Overhead Drive (IRE) | I18: Heffernan, J A | J18: Murphy, John Joseph | K18: 14 | L18: 0 | M18: 2 | O18: 6 | P18: 29.584989 | Q18: 0.033800925 | R18: 29 | S18: =IF(AND(ISNUMBER(R18),R18>1,P18>0),R18/P18-1,"") -> -0.019773178 | T18: =IF(AND(ISNUMBER(P18),P18>0),P18*EXP('Read me'!$B$22),"") -> 36.135187
A19: 1:25 | B19: Curragh | C19: Army Equitation Centenary Irish European Breeders Fund Maiden | E19: 7 | F19: Heavy | G19: 13 | H19: Tsali (IRE) | I19: Hayes, C D | J19: Coleman, Kevin | K19: 8 | L19: 0 | M19: 2 | O19: 7 | P19: 36.193559 | Q19: 0.027629225 | R19: 34 | S19: =IF(AND(ISNUMBER(R19),R19>1,P19>0),R19/P19-1,"") -> -0.060606334 | T19: =IF(AND(ISNUMBER(P19),P19>0),P19*EXP('Read me'!$B$22),"") -> 44.206913
A20: 1:25 | B20: Curragh | C20: Army Equitation Centenary Irish European Breeders Fund Maiden | E20: 7 | F20: Heavy | G20: 13 | H20: Ah Sure Look (IRE) | I20: Sheridan, J M | J20: Hassett, Martin | K20: 10 | L20: 0 | M20: 2 | O20: 8 | P20: 87.460693 | Q20: 0.011433708 | R20: 34 | S20: =IF(AND(ISNUMBER(R20),R20>1,P20>0),R20/P20-1,"") -> -0.61125394 | T20: =IF(AND(ISNUMBER(P20),P20>0),P20*EXP('Read me'!$B$22),"") -> 106.82473
A21: 1:25 | B21: Curragh | C21: Army Equitation Centenary Irish European Breeders Fund Maiden | E21: 7 | F21: Heavy | G21: 13 | H21: Johntom | I21: Carroll, G F | J21: Cromwell, Gavin Patrick | K21: 5 | L21: 0 | M21: 2 | N21: 10 | O21: 9 | P21: 95.343068 | Q21: 0.010488439 | R21: 41 | S21: =IF(AND(ISNUMBER(R21),R21>1,P21>0),R21/P21-1,"") -> -0.56997398 | T21: =IF(AND(ISNUMBER(P21),P21>0),P21*EXP('Read me'!$B$22),"") -> 116.45229
A22: 1:25 | B22: Curragh | C22: Army Equitation Centenary Irish European Breeders Fund Maiden | E22: 7 | F22: Heavy | G22: 13 | H22: Activity (IRE) | I22: Crosse, Nathan | J22: Harrington, Mrs John | K22: 3 | L22: 0 | M22: 2 | N22: 52 | O22: 10 | P22: 112.02611 | Q22: 0.0089264903 | R22: 29 | S22: =IF(AND(ISNUMBER(R22),R22>1,P22>0),R22/P22-1,"") -> -0.74113178 | T22: =IF(AND(ISNUMBER(P22),P22>0),P22*EXP('Read me'!$B$22),"") -> 136.829
A23: 1:25 | B23: Curragh | C23: Army Equitation Centenary Irish European Breeders Fund Maiden | E23: 7 | F23: Heavy | G23: 13 | H23: Soho Dragon (IRE) | I23: OConnor, Donagh | J23: Murphy, John Joseph | K23: 7 | L23: 0 | M23: 2 | O23: 11 | P23: 158.85539 | Q23: 0.0062950336 | R23: 34 | S23: =IF(AND(ISNUMBER(R23),R23>1,P23>0),R23/P23-1,"") -> -0.78596886 | T23: =IF(AND(ISNUMBER(P23),P23>0),P23*EXP('Read me'!$B$22),"") -> 194.02641
A24: 1:25 | B24: Curragh | C24: Army Equitation Centenary Irish European Breeders Fund Maiden | E24: 7 | F24: Heavy | G24: 13 | H24: One Flash (IRE) | I24: Joyce, Wesley | J24: Sexton, Adrian | K24: 11 | L24: 0 | M24: 2 | O24: 12 | P24: 282.56065 | Q24: 0.0035390632 | R24: 41 | S24: =IF(AND(ISNUMBER(R24),R24>1,P24>0),R24/P24-1,"") -> -0.85489841 | T24: =IF(AND(ISNUMBER(P24),P24>0),P24*EXP('Read me'!$B$22),"") -> 345.12036
A25: 1:25 | B25: Curragh | C25: Army Equitation Centenary Irish European Breeders Fund Maiden | E25: 7 | F25: Heavy | G25: 13 | H25: Silk Twist (IRE) | I25: McCullagh, Scott | J25: Mullins, Thomas | K25: 2 | L25: 0 | M25: 2 | N25: 10 | O25: 13 | P25: 283.78757 | Q25: 0.0035237626 | R25: 41 | S25: =IF(AND(ISNUMBER(R25),R25>1,P25>0),R25/P25-1,"") -> -0.85552574 | T25: =IF(AND(ISNUMBER(P25),P25>0),P25*EXP('Read me'!$B$22),"") -> 346.61892
A26: 1:37 | B26: Epsom | C26: Betfred Turbo Boost Nursery | D26: Class 4 | E26: 7 | F26: Good | G26: 8 | H26: Regal Tiger | I26: Murphy, Oisin | J26: Palmer, Hugo | K26: 7 | L26: 73 | M26: 2 | N26: 69 | O26: 1 | P26: 4.5975127 | Q26: 0.21750892 | R26: 5.5 | S26: =IF(AND(ISNUMBER(R26),R26>1,P26>0),R26/P26-1,"") -> 0.19629903 | T26: =IF(AND(ISNUMBER(P26),P26>0),P26*EXP('Read me'!$B$22),"") -> 5.6154147
A27: 1:37 | B27: Epsom | C27: Betfred Turbo Boost Nursery | D27: Class 4 | E27: 7 | F27: Good | G27: 8 | H27: Give Hand (IRE) | I27: Edmunds, Lewis | J27: Charlton, Roger/Harry | K27: 3 | L27: 76 | M27: 2 | N27: 17 | O27: 2 | P27: 5.8202093 | Q27: 0.17181513 | R27: 3.5 | S27: =IF(AND(ISNUMBER(R27),R27>1,P27>0),R27/P27-1,"") -> -0.39864706 | T27: =IF(AND(ISNUMBER(P27),P27>0),P27*EXP('Read me'!$B$22),"") -> 7.1088197
A28: 1:37 | B28: Epsom | C28: Betfred Turbo Boost Nursery | D28: Class 4 | E28: 7 | F28: Good | G28: 8 | H28: The Ginger Kid (IRE) | I28: Lewis, Ashley | J28: Walker, Ed | K28: 9 | L28: 83 | M28: 2 | N28: 38 | O28: 3 | P28: 6.2737356 | Q28: 0.15939467 | R28: 4.5 | S28: =IF(AND(ISNUMBER(R28),R28>1,P28>0),R28/P28-1,"") -> -0.28272399 | T28: =IF(AND(ISNUMBER(P28),P28>0),P28*EXP('Read me'!$B$22),"") -> 7.662758
A29: 1:37 | B29: Epsom | C29: Betfred Turbo Boost Nursery | D29: Class 4 | E29: 7 | F29: Good | G29: 8 | H29: Telegraphic | I29: Loughnane, Billy | J29: Johnston, Charlie | K29: 8 | L29: 80 | M29: 2 | N29: 38 | O29: 4 | P29: 8.7453849 | Q29: 0.11434603 | R29: 6.5 | S29: =IF(AND(ISNUMBER(R29),R29>1,P29>0),R29/P29-1,"") -> -0.25675084 | T29: =IF(AND(ISNUMBER(P29),P29>0),P29*EXP('Read me'!$B$22),"") -> 10.681637
A30: 1:37 | B30: Epsom | C30: Betfred Turbo Boost Nursery | D30: Class 4 | E30: 7 | F30: Good | G30: 8 | H30: Rogue Imperial | I30: Ryan, Rossa | J30: Watson, Archie | K30: 5 | L30: 78 | M30: 2 | N30: 34 | O30: 5 | P30: 9.1388947 | Q30: 0.10942242 | R30: 17 | S30: =IF(AND(ISNUMBER(R30),R30>1,P30>0),R30/P30-1,"") -> 0.86018119 | T30: =IF(AND(ISNUMBER(P30),P30>0),P30*EXP('Read me'!$B$22),"") -> 11.162271
A31: 1:37 | B31: Epsom | C31: Betfred Turbo Boost Nursery | D31: Class 4 | E31: 7 | F31: Good | G31: 8 | H31: Clive The Writer (IRE) | I31: Crouch, Hector | J31: Muir, W R & Grassick, C | K31: 1 | L31: 78 | M31: 2 | N31: 16 | O31: 6 | P31: 9.3350044 | Q31: 0.10712368 | R31: 9.5 | S31: =IF(AND(ISNUMBER(R31),R31>1,P31>0),R31/P31-1,"") -> 0.017674937 | T31: =IF(AND(ISNUMBER(P31),P31>0),P31*EXP('Read me'!$B$22),"") -> 11.4018
A32: 1:37 | B32: Epsom | C32: Betfred Turbo Boost Nursery | D32: Class 4 | E32: 7 | F32: Good | G32: 8 | H32: Angel Of Desire | I32: Fallon, Cieren | J32: Perrett, Mrs A J | K32: 6 | L32: 71 | M32: 2 | N32: 27 | O32: 7 | P32: 13.811546 | Q32: 0.07240319 | R32: 11 | S32: =IF(AND(ISNUMBER(R32),R32>1,P32>0),R32/P32-1,"") -> -0.20356492 | T32: =IF(AND(ISNUMBER(P32),P32>0),P32*EXP('Read me'!$B$22),"") -> 16.869461
A33: 1:37 | B33: Epsom | C33: Betfred Turbo Boost Nursery | D33: Class 4 | E33: 7 | F33: Good | G33: 8 | H33: Leucothea (IRE) | I33: Levey, S M | J33: Hannon (Jnr), Richard | K33: 2 | L33: 71 | M33: 2 | N33: 17 | O33: 8 | P33: 20.839422 | Q33: 0.047985976 | R33: 19 | S33: =IF(AND(ISNUMBER(R33),R33>1,P33>0),R33/P33-1,"") -> -0.088266455 | T33: =IF(AND(ISNUMBER(P33),P33>0),P33*EXP('Read me'!$B$22),"") -> 25.453327
A34: 1:49 | B34: Ffos Las | C34: Bridge, The Home Of The Carvery Nursery | D34: Class 5 | E34: 5 | F34: Good To Soft | G34: 8 | H34: Rhodes Runner (IRE) | I34: Clutterbuck, Rhys | J34: Beckett, R M | K34: 4 | L34: 75 | M34: 2 | N34: 8 | O34: 1 | P34: 4.9613223 | Q34: 0.20155917 | R34: 3.75 | S34: =IF(AND(ISNUMBER(R34),R34>1,P34>0),R34/P34-1,"") -> -0.24415311 | T34: =IF(AND(ISNUMBER(P34),P34>0),P34*EXP('Read me'!$B$22),"") -> 6.0597727
A35: 1:49 | B35: Ffos Las | C35: Bridge, The Home Of The Carvery Nursery | D35: Class 5 | E35: 5 | F35: Good To Soft | G35: 8 | H35: Perigord Noir (IRE) | I35: Sayette, B D L | J35: Baker, George | K35: 8 | L35: 71 | M35: 2 | N35: 15 | O35: 2 | P35: 5.5643037 | Q35: 0.17971701 | R35: 4.5 | S35: =IF(AND(ISNUMBER(R35),R35>1,P35>0),R35/P35-1,"") -> -0.19127347 | T35: =IF(AND(ISNUMBER(P35),P35>0),P35*EXP('Read me'!$B$22),"") -> 6.7962558
A36: 1:49 | B36: Ffos Las | C36: Bridge, The Home Of The Carvery Nursery | D36: Class 5 | E36: 5 | F36: Good To Soft | G36: 8 | H36: Naval Cop | I36: Hutchinson, Callum | J36: Balding, A M | K36: 2 | L36: 65 | M36: 2 | N36: 15 | O36: 3 | P36: 6.3248432 | Q36: 0.15810669 | R36: 4.5 | S36: =IF(AND(ISNUMBER(R36),R36>1,P36>0),R36/P36-1,"") -> -0.28851992 | T36: =IF(AND(ISNUMBER(P36),P36>0),P36*EXP('Read me'!$B$22),"") -> 7.725181
A37: 1:49 | B37: Ffos Las | C37: Bridge, The Home Of The Carvery Nursery | D37: Class 5 | E37: 5 | F37: Good To Soft | G37: 8 | H37: Blondie Larry (IRE) | I37: Carver, William | J37: Osborne, J A | K37: 5 | L37: 73 | M37: 2 | N37: 73 | O37: 4 | P37: 6.8148062 | Q37: 0.14673932 | R37: 9 | S37: =IF(AND(ISNUMBER(R37),R37>1,P37>0),R37/P37-1,"") -> 0.32065384 | T37: =IF(AND(ISNUMBER(P37),P37>0),P37*EXP('Read me'!$B$22),"") -> 8.3236231
... A41: 1:49 | B41: Ffos Las | C41: Bridge, The Home Of The Carvery Nursery | D41: Class 5 | E41: 5 | F41: Good To Soft | G41: 8 | H41: Defiant Dream | I41: Heard, Tyler | J41: Usher, M D I | K41: 3 | L41: 54 | M41: 2 | N41: 10 | O41: 8 | P41: 49.851691 | Q41: 0.0200595 | R41: 29 | S41: =IF(AND(ISNUMBER(R41),R41>1,P41>0),R41/P41-1,"") -> -0.4182745 | T41: =IF(AND(ISNUMBER(P41),P41>0),P41*EXP('Read me'!$B$22),"") -> 60.888993
A42: 2:00 | B42: Curragh | C42: Izuzu Ireland Irish European Breeders Fund Maiden | E42: 9 | F42: Heavy | G42: 9 | H42: Kingdom Of Camelot (FR) | I42: Moore, Ryan | J42: OBrien, A P | K42: 12 | L42: 0 | M42: 2 | N42: 29 | O42: 1 | P42: 2.7097568 | Q42: 0.36903681 | R42: 1.9090909 | S42: =IF(AND(ISNUMBER(R42),R42>1,P42>0),R42/P42-1,"") -> -0.29547519 | T42: =IF(AND(ISNUMBER(P42),P42>0),P42*EXP('Read me'!$B$22),"") -> 3.3097044
A43: 2:00 | B43: Curragh | C43: Izuzu Ireland Irish European Breeders Fund Maiden | E43: 9 | F43: Heavy | G43: 9 | H43: Cluster | I43: Keane, C T | J43: OBrien, Joseph Patrick | K43: 6 | L43: 0 | M43: 2 | N43: 29 | O43: 2 | P43: 4.0075054 | Q43: 0.24953179 | R43: 2.75 | S43: =IF(AND(ISNUMBER(R43),R43>1,P43>0),R43/P43-1,"") -> -0.31378758 | T43: =IF(AND(ISNUMBER(P43),P43>0),P43*EXP('Read me'!$B$22),"") -> 4.8947782
...

Sheet Ffos Las
A1: Time | B1: Course | C1: Race | D1: Class | E1: Furlongs | F1: Going | G1: Runners | H1: Horse | I1: Jockey | J1: Trainer | K1: Draw | L1: OR | M1: Age | N1: Days since run | O1: Model rank | P1: Predicted BSP | Q1: Win probability | R1: Card odds (HRB) | S1: Card odds vs model | T1: Rule: back at Betfair ≥
A2: 1:19 | B2: Ffos Las | C2: Alex And Salvo Welcome You To The Bridge Handicap | D2: Class 6 | E2: 6 | F2: Good To Soft | G2: 11 | H2: Sub Thirteen | I2: Hutchinson, Callum | J2: Scott, J | K2: 9 | L2: 53 | M2: 5 | N2: 14 | O2: 1 | P2: 3.0244583 | Q2: 0.33063772 | R2: 3.25 | S2: =IF(AND(ISNUMBER(R2),R2>1,P2>0),R2/P2-1,"") -> 0.074572576 | T2: =IF(AND(ISNUMBER(P2),P2>0),P2*EXP('Read me'!$B$22),"") -> 3.6940818
A3: 1:19 | B3: Ffos Las | C3: Alex And Salvo Welcome You To The Bridge Handicap | D3: Class 6 | E3: 6 | F3: Good To Soft | G3: 11 | H3: Macarone | I3: Ffrench Davis, Ben | J3: Harris, Miss G | K3: 8 | L3: 52 | M3: 5 | N3: 15 | O3: 2 | P3: 4.3312252 | Q3: 0.23088155 | R3: 4 | S3: =IF(AND(ISNUMBER(R3),R3>1,P3>0),R3/P3-1,"") -> -0.07647378 | T3: =IF(AND(ISNUMBER(P3),P3>0),P3*EXP('Read me'!$B$22),"") -> 5.2901704
A4: 1:19 | B4: Ffos Las | C4: Alex And Salvo Welcome You To The Bridge Handicap | D4: Class 6 | E4: 6 | F4: Good To Soft | G4: 11 | H4: Blue Point Express (IRE) | I4: Marsh, Finley | J4: Wintle, A | K4: 7 | L4: 45 | M4: 4 | N4: 27 | O4: 3 | P4: 7.187645 | Q4: 0.13912763 | R4: 6 | S4: =IF(AND(ISNUMBER(R4),R4>1,P4>0),R4/P4-1,"") -> -0.16523424 | T4: =IF(AND(ISNUMBER(P4),P4>0),P4*EXP('Read me'!$B$22),"") -> 8.7790095
A5: 1:19 | B5: Ffos Las | C5: Alex And Salvo Welcome You To The Bridge Handicap | D5: Class 6 | E5: 6 | F5: Good To Soft | G5: 11 | H5: Up The Anti (IRE) | I5: Coppins, Myla | J5: Carroll, A W | K5: 6 | L5: 53 | M5: 4 | N5: 25 | O5: 4 | P5: 10.055959 | Q5: 0.099443529 | R5: 8 | S5: =IF(AND(ISNUMBER(R5),R5>1,P5>0),R5/P5-1,"") -> -0.20445177 | T5: =IF(AND(ISNUMBER(P5),P5>0),P5*EXP('Read me'!$B$22),"") -> 12.282375
A6: 1:19 | B6: Ffos Las | C6: Alex And Salvo Welcome You To The Bridge Handicap | D6: Class 6 | E6: 6 | F6: Good To Soft | G6: 11 | H6: Music And Song (IRE) | I6: Probert, David | J6: Flood, D | K6: 5 | L6: 45 | M6: 3 | N6: 5 | O6: 5 | P6: 15.63988 | Q6: 0.063939107 | R6: 10 | S6: =IF(AND(ISNUMBER(R6),R6>1,P6>0),R6/P6-1,"") -> -0.36060893 | T6: =IF(AND(ISNUMBER(P6),P6>0),P6*EXP('Read me'!$B$22),"") -> 19.102593
A7: 1:19 | B7: Ffos Las | C7: Alex And Salvo Welcome You To The Bridge Handicap | D7: Class 6 | E7: 6 | F7: Good To Soft | G7: 11 | H7: The Bear Of Saints (FR) | I7: Carson, William | J7: Oshea, J G M | K7: 4 | L7: 54 | M7: 4 | N7: 34 | O7: 6 | P7: 16.543067 | Q7: 0.060448284 | R7: 15 | S7: =IF(AND(ISNUMBER(R7),R7>1,P7>0),R7/P7-1,"") -> -0.093275736 | T7: =IF(AND(ISNUMBER(P7),P7>0),P7*EXP('Read me'!$B$22),"") -> 20.205747
A8: 1:19 | B8: Ffos Las | C8: Alex And Salvo Welcome You To The Bridge Handicap | D8: Class 6 | E8: 6 | F8: Good To Soft | G8: 11 | H8: Pacific Prince | I8: Coughlan, Laura | J8: Bennett, J A | K8: 11 | L8: 45 | M8: 5 | N8: 20 | O8: 7 | P8: 44.329774 | Q8: 0.022558202 | R8: 41 | S8: =IF(AND(ISNUMBER(R8),R8>1,P8>0),R8/P8-1,"") -> -0.075113712 | T8: =IF(AND(ISNUMBER(P8),P8>0),P8*EXP('Read me'!$B$22),"") -> 54.144508
A9: 1:19 | B9: Ffos Las | C9: Alex And Salvo Welcome You To The Bridge Handicap | D9: Class 6 | E9: 6 | F9: Good To Soft | G9: 11 | H9: Savvi Row | I9: Heard, Tyler | J9: Millman, B R | K9: 12 | L9: 45 | M9: 3 | N9: 15 | O9: 8 | P9: 59.529493 | Q9: 0.016798396 | R9: 34 | S9: =IF(AND(ISNUMBER(R9),R9>1,P9>0),R9/P9-1,"") -> -0.42885454 | T9: =IF(AND(ISNUMBER(P9),P9>0),P9*EXP('Read me'!$B$22),"") -> 72.709487
A10: 1:19 | B10: Ffos Las | C10: Alex And Salvo Welcome You To The Bridge Handicap | D10: Class 6 | E10: 6 | F10: Good To Soft | G10: 11 | H10: Shush A Minute | I10: Bradley, Paddy | J10: Ryan, J | K10: 1 | L10: 50 | M10: 3 | N10: 306 | O10: 9 | P10: 62.476468 | Q10: 0.016006026 | R10: 7 | S10: =IF(AND(ISNUMBER(R10),R10>1,P10>0),R10/P10-1,"") -> -0.88795782 | T10: =IF(AND(ISNUMBER(P10),P10>0),P10*EXP('Read me'!$B$22),"") -> 76.308931
A11: 1:19 | B11: Ffos Las | C11: Alex And Salvo Welcome You To The Bridge Handicap | D11: Class 6 | E11: 6 | F11: Good To Soft | G11: 11 | H11: Lochaber | I11: ONeill, K T | J11: Dixon, Scott | K11: 10 | L11: 45 | M11: 5 | N11: 14 | O11: 10 | P11: 63.912016 | Q11: 0.01564651 | R11: 51 | S11: =IF(AND(ISNUMBER(R11),R11>1,P11>0),R11/P11-1,"") -> -0.20202799 | T11: =IF(AND(ISNUMBER(P11),P11>0),P11*EXP('Read me'!$B$22),"") -> 78.062313
A12: 1:19 | B12: Ffos Las | C12: Alex And Salvo Welcome You To The Bridge Handicap | D12: Class 6 | E12: 6 | F12: Good To Soft | G12: 11 | H12: Miss Gold | I12: Sayette, B D L | J12: Flood, D | K12: 2 | L12: 45 | M12: 3 | N12: 46 | O12: 11 | P12: 221.57978 | Q12: 0.0045130472 | R12: 81 | S12: =IF(AND(ISNUMBER(R12),R12>1,P12>0),R12/P12-1,"") -> -0.63444318 | T12: =IF(AND(ISNUMBER(P12),P12>0),P12*EXP('Read me'!$B$22),"") -> 270.63815
A13: 1:49 | B13: Ffos Las | C13: Bridge, The Home Of The Carvery Nursery | D13: Class 5 | E13: 5 | F13: Good To Soft | G13: 8 | H13: Rhodes Runner (IRE) | I13: Clutterbuck, Rhys | J13: Beckett, R M | K13: 4 | L13: 75 | M13: 2 | N13: 8 | O13: 1 | P13: 4.9613223 | Q13: 0.20155917 | R13: 3.75 | S13: =IF(AND(ISNUMBER(R13),R13>1,P13>0),R13/P13-1,"") -> -0.24415311 | T13: =IF(AND(ISNUMBER(P13),P13>0),P13*EXP('Read me'!$B$22),"") -> 6.0597727
... A29: 2:59 | B29: Ffos Las | C29: Happy Birthday Alex, From The Bridge Handicap | D29: Class 5 | E29: 16 | F29: Good To Soft | G29: 5 | H29: No Ordinary Joe (IRE) | I29: Marsh, Finley | J29: Stephens, Robert | K29: 4 | L29: 65 | M29: 10 | N29: 15 | O29: 5 | P29: 25.132448 | Q29: 0.0397892 | R29: 13 | S29: =IF(AND(ISNUMBER(R29),R29>1,P29>0),R29/P29-1,"") -> -0.4827404 | T29: =IF(AND(ISNUMBER(P29),P29>0),P29*EXP('Read me'!$B$22),"") -> 30.696841
A30: 3:34 | B30: Ffos Las | C30: Celebrate In Style At The Bridge Novice Stakes (GBB Race) | D30: Class 3 | F30: Good To Soft | G30: 5 | H30: Silent Force (IRE) | I30: Hutchinson, Callum | J30: Balding, A M | K30: 2 | L30: 0 | M30: 2 | N30: 43 | O30: 1 | P30: 1.720155 | Q30: 0.58134297 | R30: 1.3636364 | S30: =IF(AND(ISNUMBER(R30),R30>1,P30>0),R30/P30-1,"") -> -0.20725958 | T30: =IF(AND(ISNUMBER(P30),P30>0),P30*EXP('Read me'!$B$22),"") -> 2.101002
A31: 3:34 | B31: Ffos Las | C31: Celebrate In Style At The Bridge Novice Stakes (GBB Race) | D31: Class 3 | F31: Good To Soft | G31: 5 | H31: Ghost Raider (IRE) | I31: Clutterbuck, Rhys | J31: Beckett, R M | K31: 5 | L31: 77 | M31: 2 | N31: 21 | O31: 2 | P31: 2.8890443 | Q31: 0.34613522 | R31: 3.25 | S31: =IF(AND(ISNUMBER(R31),R31>1,P31>0),R31/P31-1,"") -> 0.12493947 | T31: =IF(AND(ISNUMBER(P31),P31>0),P31*EXP('Read me'!$B$22),"") -> 3.5286867
A32: 3:34 | B32: Ffos Las | C32: Celebrate In Style At The Bridge Novice Stakes (GBB Race) | D32: Class 3 | F32: Good To Soft | G32: 5 | H32: Naval Empire (IRE) | I32: Doughty, Jack | J32: Williams, S C | K32: 3 | L32: 0 | M32: 2 | O32: 3 | P32: 35.458939 | Q32: 0.028201633 | R32: 13 | S32: =IF(AND(ISNUMBER(R32),R32>1,P32>0),R32/P32-1,"") -> -0.63337877 | T32: =IF(AND(ISNUMBER(P32),P32>0),P32*EXP('Read me'!$B$22),"") -> 43.309646
A33: 3:34 | B33: Ffos Las | C33: Celebrate In Style At The Bridge Novice Stakes (GBB Race) | D33: Class 3 | F33: Good To Soft | G33: 5 | H33: Time Glory (IRE) | I33: Probert, David | J33: Llewellyn, B J | K33: 4 | L33: 65 | M33: 2 | N33: 29 | O33: 4 | P33: 42.061684 | Q33: 0.023774607 | R33: 29 | S33: =IF(AND(ISNUMBER(R33),R33>1,P33>0),R33/P33-1,"") -> -0.3105364 | T33: =IF(AND(ISNUMBER(P33),P33>0),P33*EXP('Read me'!$B$22),"") -> 51.374257
A34: 3:34 | B34: Ffos Las | C34: Celebrate In Style At The Bridge Novice Stakes (GBB Race) | D34: Class 3 | F34: Good To Soft | G34: 5 | H34: Fourth Crusade (IRE) | I34: Gilligan, Jack | J34: Prescott, Sir Mark | K34: 1 | L34: 0 | M34: 2 | N34: 17 | O34: 5 | P34: 48.672304 | Q34: 0.020545565 | R34: 23 | S34: =IF(AND(ISNUMBER(R34),R34>1,P34>0),R34/P34-1,"") -> -0.527452 | T34: =IF(AND(ISNUMBER(P34),P34>0),P34*EXP('Read me'!$B$22),"") -> 59.448486
A35: 4:09 | B35: Ffos Las | C35: Bridge, For All Family Occasions Handicap (Div 1) | D35: Class 6 | E35: 8 | F35: Good To Soft | G35: 9 | H35: Homeland | I35: Marsh, Finley | J35: Faulkner, T | K35: 7 | L35: 56 | M35: 4 | N35: 27 | O35: 1 | P35: 4.8554186 | Q35: 0.20595546 | R35: 5 | S35: =IF(AND(ISNUMBER(R35),R35>1,P35>0),R35/P35-1,"") -> 0.029777321 | T35: =IF(AND(ISNUMBER(P35),P35>0),P35*EXP('Read me'!$B$22),"") -> 5.9304217
A36: 4:09 | B36: Ffos Las | C36: Bridge, For All Family Occasions Handicap (Div 1) | D36: Class 6 | E36: 8 | F36: Good To Soft | G36: 9 | H36: Rosemarys Rose (IRE) | I36: Osborne, Saffie | J36: Millman, B R | K36: 6 | L36: 58 | M36: 4 | N36: 29 | O36: 2 | P36: 5.4159125 | Q36: 0.18464109 | R36: 4.5 | S36: =IF(AND(ISNUMBER(R36),R36>1,P36>0),R36/P36-1,"") -> -0.16911509 | T36: =IF(AND(ISNUMBER(P36),P36>0),P36*EXP('Read me'!$B$22),"") -> 6.6150105
A37: 4:09 | B37: Ffos Las | C37: Bridge, For All Family Occasions Handicap (Div 1) | D37: Class 6 | E37: 8 | F37: Good To Soft | G37: 9 | H37: Scarfo (IRE) | I37: Tucker, Charlie | J37: Llewellyn, B J | K37: 3 | L37: 55 | M37: 5 | N37: 6 | O37: 3 | P37: 6.1514869 | Q37: 0.16256232 | R37: 5 | S37: =IF(AND(ISNUMBER(R37),R37>1,P37>0),R37/P37-1,"") -> -0.18718839 | T37: =IF(AND(ISNUMBER(P37),P37>0),P37*EXP('Read me'!$B$22),"") -> 7.5134431
A38: 4:09 | B38: Ffos Las | C38: Bridge, For All Family Occasions Handicap (Div 1) | D38: Class 6 | E38: 8 | F38: Good To Soft | G38: 9 | H38: Grand Vista (IRE) | I38: Bradley, Paddy | J38: Muir, W R & Grassick, C | K38: 4 | L38: 53 | M38: 3 | N38: 32 | O38: 4 | P38: 9.6766345 | Q38: 0.10334171 | R38: 10 | S38: =IF(AND(ISNUMBER(R38),R38>1,P38>0),R38/P38-1,"") -> 0.033417145 | T38: =IF(AND(ISNUMBER(P38),P38>0),P38*EXP('Read me'!$B$22),"") -> 11.819068
A39: 4:09 | B39: Ffos Las | C39: Bridge, For All Family Occasions Handicap (Div 1) | D39: Class 6 | E39: 8 | F39: Good To Soft | G39: 9 | H39: A Rose Adaay | I39: Ffrench Davis, Ben | J39: Harris, Miss G | K39: 8 | L39: 50 | M39: 4 | N39: 15 | O39: 5 | P39: 11.048524 | Q39: 0.090509824 | R39: 15 | S39: =IF(AND(ISNUMBER(R39),R39>1,P39>0),R39/P39-1,"") -> 0.35764737 | T39: =IF(AND(ISNUMBER(P39),P39>0),P39*EXP('Read me'!$B$22),"") -> 13.494698
A40: 4:09 | B40: Ffos Las | C40: Bridge, For All Family Occasions Handicap (Div 1) | D40: Class 6 | E40: 8 | F40: Good To Soft | G40: 9 | H40: Cosmic Girl | I40: Hutchinson, Callum | J40: Balding, A M | K40: 9 | L40: 58 | M40: 3 | N40: 18 | O40: 6 | P40: 12.439083 | Q40: 0.08039178 | R40: 9.5 | S40: =IF(AND(ISNUMBER(R40),R40>1,P40>0),R40/P40-1,"") -> -0.23627809 | T40: =IF(AND(ISNUMBER(P40),P40>0),P40*EXP('Read me'!$B$22),"") -> 15.19313
A41: 4:09 | B41: Ffos Las | C41: Bridge, For All Family Occasions Handicap (Div 1) | D41: Class 6 | E41: 8 | F41: Good To Soft | G41: 9 | H41: Prince Ali | I41: Lewis, Zoe | J41: Faulkner, T | K41: 1 | L41: 57 | M41: 8 | N41: 27 | O41: 7 | P41: 15.487309 | Q41: 0.064568997 | R41: 6.5 | S41: =IF(AND(ISNUMBER(R41),R41>1,P41>0),R41/P41-1,"") -> -0.58030152 | T41: =IF(AND(ISNUMBER(P41),P41>0),P41*EXP('Read me'!$B$22),"") -> 18.916242
A42: 4:09 | B42: Ffos Las | C42: Bridge, For All Family Occasions Handicap (Div 1) | D42: Class 6 | E42: 8 | F42: Good To Soft | G42: 9 | H42: Pebble Dash (IRE) | I42: ONeill, K T | J42: Llewellyn, B J | K42: 2 | L42: 46 | M42: 4 | N42: 6 | O42: 8 | P42: 17.62177 | Q42: 0.056747988 | R42: 13 | S42: =IF(AND(ISNUMBER(R42),R42>1,P42>0),R42/P42-1,"") -> -0.26227616 | T42: =IF(AND(ISNUMBER(P42),P42>0),P42*EXP('Read me'!$B$22),"") -> 21.523279
A43: 4:09 | B43: Ffos Las | C43: Bridge, For All Family Occasions Handicap (Div 1) | D43: Class 6 | E43: 8 | F43: Good To Soft | G43: 9 | H43: Thestral | I43: Coppins, Myla | J43: Carroll, A W | K43: 10 | L43: 60 | M43: 3 | N43: 54 | O43: 9 | P43: 19.500469 | Q43: 0.051280818 | R43: 21 | S43: =IF(AND(ISNUMBER(R43),R43>1,P43>0),R43/P43-1,"") -> 0.076897174 | T43: =IF(AND(ISNUMBER(P43),P43>0),P43*EXP('Read me'!$B$22),"") -> 23.817927
A44: 4:44 | B44: Ffos Las | C44: Bridge, For All Family Occasions Handicap (Div 2) | D44: Class 6 | E44: 8 | F44: Good To Soft | G44: 10 | H44: Arvana Belle (IRE) | I44: Osborne, Saffie | J44: Millman, B R | K44: 5 | L44: 47 | M44: 3 | N44: 6 | O44: 1 | P44: 3.8925234 | Q44: 0.25690276 | R44: 2.625 | S44: =IF(AND(ISNUMBER(R44),R44>1,P44>0),R44/P44-1,"") -> -0.32563025 | T44: =IF(AND(ISNUMBER(P44),P44>0),P44*EXP('Read me'!$B$22),"") -> 4.7543388
A45: 4:44 | B45: Ffos Las | C45: Bridge, For All Family Occasions Handicap (Div 2) | D45: Class 6 | E45: 8 | F45: Good To Soft | G45: 10 | H45: Freedom Bay | I45: Hutchinson, Callum | J45: Hawkins, Zoe | K45: 7 | L45: 48 | M45: 4 | N45: 15 | O45: 2 | P45: 6.0008733 | Q45: 0.16664241 | R45: 8.5 | S45: =IF(AND(ISNUMBER(R45),R45>1,P45>0),R45/P45-1,"") -> 0.4164605 | T45: =IF(AND(ISNUMBER(P45),P45>0),P45*EXP('Read me'!$B$22),"") -> 7.3294832
A46: 4:44 | B46: Ffos Las | C46: Bridge, For All Family Occasions Handicap (Div 2) | D46: Class 6 | E46: 8 | F46: Good To Soft | G46: 10 | H46: King of The Dance (IRE) | I46: Probert, David | J46: Llewellyn, B J | K46: 8 | L46: 54 | M46: 7 | N46: 6 | O46: 3 | P46: 6.9588768 | Q46: 0.14370135 | R46: 6.5 | S46: =IF(AND(ISNUMBER(R46),R46>1,P46>0),R46/P46-1,"") -> -0.065941223 | T46: =IF(AND(ISNUMBER(P46),P46>0),P46*EXP('Read me'!$B$22),"") -> 8.4995914
... A58: 5:19 | B58: Ffos Las | C58: Bridge Llangennech Open Daily Amateur Jockeys Handicap | D58: Class 6 | E58: 10 | F58: Good To Soft | G58: 5 | H58: The Ormer Gatherer | I58: Hills, Mr James | J58: Bramley, Faye | K58: 2 | L58: 47 | M58: 7 | N58: 15 | O58: 5 | P58: 13.764773 | Q58: 0.072649219 | R58: 4.5 | S58: =IF(AND(ISNUMBER(R58),R58>1,P58>0),R58/P58-1,"") -> -0.67307851 | T58: =IF(AND(ISNUMBER(P58),P58>0),P58*EXP('Read me'!$B$22),"") -> 16.812332

Sheet Curragh
A1: Time | B1: Course | C1: Race | D1: Class | E1: Furlongs | F1: Going | G1: Runners | H1: Horse | I1: Jockey | J1: Trainer | K1: Draw | L1: OR | M1: Age | N1: Days since run | O1: Model rank | P1: Predicted BSP | Q1: Win probability | R1: Card odds (HRB) | S1: Card odds vs model | T1: Rule: back at Betfair ≥
A2: 1:25 | B2: Curragh | C2: Army Equitation Centenary Irish European Breeders Fund Maiden | E2: 7 | F2: Heavy | G2: 13 | H2: Raging Bull (IRE) | I2: Moore, Ryan | J2: OBrien, A P | K2: 6 | L2: 0 | M2: 2 | N2: 49 | O2: 1 | P2: 1.7510775 | Q2: 0.57107694 | R2: 1.7272727 | S2: =IF(AND(ISNUMBER(R2),R2>1,P2>0),R2/P2-1,"") -> -0.013594385 | T2: =IF(AND(ISNUMBER(P2),P2>0),P2*EXP('Read me'!$B$22),"") -> 2.1387709
A3: 1:25 | B3: Curragh | C3: Army Equitation Centenary Irish European Breeders Fund Maiden | E3: 7 | F3: Heavy | G3: 13 | H3: Yellow Sky (IRE) | I3: Coen, Ben M | J3: Murtagh, J P | K3: 12 | L3: 0 | M3: 2 | N3: 62 | O3: 2 | P3: 7.4272181 | Q3: 0.13463991 | R3: 12 | S3: =IF(AND(ISNUMBER(R3),R3>1,P3>0),R3/P3-1,"") -> 0.61567896 | T3: =IF(AND(ISNUMBER(P3),P3>0),P3*EXP('Read me'!$B$22),"") -> 9.0716247
A4: 1:25 | B4: Curragh | C4: Army Equitation Centenary Irish European Breeders Fund Maiden | E4: 7 | F4: Heavy | G4: 13 | H4: Maximilien Luce (IRE) | I4: Cleary, Jack | J4: OBrien, A P | K4: 1 | L4: 0 | M4: 2 | O4: 3 | P4: 13.08711 | Q4: 0.076411066 | R4: 7 | S4: =IF(AND(ISNUMBER(R4),R4>1,P4>0),R4/P4-1,"") -> -0.46512253 | T4: =IF(AND(ISNUMBER(P4),P4>0),P4*EXP('Read me'!$B$22),"") -> 15.984632
A5: 1:25 | B5: Curragh | C5: Army Equitation Centenary Irish European Breeders Fund Maiden | E5: 7 | F5: Heavy | G5: 13 | H5: Golden Idol (IRE) | I5: Lee, W J | J5: Bromhead, Henry De | K5: 9 | L5: 0 | M5: 2 | O5: 4 | P5: 13.310346 | Q5: 0.075129527 | R5: 5.5 | S5: =IF(AND(ISNUMBER(R5),R5>1,P5>0),R5/P5-1,"") -> -0.5867876 | T5: =IF(AND(ISNUMBER(P5),P5>0),P5*EXP('Read me'!$B$22),"") -> 16.257293
A6: 1:25 | B6: Curragh | C6: Army Equitation Centenary Irish European Breeders Fund Maiden | E6: 7 | F6: Heavy | G6: 13 | H6: Normanton (IRE) | I6: McAteer, L T | J6: Marnane, David | K6: 16 | L6: 0 | M6: 2 | O6: 5 | P6: 26.949884 | Q6: 0.037105911 | R6: 15 | S6: =IF(AND(ISNUMBER(R6),R6>1,P6>0),R6/P6-1,"") -> -0.44341133 | T6: =IF(AND(ISNUMBER(P6),P6>0),P6*EXP('Read me'!$B$22),"") -> 32.916663
A7: 1:25 | B7: Curragh | C7: Army Equitation Centenary Irish European Breeders Fund Maiden | E7: 7 | F7: Heavy | G7: 13 | H7: Overhead Drive (IRE) | I7: Heffernan, J A | J7: Murphy, John Joseph | K7: 14 | L7: 0 | M7: 2 | O7: 6 | P7: 29.584989 | Q7: 0.033800925 | R7: 29 | S7: =IF(AND(ISNUMBER(R7),R7>1,P7>0),R7/P7-1,"") -> -0.019773178 | T7: =IF(AND(ISNUMBER(P7),P7>0),P7*EXP('Read me'!$B$22),"") -> 36.135187
A8: 1:25 | B8: Curragh | C8: Army Equitation Centenary Irish European Breeders Fund Maiden | E8: 7 | F8: Heavy | G8: 13 | H8: Tsali (IRE) | I8: Hayes, C D | J8: Coleman, Kevin | K8: 8 | L8: 0 | M8: 2 | O8: 7 | P8: 36.193559 | Q8: 0.027629225 | R8: 34 | S8: =IF(AND(ISNUMBER(R8),R8>1,P8>0),R8/P8-1,"") -> -0.060606334 | T8: =IF(AND(ISNUMBER(P8),P8>0),P8*EXP('Read me'!$B$22),"") -> 44.206913
A9: 1:25 | B9: Curragh | C9: Army Equitation Centenary Irish European Breeders Fund Maiden | E9: 7 | F9: Heavy | G9: 13 | H9: Ah Sure Look (IRE) | I9: Sheridan, J M | J9: Hassett, Martin | K9: 10 | L9: 0 | M9: 2 | O9: 8 | P9: 87.460693 | Q9: 0.011433708 | R9: 34 | S9: =IF(AND(ISNUMBER(R9),R9>1,P9>0),R9/P9-1,"") -> -0.61125394 | T9: =IF(AND(ISNUMBER(P9),P9>0),P9*EXP('Read me'!$B$22),"") -> 106.82473
A10: 1:25 | B10: Curragh | C10: Army Equitation Centenary Irish European Breeders Fund Maiden | E10: 7 | F10: Heavy | G10: 13 | H10: Johntom | I10: Carroll, G F | J10: Cromwell, Gavin Patrick | K10: 5 | L10: 0 | M10: 2 | N10: 10 | O10: 9 | P10: 95.343068 | Q10: 0.010488439 | R10: 41 | S10: =IF(AND(ISNUMBER(R10),R10>1,P10>0),R10/P10-1,"") -> -0.56997398 | T10: =IF(AND(ISNUMBER(P10),P10>0),P10*EXP('Read me'!$B$22),"") -> 116.45229
A11: 1:25 | B11: Curragh | C11: Army Equitation Centenary Irish European Breeders Fund Maiden | E11: 7 | F11: Heavy | G11: 13 | H11: Activity (IRE) | I11: Crosse, Nathan | J11: Harrington, Mrs John | K11: 3 | L11: 0 | M11: 2 | N11: 52 | O11: 10 | P11: 112.02611 | Q11: 0.0089264903 | R11: 29 | S11: =IF(AND(ISNUMBER(R11),R11>1,P11>0),R11/P11-1,"") -> -0.74113178 | T11: =IF(AND(ISNUMBER(P11),P11>0),P11*EXP('Read me'!$B$22),"") -> 136.829
A12: 1:25 | B12: Curragh | C12: Army Equitation Centenary Irish European Breeders Fund Maiden | E12: 7 | F12: Heavy | G12: 13 | H12: Soho Dragon (IRE) | I12: OConnor, Donagh | J12: Murphy, John Joseph | K12: 7 | L12: 0 | M12: 2 | O12: 11 | P12: 158.85539 | Q12: 0.0062950336 | R12: 34 | S12: =IF(AND(ISNUMBER(R12),R12>1,P12>0),R12/P12-1,"") -> -0.78596886 | T12: =IF(AND(ISNUMBER(P12),P12>0),P12*EXP('Read me'!$B$22),"") -> 194.02641
A13: 1:25 | B13: Curragh | C13: Army Equitation Centenary Irish European Breeders Fund Maiden | E13: 7 | F13: Heavy | G13: 13 | H13: One Flash (IRE) | I13: Joyce, Wesley | J13: Sexton, Adrian | K13: 11 | L13: 0 | M13: 2 | O13: 12 | P13: 282.56065 | Q13: 0.0035390632 | R13: 41 | S13: =IF(AND(ISNUMBER(R13),R13>1,P13>0),R13/P13-1,"") -> -0.85489841 | T13: =IF(AND(ISNUMBER(P13),P13>0),P13*EXP('Read me'!$B$22),"") -> 345.12036
A14: 1:25 | B14: Curragh | C14: Army Equitation Centenary Irish European Breeders Fund Maiden | E14: 7 | F14: Heavy | G14: 13 | H14: Silk Twist (IRE) | I14: McCullagh, Scott | J14: Mullins, Thomas | K14: 2 | L14: 0 | M14: 2 | N14: 10 | O14: 13 | P14: 283.78757 | Q14: 0.0035237626 | R14: 41 | S14: =IF(AND(ISNUMBER(R14),R14>1,P14>0),R14/P14-1,"") -> -0.85552574 | T14: =IF(AND(ISNUMBER(P14),P14>0),P14*EXP('Read me'!$B$22),"") -> 346.61892
A15: 2:00 | B15: Curragh | C15: Izuzu Ireland Irish European Breeders Fund Maiden | E15: 9 | F15: Heavy | G15: 9 | H15: Kingdom Of Camelot (FR) | I15: Moore, Ryan | J15: OBrien, A P | K15: 12 | L15: 0 | M15: 2 | N15: 29 | O15: 1 | P15: 2.7097568 | Q15: 0.36903681 | R15: 1.9090909 | S15: =IF(AND(ISNUMBER(R15),R15>1,P15>0),R15/P15-1,"") -> -0.29547519 | T15: =IF(AND(ISNUMBER(P15),P15>0),P15*EXP('Read me'!$B$22),"") -> 3.3097044
A16: 2:00 | B16: Curragh | C16: Izuzu Ireland Irish European Breeders Fund Maiden | E16: 9 | F16: Heavy | G16: 9 | H16: Cluster | I16: Keane, C T | J16: OBrien, Joseph Patrick | K16: 6 | L16: 0 | M16: 2 | N16: 29 | O16: 2 | P16: 4.0075054 | Q16: 0.24953179 | R16: 2.75 | S16: =IF(AND(ISNUMBER(R16),R16>1,P16>0),R16/P16-1,"") -> -0.31378758 | T16: =IF(AND(ISNUMBER(P16),P16>0),P16*EXP('Read me'!$B$22),"") -> 4.8947782
A17: 2:00 | B17: Curragh | C17: Izuzu Ireland Irish European Breeders Fund Maiden | E17: 9 | F17: Heavy | G17: 9 | H17: Capability Brown (IRE) | I17: Lordan, W M | J17: OBrien, A P | K17: 1 | L17: 0 | M17: 2 | N17: 26 | O17: 3 | P17: 4.4751775 | Q17: 0.22345482 | R17: 6.5 | S17: =IF(AND(ISNUMBER(R17),R17>1,P17>0),R17/P17-1,"") -> 0.45245634 | T17: =IF(AND(ISNUMBER(P17),P17>0),P17*EXP('Read me'!$B$22),"") -> 5.4659942
A18: 2:00 | B18: Curragh | C18: Izuzu Ireland Irish European Breeders Fund Maiden | E18: 9 | F18: Heavy | G18: 9 | H18: Darivan (IRE) | I18: Coen, Ben M | J18: Murtagh, J P | K18: 5 | L18: 0 | M18: 2 | N18: 92 | O18: 4 | P18: 11.9565 | Q18: 0.083636516 | R18: 19 | S18: =IF(AND(ISNUMBER(R18),R18>1,P18>0),R18/P18-1,"") -> 0.58909381 | T18: =IF(AND(ISNUMBER(P18),P18>0),P18*EXP('Read me'!$B$22),"") -> 14.603702
A19: 2:00 | B19: Curragh | C19: Izuzu Ireland Irish European Breeders Fund Maiden | E19: 9 | F19: Heavy | G19: 9 | H19: Greatest Knight (IRE) | I19: Cleary, Jack | J19: OBrien, A P | K19: 10 | L19: 0 | M19: 2 | O19: 5 | P19: 25.267991 | Q19: 0.039575762 | R19: 21 | S19: =IF(AND(ISNUMBER(R19),R19>1,P19>0),R19/P19-1,"") -> -0.168909 | T19: =IF(AND(ISNUMBER(P19),P19>0),P19*EXP('Read me'!$B$22),"") -> 30.862394
A20: 2:00 | B20: Curragh | C20: Izuzu Ireland Irish European Breeders Fund Maiden | E20: 9 | F20: Heavy | G20: 9 | H20: Silent Kingdom (IRE) | I20: Lee, W J | J20: Dias, Diego | K20: 2 | L20: 0 | M20: 2 | O20: 6 | P20: 60.524576 | Q20: 0.016522214 | R20: 34 | S20: =IF(AND(ISNUMBER(R20),R20>1,P20>0),R20/P20-1,"") -> -0.43824472 | T20: =IF(AND(ISNUMBER(P20),P20>0),P20*EXP('Read me'!$B$22),"") -> 73.924884
A21: 2:00 | B21: Curragh | C21: Izuzu Ireland Irish European Breeders Fund Maiden | E21: 9 | F21: Heavy | G21: 9 | H21: Warrawood | I21: McCullagh, Scott | J21: McLoughlin, Daniel | K21: 11 | L21: 0 | M21: 2 | O21: 7 | P21: 74.440977 | Q21: 0.013433461 | R21: 67 | S21: =IF(AND(ISNUMBER(R21),R21>1,P21>0),R21/P21-1,"") -> -0.099958084 | T21: =IF(AND(ISNUMBER(P21),P21>0),P21*EXP('Read me'!$B$22),"") -> 90.922415
A22: 2:00 | B22: Curragh | C22: Izuzu Ireland Irish European Breeders Fund Maiden | E22: 9 | F22: Heavy | G22: 9 | H22: Lumierebleu (IRE) | I22: Heffernan, J A | J22: Murtagh, J P | K22: 3 | L22: 0 | M22: 2 | N22: 29 | O22: 8 | P22: 264.02961 | Q22: 0.0037874539 | R22: 201 | S22: =IF(AND(ISNUMBER(R22),R22>1,P22>0),R22/P22-1,"") -> -0.23872176 | T22: =IF(AND(ISNUMBER(P22),P22>0),P22*EXP('Read me'!$B$22),"") -> 322.4865
A23: 2:00 | B23: Curragh | C23: Izuzu Ireland Irish European Breeders Fund Maiden | E23: 9 | F23: Heavy | G23: 9 | H23: Alone All Alone | I23: Whelan, R P | J23: ONeill, E J | K23: 9 | L23: 0 | M23: 2 | N23: 10 | O23: 9 | P23: 979.26571 | Q23: 0.0010211733 | R23: 151 | S23: =IF(AND(ISNUMBER(R23),R23>1,P23>0),R23/P23-1,"") -> -0.84580283 | T23: =IF(AND(ISNUMBER(P23),P23>0),P23*EXP('Read me'!$B$22),"") -> 1196.0778
A24: 2:35 | B24: Curragh | C24: Qatar Racing And Equestrian Club Renaissance Stakes (Group 3) | E24: 6 | F24: Heavy | G24: 8 | H24: Soul Love | I24: Jamin, Pierre-Louis | J24: Burke, K R | K24: 9 | L24: 101 | M24: 3 | N24: 35 | O24: 1 | P24: 3.6569722 | Q24: 0.27345026 | R24: 3.75 | S24: =IF(AND(ISNUMBER(R24),R24>1,P24>0),R24/P24-1,"") -> 0.02543848 | T24: =IF(AND(ISNUMBER(P24),P24>0),P24*EXP('Read me'!$B$22),"") -> 4.4666359
A25: 2:35 | B25: Curragh | C25: Qatar Racing And Equestrian Club Renaissance Stakes (Group 3) | E25: 6 | F25: Heavy | G25: 8 | H25: Power Blue (IRE) | I25: Lee, W J | J25: Aguiar, Robson | K25: 8 | L25: 110 | M25: 3 | N25: 36 | O25: 2 | P25: 4.4795634 | Q25: 0.22323604 | R25: 3.75 | S25: =IF(AND(ISNUMBER(R25),R25>1,P25>0),R25/P25-1,"") -> -0.16286484 | T25: =IF(AND(ISNUMBER(P25),P25>0),P25*EXP('Read me'!$B$22),"") -> 5.471351
A26: 2:35 | B26: Curragh | C26: Qatar Racing And Equestrian Club Renaissance Stakes (Group 3) | E26: 6 | F26: Heavy | G26: 8 | H26: Brussels | I26: Moore, Ryan | J26: OBrien, A P | K26: 2 | L26: 101 | M26: 3 | N26: 14 | O26: 3 | P26: 5.4711503 | Q26: 0.18277692 | R26: 7 | S26: =IF(AND(ISNUMBER(R26),R26>1,P26>0),R26/P26-1,"") -> 0.27943844 | T26: =IF(AND(ISNUMBER(P26),P26>0),P26*EXP('Read me'!$B$22),"") -> 6.682478
A27: 2:35 | B27: Curragh | C27: Qatar Racing And Equestrian Club Renaissance Stakes (Group 3) | E27: 6 | F27: Heavy | G27: 8 | H27: Royal Bay Cen (IRE) | I27: Coen, Ben M | J27: Murtagh, J P | K27: 7 | L27: 104 | M27: 3 | N27: 133 | O27: 4 | P27: 6.2935973 | Q27: 0.15889164 | R27: 3.75 | S27: =IF(AND(ISNUMBER(R27),R27>1,P27>0),R27/P27-1,"") -> -0.40415634 | T27: =IF(AND(ISNUMBER(P27),P27>0),P27*EXP('Read me'!$B$22),"") -> 7.687017
A28: 2:35 | B28: Curragh | C28: Qatar Racing And Equestrian Club Renaissance Stakes (Group 3) | E28: 6 | F28: Heavy | G28: 8 | H28: Charles Darwin (IRE) | I28: Lordan, W M | J28: OBrien, A P | K28: 4 | L28: 103 | M28: 3 | N28: 71 | O28: 5 | P28: 15.720531 | Q28: 0.063611083 | R28: 29 | S28: =IF(AND(ISNUMBER(R28),R28>1,P28>0),R28/P28-1,"") -> 0.84472141 | T28: =IF(AND(ISNUMBER(P28),P28>0),P28*EXP('Read me'!$B$22),"") -> 19.2011
A29: 2:35 | B29: Curragh | C29: Qatar Racing And Equestrian Club Renaissance Stakes (Group 3) | E29: 6 | F29: Heavy | G29: 8 | H29: Big Gossey (IRE) | I29: Whearty, R | J29: OBrien, Charles | K29: 1 | L29: 104 | M29: 9 | N29: 14 | O29: 6 | P29: 22.91847 | Q29: 0.04363293 | R29: 9 | S29: =IF(AND(ISNUMBER(R29),R29>1,P29>0),R29/P29-1,"") -> -0.60730363 | T29: =IF(AND(ISNUMBER(P29),P29>0),P29*EXP('Read me'!$B$22),"") -> 27.992682
A30: 2:35 | B30: Curragh | C30: Qatar Racing And Equestrian Club Renaissance Stakes (Group 3) | E30: 6 | F30: Heavy | G30: 8 | H30: East Hampton | I30: Colgan, R C | J30: Marnane, David | K30: 6 | L30: 104 | M30: 4 | N30: 37 | O30: 7 | P30: 31.253591 | Q30: 0.031996323 | R30: 19 | S30: =IF(AND(ISNUMBER(R30),R30>1,P30>0),R30/P30-1,"") -> -0.39206987 | T30: =IF(AND(ISNUMBER(P30),P30>0),P30*EXP('Read me'!$B$22),"") -> 38.173223
A31: 2:35 | B31: Curragh | C31: Qatar Racing And Equestrian Club Renaissance Stakes (Group 3) | E31: 6 | F31: Heavy | G31: 8 | H31: Tango Flare (IRE) | I31: McAteer, L T | J31: Foley, Patrick T | K31: 3 | L31: 96 | M31: 7 | N31: 14 | O31: 8 | P31: 44.633301 | Q31: 0.022404796 | R31: 34 | S31: =IF(AND(ISNUMBER(R31),R31>1,P31>0),R31/P31-1,"") -> -0.23823693 | T31: =IF(AND(ISNUMBER(P31),P31>0),P31*EXP('Read me'!$B$22),"") -> 54.515237
A32: 3:10 | B32: Curragh | C32: Celebrating County Kildare And Lexington Twinning Maiden | E32: 6 | F32: Heavy | G32: 12 | H32: Valentino Eclipse (IRE) | I32: Heffernan, J A | J32: Stack, J A | K32: 11 | L32: 0 | M32: 3 | N32: 93 | O32: 1 | P32: 2.4347683 | Q32: 0.4107167 | R32: 1.7272727 | S32: =IF(AND(ISNUMBER(R32),R32>1,P32>0),R32/P32-1,"") -> -0.29058024 | T32: =IF(AND(ISNUMBER(P32),P32>0),P32*EXP('Read me'!$B$22),"") -> 2.9738327
A33: 3:10 | B33: Curragh | C33: Celebrating County Kildare And Lexington Twinning Maiden | E33: 6 | F33: Heavy | G33: 12 | H33: A Good Yarn (IRE) | I33: Lordan, W M | J33: Howard, Aidan Anthony | K33: 1 | L33: 0 | M33: 3 | N33: 161 | O33: 2 | P33: 3.5987295 | Q33: 0.27787584 | R33: 3.5 | S33: =IF(AND(ISNUMBER(R33),R33>1,P33>0),R33/P33-1,"") -> -0.027434553 | T33: =IF(AND(ISNUMBER(P33),P33>0),P33*EXP('Read me'!$B$22),"") -> 4.3954982
A34: 3:10 | B34: Curragh | C34: Celebrating County Kildare And Lexington Twinning Maiden | E34: 6 | F34: Heavy | G34: 12 | H34: Tourin (IRE) | I34: Ryan, Gavin | J34: Stack, J A | K34: 12 | L34: 0 | M34: 3 | N34: 26 | O34: 3 | P34: 7.1742156 | Q34: 0.13938806 | R34: 9 | S34: =IF(AND(ISNUMBER(R34),R34>1,P34>0),R34/P34-1,"") -> 0.25449254 | T34: =IF(AND(ISNUMBER(P34),P34>0),P34*EXP('Read me'!$B$22),"") -> 8.7626068
A35: 3:10 | B35: Curragh | C35: Celebrating County Kildare And Lexington Twinning Maiden | E35: 6 | F35: Heavy | G35: 12 | H35: The Hidden Garden (IRE) | I35: McDonogh, D P | J35: Harty, Edward and Patrick | K35: 13 | L35: 0 | M35: 3 | O35: 4 | P35: 14.010672 | Q35: 0.071374163 | R35: 26 | S35: =IF(AND(ISNUMBER(R35),R35>1,P35>0),R35/P35-1,"") -> 0.85572823 | T35: =IF(AND(ISNUMBER(P35),P35>0),P35*EXP('Read me'!$B$22),"") -> 17.112674
A36: 3:10 | B36: Curragh | C36: Celebrating County Kildare And Lexington Twinning Maiden | E36: 6 | F36: Heavy | G36: 12 | H36: Saga Lucia (IRE) | I36: Holohan, Reese | J36: OCallaghan, M D | K36: 6 | L36: 73 | M36: 3 | N36: 37 | O36: 5 | P36: 34.106586 | Q36: 0.029319851 | R36: 13 | S36: =IF(AND(ISNUMBER(R36),R36>1,P36>0),R36/P36-1,"") -> -0.61884194 | T36: =IF(AND(ISNUMBER(P36),P36>0),P36*EXP('Read me'!$B$22),"") -> 41.657878
A37: 3:10 | B37: Curragh | C37: Celebrating County Kildare And Lexington Twinning Maiden | E37: 6 | F37: Heavy | G37: 12 | H37: Port Arthur (IRE) | I37: Colgan, R C | J37: Grassick, M C | K37: 7 | L37: 74 | M37: 3 | N37: 12 | O37: 6 | P37: 35.727312 | Q37: 0.027989791 | R37: 21 | S37: =IF(AND(ISNUMBER(R37),R37>1,P37>0),R37/P37-1,"") -> -0.41221439 | T37: =IF(AND(ISNUMBER(P37),P37>0),P37*EXP('Read me'!$B$22),"") -> 43.637438
A38: 3:10 | B38: Curragh | C38: Celebrating County Kildare And Lexington Twinning Maiden | E38: 6 | F38: Heavy | G38: 12 | H38: Caislean Ni Cuan (IRE) | I38: McCullagh, N G | J38: Mullins, Thomas | K38: 2 | L38: 57 | M38: 3 | N38: 36 | O38: 7 | P38: 40.791335 | Q38: 0.02451501 | R38: 23 | S38: =IF(AND(ISNUMBER(R38),R38>1,P38>0),R38/P38-1,"") -> -0.43615476 | T38: =IF(AND(ISNUMBER(P38),P38>0),P38*EXP('Read me'!$B$22),"") -> 49.822649
A39: 3:10 | B39: Curragh | C39: Celebrating County Kildare And Lexington Twinning Maiden | E39: 6 | F39: Heavy | G39: 12 | H39: Tribal Belle (IRE) | I39: Hayes, C D | J39: Bunyan, Darren / OLeary, G | K39: 4 | L39: 0 | M39: 3 | N39: 26 | O39: 8 | P39: 107.1561 | Q39: 0.0093321802 | R39: 34 | S39: =IF(AND(ISNUMBER(R39),R39>1,P39>0),R39/P39-1,"") -> -0.68270587 | T39: =IF(AND(ISNUMBER(P39),P39>0),P39*EXP('Read me'!$B$22),"") -> 130.88075
A40: 3:10 | B40: Curragh | C40: Celebrating County Kildare And Lexington Twinning Maiden | E40: 6 | F40: Heavy | G40: 12 | H40: Gaineamh Min (IRE) | I40: Joyce, Wesley | J40: Byrne, Sean | K40: 10 | L40: 0 | M40: 3 | N40: 23 | O40: 9 | P40: 265.76376 | Q40: 0.0037627403 | R40: 41 | S40: =IF(AND(ISNUMBER(R40),R40>1,P40>0),R40/P40-1,"") -> -0.84572765 | T40: =IF(AND(ISNUMBER(P40),P40>0),P40*EXP('Read me'!$B$22),"") -> 324.60458
...

Sheet Epsom
A1: Time | B1: Course | C1: Race | D1: Class | E1: Furlongs | F1: Going | G1: Runners | H1: Horse | I1: Jockey | J1: Trainer | K1: Draw | L1: OR | M1: Age | N1: Days since run | O1: Model rank | P1: Predicted BSP | Q1: Win probability | R1: Card odds (HRB) | S1: Card odds vs model | T1: Rule: back at Betfair ≥
A2: 1:37 | B2: Epsom | C2: Betfred Turbo Boost Nursery | D2: Class 4 | E2: 7 | F2: Good | G2: 8 | H2: Regal Tiger | I2: Murphy, Oisin | J2: Palmer, Hugo | K2: 7 | L2: 73 | M2: 2 | N2: 69 | O2: 1 | P2: 4.5975127 | Q2: 0.21750892 | R2: 5.5 | S2: =IF(AND(ISNUMBER(R2),R2>1,P2>0),R2/P2-1,"") -> 0.19629903 | T2: =IF(AND(ISNUMBER(P2),P2>0),P2*EXP('Read me'!$B$22),"") -> 5.6154147
A3: 1:37 | B3: Epsom | C3: Betfred Turbo Boost Nursery | D3: Class 4 | E3: 7 | F3: Good | G3: 8 | H3: Give Hand (IRE) | I3: Edmunds, Lewis | J3: Charlton, Roger/Harry | K3: 3 | L3: 76 | M3: 2 | N3: 17 | O3: 2 | P3: 5.8202093 | Q3: 0.17181513 | R3: 3.5 | S3: =IF(AND(ISNUMBER(R3),R3>1,P3>0),R3/P3-1,"") -> -0.39864706 | T3: =IF(AND(ISNUMBER(P3),P3>0),P3*EXP('Read me'!$B$22),"") -> 7.1088197
A4: 1:37 | B4: Epsom | C4: Betfred Turbo Boost Nursery | D4: Class 4 | E4: 7 | F4: Good | G4: 8 | H4: The Ginger Kid (IRE) | I4: Lewis, Ashley | J4: Walker, Ed | K4: 9 | L4: 83 | M4: 2 | N4: 38 | O4: 3 | P4: 6.2737356 | Q4: 0.15939467 | R4: 4.5 | S4: =IF(AND(ISNUMBER(R4),R4>1,P4>0),R4/P4-1,"") -> -0.28272399 | T4: =IF(AND(ISNUMBER(P4),P4>0),P4*EXP('Read me'!$B$22),"") -> 7.662758
A5: 1:37 | B5: Epsom | C5: Betfred Turbo Boost Nursery | D5: Class 4 | E5: 7 | F5: Good | G5: 8 | H5: Telegraphic | I5: Loughnane, Billy | J5: Johnston, Charlie | K5: 8 | L5: 80 | M5: 2 | N5: 38 | O5: 4 | P5: 8.7453849 | Q5: 0.11434603 | R5: 6.5 | S5: =IF(AND(ISNUMBER(R5),R5>1,P5>0),R5/P5-1,"") -> -0.25675084 | T5: =IF(AND(ISNUMBER(P5),P5>0),P5*EXP('Read me'!$B$22),"") -> 10.681637
A6: 1:37 | B6: Epsom | C6: Betfred Turbo Boost Nursery | D6: Class 4 | E6: 7 | F6: Good | G6: 8 | H6: Rogue Imperial | I6: Ryan, Rossa | J6: Watson, Archie | K6: 5 | L6: 78 | M6: 2 | N6: 34 | O6: 5 | P6: 9.1388947 | Q6: 0.10942242 | R6: 17 | S6: =IF(AND(ISNUMBER(R6),R6>1,P6>0),R6/P6-1,"") -> 0.86018119 | T6: =IF(AND(ISNUMBER(P6),P6>0),P6*EXP('Read me'!$B$22),"") -> 11.162271
A7: 1:37 | B7: Epsom | C7: Betfred Turbo Boost Nursery | D7: Class 4 | E7: 7 | F7: Good | G7: 8 | H7: Clive The Writer (IRE) | I7: Crouch, Hector | J7: Muir, W R & Grassick, C | K7: 1 | L7: 78 | M7: 2 | N7: 16 | O7: 6 | P7: 9.3350044 | Q7: 0.10712368 | R7: 9.5 | S7: =IF(AND(ISNUMBER(R7),R7>1,P7>0),R7/P7-1,"") -> 0.017674937 | T7: =IF(AND(ISNUMBER(P7),P7>0),P7*EXP('Read me'!$B$22),"") -> 11.4018
A8: 1:37 | B8: Epsom | C8: Betfred Turbo Boost Nursery | D8: Class 4 | E8: 7 | F8: Good | G8: 8 | H8: Angel Of Desire | I8: Fallon, Cieren | J8: Perrett, Mrs A J | K8: 6 | L8: 71 | M8: 2 | N8: 27 | O8: 7 | P8: 13.811546 | Q8: 0.07240319 | R8: 11 | S8: =IF(AND(ISNUMBER(R8),R8>1,P8>0),R8/P8-1,"") -> -0.20356492 | T8: =IF(AND(ISNUMBER(P8),P8>0),P8*EXP('Read me'!$B$22),"") -> 16.869461
A9: 1:37 | B9: Epsom | C9: Betfred Turbo Boost Nursery | D9: Class 4 | E9: 7 | F9: Good | G9: 8 | H9: Leucothea (IRE) | I9: Levey, S M | J9: Hannon (Jnr), Richard | K9: 2 | L9: 71 | M9: 2 | N9: 17 | O9: 8 | P9: 20.839422 | Q9: 0.047985976 | R9: 19 | S9: =IF(AND(ISNUMBER(R9),R9>1,P9>0),R9/P9-1,"") -> -0.088266455 | T9: =IF(AND(ISNUMBER(P9),P9>0),P9*EXP('Read me'!$B$22),"") -> 25.453327
A10: 2:12 | B10: Epsom | C10: Betfred Derby Wild Card EBF Conditions Stakes (GBB/GBBPlus Race) | D10: Class 2 | E10: 8.5 | F10: Good | G10: 5 | H10: Rose Moon (GER) | I10: Ryan, Rossa | J10: Beckett, R M | K10: 5 | L10: 0 | M10: 2 | N10: 24 | O10: 1 | P10: 3.3125625 | Q10: 0.3018811 | R10: 2.375 | S10: =IF(AND(ISNUMBER(R10),R10>1,P10>0),R10/P10-1,"") -> -0.28303239 | T10: =IF(AND(ISNUMBER(P10),P10>0),P10*EXP('Read me'!$B$22),"") -> 4.0459729
A11: 2:12 | B11: Epsom | C11: Betfred Derby Wild Card EBF Conditions Stakes (GBB/GBBPlus Race) | D11: Class 2 | E11: 8.5 | F11: Good | G11: 5 | H11: Al Wathba (FR) | I11: Loughnane, Billy | J11: Appleby, Charlie | K11: 4 | L11: 89 | M11: 2 | N11: 17 | O11: 2 | P11: 3.524514 | Q11: 0.28372706 | R11: 4 | S11: =IF(AND(ISNUMBER(R11),R11>1,P11>0),R11/P11-1,"") -> 0.13490825 | T11: =IF(AND(ISNUMBER(P11),P11>0),P11*EXP('Read me'!$B$22),"") -> 4.3048511
