Workbook

Sheet Read me
A1: Predictions for 2026-09-26
A3: Runners | B3: 575
A4: Races | B4: 53
A5: Meetings | B5: 7
A7: The model | B7: 944
A8: Features | B8: 944
A9: Trained through | B9: 2026-09-22
A10: Boosting rounds | B10: 6000
A11: Target | B11: logit_norm_prob
A12: Feature code hash | B12: f879b10c8369467a
A14: How to read it
A15: Predicted BSP | B15: The model's forecast of the Betfair Starting Price, from pre-race information only. The prices in each race make a book of exactly 100%.
A16: Win probability | B16: 1 / predicted BSP: the model's chance for the horse, normalised within the race.
A17: Model rank | B17: 1 = the model's shortest price in the race (highlighted green).
A18: Card odds (HRB) | B18: The odds printed on the horseracebase card when it was fetched: a bookmaker forecast, not the Betfair morning price the early-price rule was tested against.
A19: Card odds vs model | B19: Card odds / predicted BSP - 1. Positive: the card is longer than the model.
A21: The early-price rule
A22: Margin (log) | B22: 0.2
A23: Rule: back at Betfair ≥ | B23: Predicted BSP × e^margin: at 0.2, a Betfair price at least 1.22 times the model's (the model at least 22% shorter). The rule was fixed before it was first tested (reports/clv_betfair_2026q1.md): back at Betfair's morning volume-weighted price, where at least £100 has been matched in the morning, and close the position at BSP (lay at BSP to level the book). It is a trade on the price, not a bet held to the result. The margin (blue) is the one input: change it to see the prices at another threshold.
A25: Note | B25: The 944: the model recommended to serve from 27 Sep (reports/serving_note_2026-09-27.md), priced here by predict-now run 12 on the card fetched at 09:44 UTC (575 runners in 53 races; non-runners declared by then are out, and each race's book is 100% of those left). It is not yet the served model: the 06:00 job priced today with the 615, whose picks are on the '944 vs 615' sheet. Out of sample (Jan-Mar 2026), the 944's early-price rule returned +8.44% per trade (90% interval +7.17 to +9.82) on 4,602 trades, traded out at BSP and net of commission; its top pick traded out at BSP +1.19% (+0.44 to +1.96), and +5.18% where the rule also picks it. Held to the result, the top pick lost (-7.56% at BSP): the edge is in the price, not the result. The rule's forward test (pre-registered, from 25 Sep) has not reported yet.

Sheet Top picks
A1: Time | B1: Course | C1: Race | D1: Runners | E1: Top pick | F1: Jockey | G1: Trainer | H1: Predicted BSP | I1: Win probability | J1: Second choice | K1: Second's BSP | L1: Second's probability | M1: Probability gap | N1: Card odds (HRB) | O1: Rule: back at Betfair ≥
A2: 1:22 | B2: Newmarket (Rowley) | C2: British Stallion Studs EBF Jersey Lily Fillies Nursery | D2: 10 | E2: Al Samsama (IRE) | F2: Loughnane, Billy | G2: Hughes, Richard | H2: 5.4223912 | I2: 0.18442048 | J2: Next Of Kin | K2: 7.3693735 | L2: 0.13569675 | M2: =IF(AND(ISNUMBER(I2),ISNUMBER(L2)),I2-L2,"") -> 0.048723738 | N2: 7.5 | O2: =IF(AND(ISNUMBER(H2),H2>0),H2*EXP('Read me'!$B$22),"") -> 6.6229235
A3: 1:30 | B3: Curragh | C3: Market Square Monasterevin Irish European Breeders Fund Maiden | D3: 13 | E3: Benown (IRE) | F3: Sheridan, J M | G3: OBrien, Joseph Patrick | H3: 1.9022607 | I3: 0.52569029 | J3: Heralds March (IRE) | K3: 5.3234689 | L3: 0.18784744 | M3: =IF(AND(ISNUMBER(I3),ISNUMBER(L3)),I3-L3,"") -> 0.33784285 | N3: 1.7272727 | O3: =IF(AND(ISNUMBER(H3),H3>0),H3*EXP('Read me'!$B$22),"") -> 2.3234265
A4: 1:35 | B4: Haydock | C4: William Hill Epic Boosts Handicap | D4: 10 | E4: Eternal Force | F4: Fallon, Cieren | G4: Haggas, W J | H4: 5.2683602 | I4: 0.18981238 | J4: Centigrade (IRE) | K4: 5.8434044 | L4: 0.17113311 | M4: =IF(AND(ISNUMBER(I4),ISNUMBER(L4)),I4-L4,"") -> 0.018679269 | N4: 4.5 | O4: =IF(AND(ISNUMBER(H4),H4>0),H4*EXP('Read me'!$B$22),"") -> 6.4347896
A5: 1:44 | B5: Ripon | C5: Theakston Brewing Legends Since 1827 EBF Novice Stakes (GBB Race) | D5: 9 | E5: Scenic Route (IRE) | F5: Orr, Oisin | G5: Fahey, R A | H5: 2.1969837 | I5: 0.45516951 | J5: Bulletsnap (IRE) | K5: 2.6507783 | L5: 0.37724769 | M5: =IF(AND(ISNUMBER(I5),ISNUMBER(L5)),I5-L5,"") -> 0.077921817 | N5: 1.9090909 | O5: =IF(AND(ISNUMBER(H5),H5>0),H5*EXP('Read me'!$B$22),"") -> 2.683402
A6: 1:55 | B6: Newmarket (Rowley) | C6: Tattersalls Online Royal Lodge Stakes (Group 2) | D6: 7 | E6: Haffner (USA) | F6: Moore, Ryan | G6: OBrien, A P | H6: 4.1555937 | I6: 0.2406395 | J6: First Law (IRE) | K6: 4.324806 | L6: 0.23122425 | M6: =IF(AND(ISNUMBER(I6),ISNUMBER(L6)),I6-L6,"") -> 0.0094152549 | N6: 4.5 | O6: =IF(AND(ISNUMBER(H6),H6>0),H6*EXP('Read me'!$B$22),"") -> 5.0756537
A7: 2:00 | B7: Curragh | C7: Kwiff More Bang For Your Bet Rated Race | D7: 9 | E7: Oro Blanco (IRE) | F7: Kennedy, K G | G7: Harrington, Mrs John | H7: 4.4337459 | I7: 0.22554292 | J7: Killashee Warrior | K7: 5.0561504 | L7: 0.19777893 | M7: =IF(AND(ISNUMBER(I7),ISNUMBER(L7)),I7-L7,"") -> 0.027763992 | N7: 3.75 | O7: =IF(AND(ISNUMBER(H7),H7>0),H7*EXP('Read me'!$B$22),"") -> 5.4153895
A8: 2:10 | B8: Haydock | C8: William Hill Best Odds Guaranteed Handicap | D8: 10 | E8: Trilby | F8: McDonald, P J | G8: England, Sam | H8: 4.5888249 | I8: 0.21792071 | J8: King Of Light | K8: 4.8875045 | L8: 0.20460339 | M8: =IF(AND(ISNUMBER(I8),ISNUMBER(L8)),I8-L8,"") -> 0.013317322 | N8: 3.25 | O8: =IF(AND(ISNUMBER(H8),H8>0),H8*EXP('Read me'!$B$22),"") -> 5.6048034
A9: 2:16 | B9: Ripon | C9: Lloyd Landrover Ripon Nursery (GBBPlus Race) | D9: 6 | E9: Aphra Behn | F9: Hart, Jason | G9: Beckett, R M | H9: 3.9137923 | I9: 0.25550666 | J9: Zarakova | K9: 4.3249916 | L9: 0.23121432 | M9: =IF(AND(ISNUMBER(I9),ISNUMBER(L9)),I9-L9,"") -> 0.02429234 | N9: 2.625 | O9: =IF(AND(ISNUMBER(H9),H9>0),H9*EXP('Read me'!$B$22),"") -> 4.7803167
A10: 2:27 | B10: Newmarket (Rowley) | C10: Tattersalls Sceptre Sessions Cheveley Park Stakes (Fillies Group 1) | D10: 6 | E10: Sun Goddess (IRE) | F10: Moore, Ryan | G10: OBrien, A P | H10: 1.8278127 | I10: 0.547102 | J10: Libertango (IRE) | K10: 6.5055108 | L10: 0.15371583 | M10: =IF(AND(ISNUMBER(I10),ISNUMBER(L10)),I10-L10,"") -> 0.39338617 | N10: 2.5 | O10: =IF(AND(ISNUMBER(H10),H10>0),H10*EXP('Read me'!$B$22),"") -> 2.2324955
A11: 2:30 | B11: Market Rasen | C11: Market Rasen Racecourse Conference & Events Mares Maiden Hurdle (GBB Race) | D11: 9 | E11: Elated | F11: Jones, Ben R | G11: Pauling, Ben | H11: 1.7522701 | I11: 0.57068828 | J11: No More Teardrops | K11: 3.6316584 | L11: 0.2753563 | M11: =IF(AND(ISNUMBER(I11),ISNUMBER(L11)),I11-L11,"") -> 0.29533199 | N11: 2.2 | O11: =IF(AND(ISNUMBER(H11),H11>0),H11*EXP('Read me'!$B$22),"") -> 2.1402275
A12: 2:35 | B12: Curragh | C12: Kwiff Supercharged Joe McGrath Handicap (Premier Handicap) | D12: 20 | E12: Red Evolution (IRE) | F12: Holohan, Reese | G12: OCallaghan, M D | H12: 6.6003902 | I12: 0.15150619 | J12: Dark Ace (IRE) | K12: 8.7366641 | L12: 0.11446016 | M12: =IF(AND(ISNUMBER(I12),ISNUMBER(L12)),I12-L12,"") -> 0.037046032 | N12: 5.5 | O12: =IF(AND(ISNUMBER(H12),H12>0),H12*EXP('Read me'!$B$22),"") -> 8.0617348
A13: 2:40 | B13: Haydock | C13: British EBF Fillies Novice Stakes (GBB Race) | D13: 9 | E13: Kaguyahime (IRE) | F13: Bowen, S D | G13: Varian, Roger | H13: 2.5250319 | I13: 0.3960346 | J13: My Girl Dee Mo (IRE) | K13: 7.0988927 | L13: 0.14086704 | M13: =IF(AND(ISNUMBER(I13),ISNUMBER(L13)),I13-L13,"") -> 0.25516756 | N13: 1.7272727 | O13: =IF(AND(ISNUMBER(H13),H13>0),H13*EXP('Read me'!$B$22),"") -> 3.0840809
... A54: 8:30 | B54: Southwell | C54: Golf & Gallop Southwell Golf Club Handicap | D54: 13 | E54: Massimo Blue | F54: Callan, Jack | G54: Cunha, Dylan | H54: 4.352474 | I54: 0.22975439 | J54: Ormolulu (IRE) | K54: 6.1152374 | L54: 0.16352595 | M54: =IF(AND(ISNUMBER(I54),ISNUMBER(L54)),I54-L54,"") -> 0.066228438 | N54: 3.25 | O54: =IF(AND(ISNUMBER(H54),H54>0),H54*EXP('Read me'!$B$22),"") -> 5.3161238

Sheet 944 vs 615
A1: Time | B1: Course | C1: Race | D1: Runners (now) | E1: 944 top pick | F1: 944 BSP | G1: Its 615 BSP | H1: 615 top pick (runners still declared) | I1: 615 BSP | J1: Same pick? | K1: 944 vs 615 on the 944's pick
A2: 1:22 | B2: Newmarket (Rowley) | C2: British Stallion Studs EBF Jersey Lily Fillies Nursery | D2: 10 | E2: Al Samsama (IRE) | F2: 5.4223912 | G2: 5.0320897 | H2: Al Samsama (IRE) | I2: 5.0320897 | J2: =IF(E2=H2,"yes","no") -> yes | K2: =IF(AND(ISNUMBER(F2),ISNUMBER(G2)),F2/G2-1,"") -> 0.077562512
A3: 1:30 | B3: Curragh | C3: Market Square Monasterevin Irish European Breeders Fund Maiden | D3: 13 | E3: Benown (IRE) | F3: 1.9022607 | G3: 1.8188856 | H3: Benown (IRE) | I3: 1.8188856 | J3: =IF(E3=H3,"yes","no") -> yes | K3: =IF(AND(ISNUMBER(F3),ISNUMBER(G3)),F3/G3-1,"") -> 0.045838587
A4: 1:35 | B4: Haydock | C4: William Hill Epic Boosts Handicap | D4: 10 | E4: Eternal Force | F4: 5.2683602 | G4: 5.0720579 | H4: Eternal Force | I4: 5.0720579 | J4: =IF(E4=H4,"yes","no") -> yes | K4: =IF(AND(ISNUMBER(F4),ISNUMBER(G4)),F4/G4-1,"") -> 0.038702687
A5: 1:44 | B5: Ripon | C5: Theakston Brewing Legends Since 1827 EBF Novice Stakes (GBB Race) | D5: 9 | E5: Scenic Route (IRE) | F5: 2.1969837 | G5: 2.3162732 | H5: Scenic Route (IRE) | I5: 2.3162732 | J5: =IF(E5=H5,"yes","no") -> yes | K5: =IF(AND(ISNUMBER(F5),ISNUMBER(G5)),F5/G5-1,"") -> -0.051500622
A6: 1:55 | B6: Newmarket (Rowley) | C6: Tattersalls Online Royal Lodge Stakes (Group 2) | D6: 7 | E6: Haffner (USA) | F6: 4.1555937 | G6: 4.0725504 | H6: Haffner (USA) | I6: 4.0725504 | J6: =IF(E6=H6,"yes","no") -> yes | K6: =IF(AND(ISNUMBER(F6),ISNUMBER(G6)),F6/G6-1,"") -> 0.020390992
A7: 2:00 | B7: Curragh | C7: Kwiff More Bang For Your Bet Rated Race | D7: 9 | E7: Oro Blanco (IRE) | F7: 4.4337459 | G7: 5.5956726 | H7: Lewis Carroll (IRE) | I7: 4.302178 | J7: =IF(E7=H7,"yes","no") -> no | K7: =IF(AND(ISNUMBER(F7),ISNUMBER(G7)),F7/G7-1,"") -> -0.20764736
A8: 2:10 | B8: Haydock | C8: William Hill Best Odds Guaranteed Handicap | D8: 10 | E8: Trilby | F8: 4.5888249 | G8: 5.5491618 | H8: King Of Light | I8: 4.8977923 | J8: =IF(E8=H8,"yes","no") -> no | K8: =IF(AND(ISNUMBER(F8),ISNUMBER(G8)),F8/G8-1,"") -> -0.17305981
A9: 2:16 | B9: Ripon | C9: Lloyd Landrover Ripon Nursery (GBBPlus Race) | D9: 6 | E9: Aphra Behn | F9: 3.9137923 | G9: 3.8802742 | H9: Aphra Behn | I9: 3.8802742 | J9: =IF(E9=H9,"yes","no") -> yes | K9: =IF(AND(ISNUMBER(F9),ISNUMBER(G9)),F9/G9-1,"") -> 0.0086380832
A10: 2:27 | B10: Newmarket (Rowley) | C10: Tattersalls Sceptre Sessions Cheveley Park Stakes (Fillies Group 1) | D10: 6 | E10: Sun Goddess (IRE) | F10: 1.8278127 | G10: 1.5874357 | H10: Sun Goddess (IRE) | I10: 1.5874357 | J10: =IF(E10=H10,"yes","no") -> yes | K10: =IF(AND(ISNUMBER(F10),ISNUMBER(G10)),F10/G10-1,"") -> 0.1514247
A11: 2:30 | B11: Market Rasen | C11: Market Rasen Racecourse Conference & Events Mares Maiden Hurdle (GBB Race) | D11: 9 | E11: Elated | F11: 1.7522701 | G11: 1.8536781 | H11: Elated | I11: 1.8536781 | J11: =IF(E11=H11,"yes","no") -> yes | K11: =IF(AND(ISNUMBER(F11),ISNUMBER(G11)),F11/G11-1,"") -> -0.054706397
A12: 2:35 | B12: Curragh | C12: Kwiff Supercharged Joe McGrath Handicap (Premier Handicap) | D12: 20 | E12: Red Evolution (IRE) | F12: 6.6003902 | G12: 6.5999215 | H12: Red Evolution (IRE) | I12: 6.5999215 | J12: =IF(E12=H12,"yes","no") -> yes | K12: =IF(AND(ISNUMBER(F12),ISNUMBER(G12)),F12/G12-1,"") -> 7.1018879e-05
A13: 2:40 | B13: Haydock | C13: British EBF Fillies Novice Stakes (GBB Race) | D13: 9 | E13: Kaguyahime (IRE) | F13: 2.5250319 | G13: 2.6092316 | H13: Kaguyahime (IRE) | I13: 2.6092316 | J13: =IF(E13=H13,"yes","no") -> yes | K13: =IF(AND(ISNUMBER(F13),ISNUMBER(G13)),F13/G13-1,"") -> -0.032269937
... A54: 8:30 | B54: Southwell | C54: Golf & Gallop Southwell Golf Club Handicap | D54: 13 | E54: Massimo Blue | F54: 4.352474 | G54: 4.5114719 | H54: Massimo Blue | I54: 4.5114719 | J54: =IF(E54=H54,"yes","no") -> yes | K54: =IF(AND(ISNUMBER(F54),ISNUMBER(G54)),F54/G54-1,"") -> -0.035243011
A56: Races with the same top pick | E56: =COUNTIF(J2:J54,"yes")&" of "&COUNTA(J2:J54) -> 44 of 53
A57: The 615's prices are this morning's 06:00 record (Daily Predictions run 197, the forward test's file); the 944's are from the card fetched at 09:44 UTC, so a race that lost a runner since 06:00 is priced on the smaller field.

Sheet All runners
A1: Time | B1: Course | C1: Race | D1: Class | E1: Furlongs | F1: Going | G1: Runners | H1: Horse | I1: Jockey | J1: Trainer | K1: Draw | L1: OR | M1: Age | N1: Days since run | O1: Model rank | P1: Predicted BSP | Q1: Win probability | R1: Card odds (HRB) | S1: Card odds vs model | T1: Rule: back at Betfair ≥
A2: 1:22 | B2: Newmarket (Rowley) | C2: British Stallion Studs EBF Jersey Lily Fillies Nursery | D2: Class 2 | E2: 7 | F2: Good To Firm | G2: 10 | H2: Al Samsama (IRE) | I2: Loughnane, Billy | J2: Hughes, Richard | K2: 2 | L2: 85 | M2: 2 | N2: 18 | O2: 1 | P2: 5.4223912 | Q2: 0.18442048 | R2: 7.5 | S2: =IF(AND(ISNUMBER(R2),R2>1,P2>0),R2/P2-1,"") -> 0.38315362 | T2: =IF(AND(ISNUMBER(P2),P2>0),P2*EXP('Read me'!$B$22),"") -> 6.6229235
A3: 1:22 | B3: Newmarket (Rowley) | C3: British Stallion Studs EBF Jersey Lily Fillies Nursery | D3: Class 2 | E3: 7 | F3: Good To Firm | G3: 10 | H3: Next Of Kin | I3: Marquand, Tom | J3: Haggas, W J | K3: 3 | L3: 76 | M3: 2 | N3: 8 | O3: 2 | P3: 7.3693735 | Q3: 0.13569675 | R3: 8.5 | S3: =IF(AND(ISNUMBER(R3),R3>1,P3>0),R3/P3-1,"") -> 0.15342234 | T3: =IF(AND(ISNUMBER(P3),P3>0),P3*EXP('Read me'!$B$22),"") -> 9.0009731
A4: 1:22 | B4: Newmarket (Rowley) | C4: British Stallion Studs EBF Jersey Lily Fillies Nursery | D4: Class 2 | E4: 7 | F4: Good To Firm | G4: 10 | H4: Zephyra | I4: Murphy, Oisin | J4: Botti, M | K4: 4 | L4: 77 | M4: 2 | N4: 10 | O4: 3 | P4: 7.8795883 | Q4: 0.12691018 | R4: 10 | S4: =IF(AND(ISNUMBER(R4),R4>1,P4>0),R4/P4-1,"") -> 0.26910183 | T4: =IF(AND(ISNUMBER(P4),P4>0),P4*EXP('Read me'!$B$22),"") -> 9.6241509
A5: 1:22 | B5: Newmarket (Rowley) | C5: British Stallion Studs EBF Jersey Lily Fillies Nursery | D5: Class 2 | E5: 7 | F5: Good To Firm | G5: 10 | H5: Marsala (IRE) | I5: Ryan, Rossa | J5: Beckett, R M | K5: 6 | L5: 74 | M5: 2 | N5: 22 | O5: 4 | P5: 8.3992734 | Q5: 0.11905792 | R5: 7 | S5: =IF(AND(ISNUMBER(R5),R5>1,P5>0),R5/P5-1,"") -> -0.16659457 | T5: =IF(AND(ISNUMBER(P5),P5>0),P5*EXP('Read me'!$B$22),"") -> 10.258896
A6: 1:22 | B6: Newmarket (Rowley) | C6: British Stallion Studs EBF Jersey Lily Fillies Nursery | D6: Class 2 | E6: 7 | F6: Good To Firm | G6: 10 | H6: Fire Thunder (IRE) | I6: Sousa, Silvestre De | J6: Botti, M | K6: 8 | L6: 70 | M6: 2 | N6: 42 | O6: 5 | P6: 9.2469802 | Q6: 0.10814341 | R6: 4.5 | S6: =IF(AND(ISNUMBER(R6),R6>1,P6>0),R6/P6-1,"") -> -0.51335464 | T6: =IF(AND(ISNUMBER(P6),P6>0),P6*EXP('Read me'!$B$22),"") -> 11.294287
A7: 1:22 | B7: Newmarket (Rowley) | C7: British Stallion Studs EBF Jersey Lily Fillies Nursery | D7: Class 2 | E7: 7 | F7: Good To Firm | G7: 10 | H7: Bymiddaytomorrow (IRE) | I7: Lee, Clifford | J7: Walker, Ed | K7: 9 | L7: 82 | M7: 2 | N7: 16 | O7: 6 | P7: 10.374905 | Q7: 0.096386429 | R7: 9.5 | S7: =IF(AND(ISNUMBER(R7),R7>1,P7>0),R7/P7-1,"") -> -0.084328923 | T7: =IF(AND(ISNUMBER(P7),P7>0),P7*EXP('Read me'!$B$22),"") -> 12.671937
A8: 1:22 | B8: Newmarket (Rowley) | C8: British Stallion Studs EBF Jersey Lily Fillies Nursery | D8: Class 2 | E8: 7 | F8: Good To Firm | G8: 10 | H8: Polyxena (IRE) | I8: Ghiani, Marco | J8: Williams, S C | K8: 1 | L8: 82 | M8: 2 | N8: 19 | O8: 7 | P8: 11.21555 | Q8: 0.089161921 | R8: 7 | S8: =IF(AND(ISNUMBER(R8),R8>1,P8>0),R8/P8-1,"") -> -0.37586655 | T8: =IF(AND(ISNUMBER(P8),P8>0),P8*EXP('Read me'!$B$22),"") -> 13.698704
A9: 1:22 | B9: Newmarket (Rowley) | C9: British Stallion Studs EBF Jersey Lily Fillies Nursery | D9: Class 2 | E9: 7 | F9: Good To Firm | G9: 10 | H9: Tansy Lane | I9: Havlin, Robert | J9: Owen, J P | K9: 7 | L9: 74 | M9: 2 | N9: 43 | O9: 8 | P9: 11.866381 | Q9: 0.084271692 | R9: 13 | S9: =IF(AND(ISNUMBER(R9),R9>1,P9>0),R9/P9-1,"") -> 0.095531993 | T9: =IF(AND(ISNUMBER(P9),P9>0),P9*EXP('Read me'!$B$22),"") -> 14.49363
A10: 1:22 | B10: Newmarket (Rowley) | C10: British Stallion Studs EBF Jersey Lily Fillies Nursery | D10: Class 2 | E10: 7 | F10: Good To Firm | G10: 10 | H10: Kiah (IRE) | I10: Egan, David | J10: Meehan, B J | K10: 5 | L10: 76 | M10: 2 | N10: 30 | O10: 9 | P10: 34.251046 | Q10: 0.029196189 | R10: 13 | S10: =IF(AND(ISNUMBER(R10),R10>1,P10>0),R10/P10-1,"") -> -0.62044955 | T10: =IF(AND(ISNUMBER(P10),P10>0),P10*EXP('Read me'!$B$22),"") -> 41.834322
A11: 1:22 | B11: Newmarket (Rowley) | C11: British Stallion Studs EBF Jersey Lily Fillies Nursery | D11: Class 2 | E11: 7 | F11: Good To Firm | G11: 10 | H11: Tie A Navyribbon | I11: Gordon, Josephine | J11: Stone, W B | K11: 10 | L11: 80 | M11: 2 | N11: 16 | O11: 10 | P11: 37.376154 | Q11: 0.026755027 | R11: 29 | S11: =IF(AND(ISNUMBER(R11),R11>1,P11>0),R11/P11-1,"") -> -0.22410423 | T11: =IF(AND(ISNUMBER(P11),P11>0),P11*EXP('Read me'!$B$22),"") -> 45.651338
A12: 1:30 | B12: Curragh | C12: Market Square Monasterevin Irish European Breeders Fund Maiden | E12: 6 | F12: Good | G12: 13 | H12: Benown (IRE) | I12: Sheridan, J M | J12: OBrien, Joseph Patrick | K12: 14 | L12: 0 | M12: 2 | N12: 48 | O12: 1 | P12: 1.9022607 | Q12: 0.52569029 | R12: 1.7272727 | S12: =IF(AND(ISNUMBER(R12),R12>1,P12>0),R12/P12-1,"") -> -0.091989498 | T12: =IF(AND(ISNUMBER(P12),P12>0),P12*EXP('Read me'!$B$22),"") -> 2.3234265
A13: 1:30 | B13: Curragh | C13: Market Square Monasterevin Irish European Breeders Fund Maiden | E13: 6 | F13: Good | G13: 13 | H13: Heralds March (IRE) | I13: Keane, C T | J13: Lyons, G M | K13: 12 | L13: 0 | M13: 2 | N13: 35 | O13: 2 | P13: 5.3234689 | Q13: 0.18784744 | R13: 5.5 | S13: =IF(AND(ISNUMBER(R13),R13>1,P13>0),R13/P13-1,"") -> 0.033160919 | T13: =IF(AND(ISNUMBER(P13),P13>0),P13*EXP('Read me'!$B$22),"") -> 6.5020996
A14: 1:30 | B14: Curragh | C14: Market Square Monasterevin Irish European Breeders Fund Maiden | E14: 6 | F14: Good | G14: 13 | H14: Controlla (IRE) | I14: OConnor, Donagh | J14: Aguiar, Robson | K14: 11 | L14: 96 | M14: 2 | N14: 13 | O14: 3 | P14: 8.4672894 | Q14: 0.11810155 | R14: 3.25 | S14: =IF(AND(ISNUMBER(R14),R14>1,P14>0),R14/P14-1,"") -> -0.61616996 | T14: =IF(AND(ISNUMBER(P14),P14>0),P14*EXP('Read me'!$B$22),"") -> 10.341971
A15: 1:30 | B15: Curragh | C15: Market Square Monasterevin Irish European Breeders Fund Maiden | E15: 6 | F15: Good | G15: 13 | H15: Jungle Wise (IRE) | I15: Coen, Ben M | J15: Murphy, Daniel | K15: 8 | L15: 0 | M15: 2 | N15: 17 | O15: 4 | P15: 11.692526 | Q15: 0.085524719 | R15: 11 | S15: =IF(AND(ISNUMBER(R15),R15>1,P15>0),R15/P15-1,"") -> -0.059228091 | T15: =IF(AND(ISNUMBER(P15),P15>0),P15*EXP('Read me'!$B$22),"") -> 14.281283
A16: 1:30 | B16: Curragh | C16: Market Square Monasterevin Irish European Breeders Fund Maiden | E16: 6 | F16: Good | G16: 13 | H16: Shake It Out | I16: Whelan, R P | J16: Cotter, Kieran P | K16: 10 | L16: 0 | M16: 2 | O16: 5 | P16: 53.338562 | Q16: 0.018748162 | R16: 51 | S16: =IF(AND(ISNUMBER(R16),R16>1,P16>0),R16/P16-1,"") -> -0.043843731 | T16: =IF(AND(ISNUMBER(P16),P16>0),P16*EXP('Read me'!$B$22),"") -> 65.147866
A17: 1:30 | B17: Curragh | C17: Market Square Monasterevin Irish European Breeders Fund Maiden | E17: 6 | F17: Good | G17: 13 | H17: Moon Gypsy (IRE) | I17: Mulligan, R M | J17: Burns, J G | K17: 9 | L17: 0 | M17: 2 | O17: 6 | P17: 59.575275 | Q17: 0.016785487 | R17: 201 | S17: =IF(AND(ISNUMBER(R17),R17>1,P17>0),R17/P17-1,"") -> 2.3738829 | T17: =IF(AND(ISNUMBER(P17),P17>0),P17*EXP('Read me'!$B$22),"") -> 72.765406
A18: 1:30 | B18: Curragh | C18: Market Square Monasterevin Irish European Breeders Fund Maiden | E18: 6 | F18: Good | G18: 13 | H18: Katty (IRE) | I18: Heffernan, J A | J18: Sexton, Adrian | K18: 5 | L18: 0 | M18: 2 | N18: 37 | O18: 7 | P18: 62.059397 | Q18: 0.016113595 | R18: 29 | S18: =IF(AND(ISNUMBER(R18),R18>1,P18>0),R18/P18-1,"") -> -0.53270574 | T18: =IF(AND(ISNUMBER(P18),P18>0),P18*EXP('Read me'!$B$22),"") -> 75.799519
A19: 1:30 | B19: Curragh | C19: Market Square Monasterevin Irish European Breeders Fund Maiden | E19: 6 | F19: Good | G19: 13 | H19: Royal Sovereign (IRE) | I19: Joyce, Wesley | J19: Mulvany, Michael | K19: 3 | L19: 0 | M19: 2 | O19: 8 | P19: 91.538823 | Q19: 0.010924327 | R19: 51 | S19: =IF(AND(ISNUMBER(R19),R19>1,P19>0),R19/P19-1,"") -> -0.44285935 | T19: =IF(AND(ISNUMBER(P19),P19>0),P19*EXP('Read me'!$B$22),"") -> 111.80577
A20: 1:30 | B20: Curragh | C20: Market Square Monasterevin Irish European Breeders Fund Maiden | E20: 6 | F20: Good | G20: 13 | H20: Starlit (IRE) | I20: Kennedy, K G | J20: Harrington, Mrs John | K20: 7 | L20: 0 | M20: 2 | N20: 42 | O20: 9 | P20: 105.08303 | Q20: 0.0095162848 | R20: 26 | S20: =IF(AND(ISNUMBER(R20),R20>1,P20>0),R20/P20-1,"") -> -0.75257659 | T20: =IF(AND(ISNUMBER(P20),P20>0),P20*EXP('Read me'!$B$22),"") -> 128.3487
A21: 1:30 | B21: Curragh | C21: Market Square Monasterevin Irish European Breeders Fund Maiden | E21: 6 | F21: Good | G21: 13 | H21: Champion Basma (IRE) | I21: Hayes, C D | J21: ONeill, E J | K21: 2 | L21: 0 | M21: 2 | N21: 9 | O21: 10 | P21: 213.77245 | Q21: 0.0046778712 | R21: 67 | S21: =IF(AND(ISNUMBER(R21),R21>1,P21>0),R21/P21-1,"") -> -0.68658263 | T21: =IF(AND(ISNUMBER(P21),P21>0),P21*EXP('Read me'!$B$22),"") -> 261.10226
A22: 1:30 | B22: Curragh | C22: Market Square Monasterevin Irish European Breeders Fund Maiden | E22: 6 | F22: Good | G22: 13 | H22: Fen Phasee (IRE) | I22: Cleary, R P | J22: Davis, Sean | K22: 4 | L22: 0 | M22: 2 | O22: 11 | P22: 393.51875 | Q22: 0.002541175 | R22: 126 | S22: =IF(AND(ISNUMBER(R22),R22>1,P22>0),R22/P22-1,"") -> -0.67981195 | T22: =IF(AND(ISNUMBER(P22),P22>0),P22*EXP('Read me'!$B$22),"") -> 480.64489
A23: 1:30 | B23: Curragh | C23: Market Square Monasterevin Irish European Breeders Fund Maiden | E23: 6 | F23: Good | G23: 13 | H23: Ar Son Na Cuise (IRE) | I23: McDonogh, D P | J23: OBrien, Joseph Patrick | K23: 13 | L23: 0 | M23: 2 | N23: 17 | O23: 12 | P23: 402.27202 | Q23: 0.0024858801 | R23: 101 | S23: =IF(AND(ISNUMBER(R23),R23>1,P23>0),R23/P23-1,"") -> -0.74892611 | T23: =IF(AND(ISNUMBER(P23),P23>0),P23*EXP('Read me'!$B$22),"") -> 491.33615
A24: 1:30 | B24: Curragh | C24: Market Square Monasterevin Irish European Breeders Fund Maiden | E24: 6 | F24: Good | G24: 13 | H24: Brageiro (IRE) | I24: McAteer, L T | J24: OSullivan, Ross | K24: 1 | L24: 0 | M24: 2 | N24: 9 | O24: 13 | P24: 958.57182 | Q24: 0.0010432186 | R24: 201 | S24: =IF(AND(ISNUMBER(R24),R24>1,P24>0),R24/P24-1,"") -> -0.79031305 | T24: =IF(AND(ISNUMBER(P24),P24>0),P24*EXP('Read me'!$B$22),"") -> 1170.8023
A25: 1:35 | B25: Haydock | C25: William Hill Epic Boosts Handicap | D25: Class 2 | E25: 8 | F25: Heavy | G25: 10 | H25: Eternal Force | I25: Fallon, Cieren | J25: Haggas, W J | K25: 4 | L25: 96 | M25: 4 | N25: 37 | O25: 1 | P25: 5.2683602 | Q25: 0.18981238 | R25: 4.5 | S25: =IF(AND(ISNUMBER(R25),R25>1,P25>0),R25/P25-1,"") -> -0.14584427 | T25: =IF(AND(ISNUMBER(P25),P25>0),P25*EXP('Read me'!$B$22),"") -> 6.4347896
A26: 1:35 | B26: Haydock | C26: William Hill Epic Boosts Handicap | D26: Class 2 | E26: 8 | F26: Heavy | G26: 10 | H26: Centigrade (IRE) | I26: Crouch, Hector | J26: Beckett, R M | K26: 9 | L26: 100 | M26: 4 | N26: 10 | O26: 2 | P26: 5.8434044 | Q26: 0.17113311 | R26: 6.5 | S26: =IF(AND(ISNUMBER(R26),R26>1,P26>0),R26/P26-1,"") -> 0.11236525 | T26: =IF(AND(ISNUMBER(P26),P26>0),P26*EXP('Read me'!$B$22),"") -> 7.1371503
A27: 1:35 | B27: Haydock | C27: William Hill Epic Boosts Handicap | D27: Class 2 | E27: 8 | F27: Heavy | G27: 10 | H27: Looka (USA) | I27: Levey, S M | J27: Botti, M | K27: 3 | L27: 93 | M27: 3 | N27: 23 | O27: 3 | P27: 7.4300309 | Q27: 0.13458894 | R27: 7 | S27: =IF(AND(ISNUMBER(R27),R27>1,P27>0),R27/P27-1,"") -> -0.057877408 | T27: =IF(AND(ISNUMBER(P27),P27>0),P27*EXP('Read me'!$B$22),"") -> 9.0750603
A28: 1:35 | B28: Haydock | C28: William Hill Epic Boosts Handicap | D28: Class 2 | E28: 8 | F28: Heavy | G28: 10 | H28: Cerulean Bay (IRE) | I28: Tudhope, Daniel | J28: OMeara, D | K28: 1 | L28: 104 | M28: 5 | N28: 37 | O28: 4 | P28: 7.6360691 | Q28: 0.13095743 | R28: 7.5 | S28: =IF(AND(ISNUMBER(R28),R28>1,P28>0),R28/P28-1,"") -> -0.017819255 | T28: =IF(AND(ISNUMBER(P28),P28>0),P28*EXP('Read me'!$B$22),"") -> 9.3267158
A29: 1:35 | B29: Haydock | C29: William Hill Epic Boosts Handicap | D29: Class 2 | E29: 8 | F29: Heavy | G29: 10 | H29: Arctic Thunder (IRE) | I29: Lewis, Ashley | J29: Walker, Ed | K29: 10 | L29: 96 | M29: 5 | N29: 22 | O29: 5 | P29: 12.16776 | Q29: 0.082184395 | R29: 11 | S29: =IF(AND(ISNUMBER(R29),R29>1,P29>0),R29/P29-1,"") -> -0.095971651 | T29: =IF(AND(ISNUMBER(P29),P29>0),P29*EXP('Read me'!$B$22),"") -> 14.861736
A30: 1:35 | B30: Haydock | C30: William Hill Epic Boosts Handicap | D30: Class 2 | E30: 8 | F30: Heavy | G30: 10 | H30: Godwinson | I30: Probert, David | J30: Channon, Jack | K30: 5 | L30: 96 | M30: 6 | N30: 57 | O30: 6 | P30: 14.699878 | Q30: 0.068027777 | R30: 10 | S30: =IF(AND(ISNUMBER(R30),R30>1,P30>0),R30/P30-1,"") -> -0.31972223 | T30: =IF(AND(ISNUMBER(P30),P30>0),P30*EXP('Read me'!$B$22),"") -> 17.954471
A31: 1:35 | B31: Haydock | C31: William Hill Epic Boosts Handicap | D31: Class 2 | E31: 8 | F31: Heavy | G31: 10 | H31: Mister Winston | I31: McDonald, P J | J31: Balding, A M | K31: 6 | L31: 100 | M31: 4 | N31: 14 | O31: 7 | P31: 14.954557 | Q31: 0.06686925 | R31: 10 | S31: =IF(AND(ISNUMBER(R31),R31>1,P31>0),R31/P31-1,"") -> -0.3313075 | T31: =IF(AND(ISNUMBER(P31),P31>0),P31*EXP('Read me'!$B$22),"") -> 18.265537
A32: 1:35 | B32: Haydock | C32: William Hill Epic Boosts Handicap | D32: Class 2 | E32: 8 | F32: Heavy | G32: 10 | H32: Commanders Intent (FR) | I32: Rodriguez, Callum | J32: Scott, George | K32: 2 | L32: 100 | M32: 3 | N32: 163 | O32: 8 | P32: 17.48279 | Q32: 0.057199107 | R32: 10 | S32: =IF(AND(ISNUMBER(R32),R32>1,P32>0),R32/P32-1,"") -> -0.42800893 | T32: =IF(AND(ISNUMBER(P32),P32>0),P32*EXP('Read me'!$B$22),"") -> 21.353529
A33: 1:35 | B33: Haydock | C33: William Hill Epic Boosts Handicap | D33: Class 2 | E33: 8 | F33: Heavy | G33: 10 | H33: Desperate Dan (IRE) | I33: Wood, George | J33: Chapple-Hyam, P W | K33: 7 | L33: 85 | M33: 5 | N33: 106 | O33: 9 | P33: 18.929647 | Q33: 0.052827187 | R33: 23 | S33: =IF(AND(ISNUMBER(R33),R33>1,P33>0),R33/P33-1,"") -> 0.2150253 | T33: =IF(AND(ISNUMBER(P33),P33>0),P33*EXP('Read me'!$B$22),"") -> 23.120723
A34: 1:35 | B34: Haydock | C34: William Hill Epic Boosts Handicap | D34: Class 2 | E34: 8 | F34: Heavy | G34: 10 | H34: Checkandchallenge | I34: Shepherd, Callum | J34: Knight, W J | K34: 8 | L34: 96 | M34: 7 | N34: 14 | O34: 10 | P34: 21.551533 | Q34: 0.046400412 | R34: 17 | S34: =IF(AND(ISNUMBER(R34),R34>1,P34>0),R34/P34-1,"") -> -0.211193 | T34: =IF(AND(ISNUMBER(P34),P34>0),P34*EXP('Read me'!$B$22),"") -> 26.323102
A35: 1:44 | B35: Ripon | C35: Theakston Brewing Legends Since 1827 EBF Novice Stakes (GBB Race) | D35: Class 4 | E35: 6 | F35: Good | G35: 9 | H35: Scenic Route (IRE) | I35: Orr, Oisin | J35: Fahey, R A | K35: 3 | L35: 78 | M35: 2 | N35: 20 | O35: 1 | P35: 2.1969837 | Q35: 0.45516951 | R35: 1.9090909 | S35: =IF(AND(ISNUMBER(R35),R35>1,P35>0),R35/P35-1,"") -> -0.13104004 | T35: =IF(AND(ISNUMBER(P35),P35>0),P35*EXP('Read me'!$B$22),"") -> 2.683402
A36: 1:44 | B36: Ripon | C36: Theakston Brewing Legends Since 1827 EBF Novice Stakes (GBB Race) | D36: Class 4 | E36: 6 | F36: Good | G36: 9 | H36: Bulletsnap (IRE) | I36: Hart, Jason | J36: Haggas, W J | K36: 9 | L36: 78 | M36: 2 | N36: 28 | O36: 2 | P36: 2.6507783 | Q36: 0.37724769 | R36: 2.5 | S36: =IF(AND(ISNUMBER(R36),R36>1,P36>0),R36/P36-1,"") -> -0.056880779 | T36: =IF(AND(ISNUMBER(P36),P36>0),P36*EXP('Read me'!$B$22),"") -> 3.237668
... A39: 1:44 | B39: Ripon | C39: Theakston Brewing Legends Since 1827 EBF Novice Stakes (GBB Race) | D39: Class 4 | E39: 6 | F39: Good | G39: 9 | H39: Commander Keith (IRE) | I39: Stammers, Oliver | J39: Frost, Kevin | K39: 2 | L39: 0 | M39: 2 | N39: 35 | O39: 5 | P39: 55.715171 | Q39: 0.017948433 | R39: 34 | S39: =IF(AND(ISNUMBER(R39),R39>1,P39>0),R39/P39-1,"") -> -0.38975329 | T39: =IF(AND(ISNUMBER(P39),P39>0),P39*EXP('Read me'!$B$22),"") -> 68.050664
A40: 1:44 | B40: Ripon | C40: Theakston Brewing Legends Since 1827 EBF Novice Stakes (GBB Race) | D40: Class 4 | E40: 6 | F40: Good | G40: 9 | H40: Jeans Tipple (FR) | I40: Beasley, Connor | J40: Kirby, P A | K40: 4 | L40: 0 | M40: 2 | O40: 6 | P40: 93.029003 | Q40: 0.010749336 | R40: 26 | S40: =IF(AND(ISNUMBER(R40),R40>1,P40>0),R40/P40-1,"") -> -0.72051727 | T40: =IF(AND(ISNUMBER(P40),P40>0),P40*EXP('Read me'!$B$22),"") -> 113.62588
A41: 1:44 | B41: Ripon | C41: Theakston Brewing Legends Since 1827 EBF Novice Stakes (GBB Race) | D41: Class 4 | E41: 6 | F41: Good | G41: 9 | H41: Cracking Toast | I41: Sexton, Ryan | J41: Hanmer, G D | K41: 8 | L41: 0 | M41: 2 | N41: 15 | O41: 7 | P41: 265.23782 | Q41: 0.0037702013 | R41: 67 | S41: =IF(AND(ISNUMBER(R41),R41>1,P41>0),R41/P41-1,"") -> -0.74739651 | T41: =IF(AND(ISNUMBER(P41),P41>0),P41*EXP('Read me'!$B$22),"") -> 323.96221
A42: 1:44 | B42: Ripon | C42: Theakston Brewing Legends Since 1827 EBF Novice Stakes (GBB Race) | D42: Class 4 | E42: 6 | F42: Good | G42: 9 | H42: Harry Akoya | I42: McManoman, Faye | J42: Tinkler, N | K42: 5 | L42: 0 | M42: 2 | N42: 10 | O42: 8 | P42: 711.80747 | Q42: 0.0014048743 | R42: 51 | S42: =IF(AND(ISNUMBER(R42),R42>1,P42>0),R42/P42-1,"") -> -0.92835141 | T42: =IF(AND(ISNUMBER(P42),P42>0),P42*EXP('Read me'!$B$22),"") -> 869.4036
...

Sheet Newmarket (Rowley)
A1: Time | B1: Course | C1: Race | D1: Class | E1: Furlongs | F1: Going | G1: Runners | H1: Horse | I1: Jockey | J1: Trainer | K1: Draw | L1: OR | M1: Age | N1: Days since run | O1: Model rank | P1: Predicted BSP | Q1: Win probability | R1: Card odds (HRB) | S1: Card odds vs model | T1: Rule: back at Betfair ≥
A2: 1:22 | B2: Newmarket (Rowley) | C2: British Stallion Studs EBF Jersey Lily Fillies Nursery | D2: Class 2 | E2: 7 | F2: Good To Firm | G2: 10 | H2: Al Samsama (IRE) | I2: Loughnane, Billy | J2: Hughes, Richard | K2: 2 | L2: 85 | M2: 2 | N2: 18 | O2: 1 | P2: 5.4223912 | Q2: 0.18442048 | R2: 7.5 | S2: =IF(AND(ISNUMBER(R2),R2>1,P2>0),R2/P2-1,"") -> 0.38315362 | T2: =IF(AND(ISNUMBER(P2),P2>0),P2*EXP('Read me'!$B$22),"") -> 6.6229235
A3: 1:22 | B3: Newmarket (Rowley) | C3: British Stallion Studs EBF Jersey Lily Fillies Nursery | D3: Class 2 | E3: 7 | F3: Good To Firm | G3: 10 | H3: Next Of Kin | I3: Marquand, Tom | J3: Haggas, W J | K3: 3 | L3: 76 | M3: 2 | N3: 8 | O3: 2 | P3: 7.3693735 | Q3: 0.13569675 | R3: 8.5 | S3: =IF(AND(ISNUMBER(R3),R3>1,P3>0),R3/P3-1,"") -> 0.15342234 | T3: =IF(AND(ISNUMBER(P3),P3>0),P3*EXP('Read me'!$B$22),"") -> 9.0009731
A4: 1:22 | B4: Newmarket (Rowley) | C4: British Stallion Studs EBF Jersey Lily Fillies Nursery | D4: Class 2 | E4: 7 | F4: Good To Firm | G4: 10 | H4: Zephyra | I4: Murphy, Oisin | J4: Botti, M | K4: 4 | L4: 77 | M4: 2 | N4: 10 | O4: 3 | P4: 7.8795883 | Q4: 0.12691018 | R4: 10 | S4: =IF(AND(ISNUMBER(R4),R4>1,P4>0),R4/P4-1,"") -> 0.26910183 | T4: =IF(AND(ISNUMBER(P4),P4>0),P4*EXP('Read me'!$B$22),"") -> 9.6241509
A5: 1:22 | B5: Newmarket (Rowley) | C5: British Stallion Studs EBF Jersey Lily Fillies Nursery | D5: Class 2 | E5: 7 | F5: Good To Firm | G5: 10 | H5: Marsala (IRE) | I5: Ryan, Rossa | J5: Beckett, R M | K5: 6 | L5: 74 | M5: 2 | N5: 22 | O5: 4 | P5: 8.3992734 | Q5: 0.11905792 | R5: 7 | S5: =IF(AND(ISNUMBER(R5),R5>1,P5>0),R5/P5-1,"") -> -0.16659457 | T5: =IF(AND(ISNUMBER(P5),P5>0),P5*EXP('Read me'!$B$22),"") -> 10.258896
A6: 1:22 | B6: Newmarket (Rowley) | C6: British Stallion Studs EBF Jersey Lily Fillies Nursery | D6: Class 2 | E6: 7 | F6: Good To Firm | G6: 10 | H6: Fire Thunder (IRE) | I6: Sousa, Silvestre De | J6: Botti, M | K6: 8 | L6: 70 | M6: 2 | N6: 42 | O6: 5 | P6: 9.2469802 | Q6: 0.10814341 | R6: 4.5 | S6: =IF(AND(ISNUMBER(R6),R6>1,P6>0),R6/P6-1,"") -> -0.51335464 | T6: =IF(AND(ISNUMBER(P6),P6>0),P6*EXP('Read me'!$B$22),"") -> 11.294287
A7: 1:22 | B7: Newmarket (Rowley) | C7: British Stallion Studs EBF Jersey Lily Fillies Nursery | D7: Class 2 | E7: 7 | F7: Good To Firm | G7: 10 | H7: Bymiddaytomorrow (IRE) | I7: Lee, Clifford | J7: Walker, Ed | K7: 9 | L7: 82 | M7: 2 | N7: 16 | O7: 6 | P7: 10.374905 | Q7: 0.096386429 | R7: 9.5 | S7: =IF(AND(ISNUMBER(R7),R7>1,P7>0),R7/P7-1,"") -> -0.084328923 | T7: =IF(AND(ISNUMBER(P7),P7>0),P7*EXP('Read me'!$B$22),"") -> 12.671937
A8: 1:22 | B8: Newmarket (Rowley) | C8: British Stallion Studs EBF Jersey Lily Fillies Nursery | D8: Class 2 | E8: 7 | F8: Good To Firm | G8: 10 | H8: Polyxena (IRE) | I8: Ghiani, Marco | J8: Williams, S C | K8: 1 | L8: 82 | M8: 2 | N8: 19 | O8: 7 | P8: 11.21555 | Q8: 0.089161921 | R8: 7 | S8: =IF(AND(ISNUMBER(R8),R8>1,P8>0),R8/P8-1,"") -> -0.37586655 | T8: =IF(AND(ISNUMBER(P8),P8>0),P8*EXP('Read me'!$B$22),"") -> 13.698704
A9: 1:22 | B9: Newmarket (Rowley) | C9: British Stallion Studs EBF Jersey Lily Fillies Nursery | D9: Class 2 | E9: 7 | F9: Good To Firm | G9: 10 | H9: Tansy Lane | I9: Havlin, Robert | J9: Owen, J P | K9: 7 | L9: 74 | M9: 2 | N9: 43 | O9: 8 | P9: 11.866381 | Q9: 0.084271692 | R9: 13 | S9: =IF(AND(ISNUMBER(R9),R9>1,P9>0),R9/P9-1,"") -> 0.095531993 | T9: =IF(AND(ISNUMBER(P9),P9>0),P9*EXP('Read me'!$B$22),"") -> 14.49363
A10: 1:22 | B10: Newmarket (Rowley) | C10: British Stallion Studs EBF Jersey Lily Fillies Nursery | D10: Class 2 | E10: 7 | F10: Good To Firm | G10: 10 | H10: Kiah (IRE) | I10: Egan, David | J10: Meehan, B J | K10: 5 | L10: 76 | M10: 2 | N10: 30 | O10: 9 | P10: 34.251046 | Q10: 0.029196189 | R10: 13 | S10: =IF(AND(ISNUMBER(R10),R10>1,P10>0),R10/P10-1,"") -> -0.62044955 | T10: =IF(AND(ISNUMBER(P10),P10>0),P10*EXP('Read me'!$B$22),"") -> 41.834322
A11: 1:22 | B11: Newmarket (Rowley) | C11: British Stallion Studs EBF Jersey Lily Fillies Nursery | D11: Class 2 | E11: 7 | F11: Good To Firm | G11: 10 | H11: Tie A Navyribbon | I11: Gordon, Josephine | J11: Stone, W B | K11: 10 | L11: 80 | M11: 2 | N11: 16 | O11: 10 | P11: 37.376154 | Q11: 0.026755027 | R11: 29 | S11: =IF(AND(ISNUMBER(R11),R11>1,P11>0),R11/P11-1,"") -> -0.22410423 | T11: =IF(AND(ISNUMBER(P11),P11>0),P11*EXP('Read me'!$B$22),"") -> 45.651338
A12: 1:55 | B12: Newmarket (Rowley) | C12: Tattersalls Online Royal Lodge Stakes (Group 2) | E12: 8 | F12: Good To Firm | G12: 7 | H12: Haffner (USA) | I12: Moore, Ryan | J12: OBrien, A P | K12: 4 | L12: 110 | M12: 2 | N12: 13 | O12: 1 | P12: 4.1555937 | Q12: 0.2406395 | R12: 4.5 | S12: =IF(AND(ISNUMBER(R12),R12>1,P12>0),R12/P12-1,"") -> 0.082877751 | T12: =IF(AND(ISNUMBER(P12),P12>0),P12*EXP('Read me'!$B$22),"") -> 5.0756537
A13: 1:55 | B13: Newmarket (Rowley) | C13: Tattersalls Online Royal Lodge Stakes (Group 2) | E13: 8 | F13: Good To Firm | G13: 7 | H13: First Law (IRE) | I13: Buick, William | J13: Appleby, Charlie | K13: 2 | L13: 101 | M13: 2 | N13: 21 | O13: 2 | P13: 4.324806 | Q13: 0.23122425 | R13: 4.5 | S13: =IF(AND(ISNUMBER(R13),R13>1,P13>0),R13/P13-1,"") -> 0.040509104 | T13: =IF(AND(ISNUMBER(P13),P13>0),P13*EXP('Read me'!$B$22),"") -> 5.28233
A14: 1:55 | B14: Newmarket (Rowley) | C14: Tattersalls Online Royal Lodge Stakes (Group 2) | E14: 8 | F14: Good To Firm | G14: 7 | H14: Quest For Stars (FR) | I14: Loughnane, Billy | J14: Appleby, Charlie | K14: 6 | L14: 105 | M14: 2 | N14: 14 | O14: 3 | P14: 4.8755087 | Q14: 0.2051068 | R14: 5 | S14: =IF(AND(ISNUMBER(R14),R14>1,P14>0),R14/P14-1,"") -> 0.025534021 | T14: =IF(AND(ISNUMBER(P14),P14>0),P14*EXP('Read me'!$B$22),"") -> 5.9549597
A15: 1:55 | B15: Newmarket (Rowley) | C15: Tattersalls Online Royal Lodge Stakes (Group 2) | E15: 8 | F15: Good To Firm | G15: 7 | H15: Burning Up | I15: Lee, Clifford | J15: Burke, K R | K15: 7 | L15: 97 | M15: 2 | N15: 23 | O15: 4 | P15: 7.4636157 | Q15: 0.13398332 | R15: 4.5 | S15: =IF(AND(ISNUMBER(R15),R15>1,P15>0),R15/P15-1,"") -> -0.39707507 | T15: =IF(AND(ISNUMBER(P15),P15>0),P15*EXP('Read me'!$B$22),"") -> 9.1160808
A16: 1:55 | B16: Newmarket (Rowley) | C16: Tattersalls Online Royal Lodge Stakes (Group 2) | E16: 8 | F16: Good To Firm | G16: 7 | H16: Quicken Away (USA) | I16: Murphy, Oisin | J16: Balding, A M | K16: 5 | L16: 0 | M16: 2 | N16: 18 | O16: 5 | P16: 9.0785 | Q16: 0.11015036 | R16: 7 | S16: =IF(AND(ISNUMBER(R16),R16>1,P16>0),R16/P16-1,"") -> -0.22894751 | T16: =IF(AND(ISNUMBER(P16),P16>0),P16*EXP('Read me'!$B$22),"") -> 11.088505
A17: 1:55 | B17: Newmarket (Rowley) | C17: Tattersalls Online Royal Lodge Stakes (Group 2) | E17: 8 | F17: Good To Firm | G17: 7 | H17: Rocket Boy (IRE) | I17: Ghiani, Marco | J17: Botti, M | K17: 3 | L17: 100 | M17: 2 | N17: 21 | O17: 6 | P17: 19.160325 | Q17: 0.052191181 | R17: 17 | S17: =IF(AND(ISNUMBER(R17),R17>1,P17>0),R17/P17-1,"") -> -0.11274993 | T17: =IF(AND(ISNUMBER(P17),P17>0),P17*EXP('Read me'!$B$22),"") -> 23.402474
A18: 1:55 | B18: Newmarket (Rowley) | C18: Tattersalls Online Royal Lodge Stakes (Group 2) | E18: 8 | F18: Good To Firm | G18: 7 | H18: Iwasjustsaying | I18: Mitchell, Jack | J18: Johnston, Charlie | K18: 1 | L18: 86 | M18: 2 | N18: 18 | O18: 7 | P18: 37.446739 | Q18: 0.026704595 | R18: 23 | S18: =IF(AND(ISNUMBER(R18),R18>1,P18>0),R18/P18-1,"") -> -0.38579431 | T18: =IF(AND(ISNUMBER(P18),P18>0),P18*EXP('Read me'!$B$22),"") -> 45.73755
A19: 2:27 | B19: Newmarket (Rowley) | C19: Tattersalls Sceptre Sessions Cheveley Park Stakes (Fillies Group 1) | E19: 6 | F19: Good To Firm | G19: 6 | H19: Sun Goddess (IRE) | I19: Moore, Ryan | J19: OBrien, A P | K19: 6 | L19: 119 | M19: 2 | N19: 13 | O19: 1 | P19: 1.8278127 | Q19: 0.547102 | R19: 2.5 | S19: =IF(AND(ISNUMBER(R19),R19>1,P19>0),R19/P19-1,"") -> 0.36775501 | T19: =IF(AND(ISNUMBER(P19),P19>0),P19*EXP('Read me'!$B$22),"") -> 2.2324955
A20: 2:27 | B20: Newmarket (Rowley) | C20: Tattersalls Sceptre Sessions Cheveley Park Stakes (Fillies Group 1) | E20: 6 | F20: Good To Firm | G20: 6 | H20: Libertango (IRE) | I20: Loughnane, Billy | J20: Boughey, George | K20: 2 | L20: 107 | M20: 2 | N20: 37 | O20: 2 | P20: 6.5055108 | Q20: 0.15371583 | R20: 5.5 | S20: =IF(AND(ISNUMBER(R20),R20>1,P20>0),R20/P20-1,"") -> -0.15456293 | T20: =IF(AND(ISNUMBER(P20),P20>0),P20*EXP('Read me'!$B$22),"") -> 7.9458488
A21: 2:27 | B21: Newmarket (Rowley) | C21: Tattersalls Sceptre Sessions Cheveley Park Stakes (Fillies Group 1) | E21: 6 | F21: Good To Firm | G21: 6 | H21: Senorita Bonita (IRE) | I21: Murphy, Oisin | J21: Crisford, Simon | K21: 1 | L21: 117 | M21: 2 | N21: 78 | O21: 3 | P21: 6.5580225 | Q21: 0.15248499 | R21: 3 | S21: =IF(AND(ISNUMBER(R21),R21>1,P21>0),R21/P21-1,"") -> -0.54254503 | T21: =IF(AND(ISNUMBER(P21),P21>0),P21*EXP('Read me'!$B$22),"") -> 8.0099868
A22: 2:27 | B22: Newmarket (Rowley) | C22: Tattersalls Sceptre Sessions Cheveley Park Stakes (Fillies Group 1) | E22: 6 | F22: Good To Firm | G22: 6 | H22: Alwaysanangel (IRE) | I22: Buick, William | J22: OBrien, Joseph Patrick | K22: 3 | L22: 104 | M22: 2 | N22: 43 | O22: 4 | P22: 12.459672 | Q22: 0.080258936 | R22: 11 | S22: =IF(AND(ISNUMBER(R22),R22>1,P22>0),R22/P22-1,"") -> -0.11715171 | T22: =IF(AND(ISNUMBER(P22),P22>0),P22*EXP('Read me'!$B$22),"") -> 15.218278
A23: 2:27 | B23: Newmarket (Rowley) | C23: Tattersalls Sceptre Sessions Cheveley Park Stakes (Fillies Group 1) | E23: 6 | F23: Good To Firm | G23: 6 | H23: Moonrise (IRE) | I23: Marquand, Tom | J23: Balding, A M | K23: 5 | L23: 109 | M23: 2 | N23: 21 | O23: 5 | P23: 16.851917 | Q23: 0.05934043 | R23: 17 | S23: =IF(AND(ISNUMBER(R23),R23>1,P23>0),R23/P23-1,"") -> 0.0087873064 | T23: =IF(AND(ISNUMBER(P23),P23>0),P23*EXP('Read me'!$B$22),"") -> 20.582978
... A31: 3:00 | B31: Newmarket (Rowley) | C31: Tattersalls Middle Park Stakes (Group 1) | E31: 6 | F31: Good To Firm | G31: 7 | H31: Force Noir (IRE) | I31: Egan, David | J31: Aguiar, Robson | K31: 3 | L31: 94 | M31: 2 | N31: 8 | O31: 7 | P31: 107.78667 | Q31: 0.0092775848 | R31: 67 | S31: =IF(AND(ISNUMBER(R31),R31>1,P31>0),R31/P31-1,"") -> -0.37840182 | T31: =IF(AND(ISNUMBER(P31),P31>0),P31*EXP('Read me'!$B$22),"") -> 131.65094
A32: 3:40 | B32: Newmarket (Rowley) | C32: bet365 Cambridgeshire (Heritage Handicap) | D32: Class 2 | E32: 9 | F32: Good To Firm | G32: 27 | H32: Gavriel | I32: Havlin, Robert | J32: Gosden, John and Thady | K32: 28 | L32: 99 | M32: 3 | N32: 21 | O32: 1 | P32: 8.5823655 | Q32: 0.11651799 | R32: 5 | S32: =IF(AND(ISNUMBER(R32),R32>1,P32>0),R32/P32-1,"") -> -0.41741004 | T32: =IF(AND(ISNUMBER(P32),P32>0),P32*EXP('Read me'!$B$22),"") -> 10.482525
A33: 3:40 | B33: Newmarket (Rowley) | C33: bet365 Cambridgeshire (Heritage Handicap) | D33: Class 2 | E33: 9 | F33: Good To Firm | G33: 27 | H33: Bourbon Blues | I33: Moore, Ryan | J33: Meehan, B J | K33: 13 | L33: 105 | M33: 3 | N33: 16 | O33: 2 | P33: 10.901632 | Q33: 0.091729387 | R33: 11 | S33: =IF(AND(ISNUMBER(R33),R33>1,P33>0),R33/P33-1,"") -> 0.0090232517 | T33: =IF(AND(ISNUMBER(P33),P33>0),P33*EXP('Read me'!$B$22),"") -> 13.315283
A34: 3:40 | B34: Newmarket (Rowley) | C34: bet365 Cambridgeshire (Heritage Handicap) | D34: Class 2 | E34: 9 | F34: Good To Firm | G34: 27 | H34: Shafdar (IRE) | I34: Buick, William | J34: Williams, Ian | K34: 5 | L34: 93 | M34: 4 | N34: 14 | O34: 3 | P34: 12.89285 | Q34: 0.07756237 | R34: 26 | S34: =IF(AND(ISNUMBER(R34),R34>1,P34>0),R34/P34-1,"") -> 1.0166216 | T34: =IF(AND(ISNUMBER(P34),P34>0),P34*EXP('Read me'!$B$22),"") -> 15.747362
A35: 3:40 | B35: Newmarket (Rowley) | C35: bet365 Cambridgeshire (Heritage Handicap) | D35: Class 2 | E35: 9 | F35: Good To Firm | G35: 27 | H35: Indalo (IRE) | I35: Dawson, R | J35: Varian, Roger | K35: 26 | L35: 104 | M35: 5 | N35: 57 | O35: 4 | P35: 13.646506 | Q35: 0.073278829 | R35: 9.5 | S35: =IF(AND(ISNUMBER(R35),R35>1,P35>0),R35/P35-1,"") -> -0.30385112 | T35: =IF(AND(ISNUMBER(P35),P35>0),P35*EXP('Read me'!$B$22),"") -> 16.66788
A36: 3:40 | B36: Newmarket (Rowley) | C36: bet365 Cambridgeshire (Heritage Handicap) | D36: Class 2 | E36: 9 | F36: Good To Firm | G36: 27 | H36: Hand Of God | I36: Edmunds, Lewis | J36: Charlton, Roger/Harry | K36: 24 | L36: 106 | M36: 5 | N36: 77 | O36: 5 | P36: 15.73198 | Q36: 0.063564792 | R36: 9.5 | S36: =IF(AND(ISNUMBER(R36),R36>1,P36>0),R36/P36-1,"") -> -0.39613448 | T36: =IF(AND(ISNUMBER(P36),P36>0),P36*EXP('Read me'!$B$22),"") -> 19.215083
A37: 3:40 | B37: Newmarket (Rowley) | C37: bet365 Cambridgeshire (Heritage Handicap) | D37: Class 2 | E37: 9 | F37: Good To Firm | G37: 27 | H37: Alcarath (IRE) | I37: Ryan, Rossa | J37: King, A | K37: 1 | L37: 92 | M37: 4 | N37: 28 | O37: 6 | P37: 18.156636 | Q37: 0.055076281 | R37: 13 | S37: =IF(AND(ISNUMBER(R37),R37>1,P37>0),R37/P37-1,"") -> -0.28400835 | T37: =IF(AND(ISNUMBER(P37),P37>0),P37*EXP('Read me'!$B$22),"") -> 22.176566
A38: 3:40 | B38: Newmarket (Rowley) | C38: bet365 Cambridgeshire (Heritage Handicap) | D38: Class 2 | E38: 9 | F38: Good To Firm | G38: 27 | H38: Harmonics (IRE) | I38: Foley, Shane | J38: Gosden, John and Thady | K38: 18 | L38: 97 | M38: 3 | N38: 19 | O38: 7 | P38: 18.309284 | Q38: 0.0546171 | R38: 13 | S38: =IF(AND(ISNUMBER(R38),R38>1,P38>0),R38/P38-1,"") -> -0.2899777 | T38: =IF(AND(ISNUMBER(P38),P38>0),P38*EXP('Read me'!$B$22),"") -> 22.36301
A39: 3:40 | B39: Newmarket (Rowley) | C39: bet365 Cambridgeshire (Heritage Handicap) | D39: Class 2 | E39: 9 | F39: Good To Firm | G39: 27 | H39: Pierre Royal (IRE) | I39: Sheehy, M P | J39: McGuinness, Adrian | K39: 9 | L39: 91 | M39: 4 | N39: 13 | O39: 8 | P39: 20.336599 | Q39: 0.04917243 | R39: 34 | S39: =IF(AND(ISNUMBER(R39),R39>1,P39>0),R39/P39-1,"") -> 0.6718626 | T39: =IF(AND(ISNUMBER(P39),P39>0),P39*EXP('Read me'!$B$22),"") -> 24.839179
A40: 3:40 | B40: Newmarket (Rowley) | C40: bet365 Cambridgeshire (Heritage Handicap) | D40: Class 2 | E40: 9 | F40: Good To Firm | G40: 27 | H40: Spanish Voice | I40: Murphy, Oisin | J40: Balding, A M | K40: 11 | L40: 94 | M40: 4 | N40: 22 | O40: 9 | P40: 23.522031 | Q40: 0.042513336 | R40: 15 | S40: =IF(AND(ISNUMBER(R40),R40>1,P40>0),R40/P40-1,"") -> -0.36229996 | T40: =IF(AND(ISNUMBER(P40),P40>0),P40*EXP('Read me'!$B$22),"") -> 28.729873
A41: 3:40 | B41: Newmarket (Rowley) | C41: bet365 Cambridgeshire (Heritage Handicap) | D41: Class 2 | E41: 9 | F41: Good To Firm | G41: 27 | H41: Erzindjan (IRE) | I41: Loughnane, Billy | J41: Kent, T J | K41: 25 | L41: 100 | M41: 8 | N41: 35 | O41: 10 | P41: 24.327207 | Q41: 0.04110624 | R41: 9 | S41: =IF(AND(ISNUMBER(R41),R41>1,P41>0),R41/P41-1,"") -> -0.63004384 | T41: =IF(AND(ISNUMBER(P41),P41>0),P41*EXP('Read me'!$B$22),"") -> 29.713317
A42: 3:40 | B42: Newmarket (Rowley) | C42: bet365 Cambridgeshire (Heritage Handicap) | D42: Class 2 | E42: 9 | F42: Good To Firm | G42: 27 | H42: Thunder Run (IRE) | I42: Lee, Clifford | J42: Burke, K R | K42: 16 | L42: 108 | M42: 5 | N42: 14 | O42: 11 | P42: 24.975489 | Q42: 0.040039257 | R42: 26 | S42: =IF(AND(ISNUMBER(R42),R42>1,P42>0),R42/P42-1,"") -> 0.041020678 | T42: =IF(AND(ISNUMBER(P42),P42>0),P42*EXP('Read me'!$B$22),"") -> 30.505131
A43: 3:40 | B43: Newmarket (Rowley) | C43: bet365 Cambridgeshire (Heritage Handicap) | D43: Class 2 | E43: 9 | F43: Good To Firm | G43: 27 | H43: Wild Thoughts (IRE) | I43: Osborne, Saffie | J43: Spencer, Richard | K43: 19 | L43: 93 | M43: 3 | N43: 9 | O43: 12 | P43: 28.305055 | Q43: 0.035329378 | R43: 17 | S43: =IF(AND(ISNUMBER(R43),R43>1,P43>0),R43/P43-1,"") -> -0.39940057 | T43: =IF(AND(ISNUMBER(P43),P43>0),P43*EXP('Read me'!$B$22),"") -> 34.571873
... A61: 4:15 | B61: Newmarket (Rowley) | C61: Blandford Bloodstock 25th Anniversary EBF Maiden Fillies Stakes (GBB Race) | D61: Class 2 | E61: 7 | F61: Good To Firm | G61: 11 | H61: La Pittura | I61: Murphy, Oisin | J61: Balding, A M | K61: 10 | L61: 0 | M61: 2 | N61: 21 | O61: 3 | P61: 7.5001601 | Q61: 0.13333049 | R61: 4.3333333 | S61: =IF(AND(ISNUMBER(R61),R61>1,P61>0),R61/P61-1,"") -> -0.42223456 | T61: =IF(AND(ISNUMBER(P61),P61>0),P61*EXP('Read me'!$B$22),"") -> 9.1607163
A62: 4:15 | B62: Newmarket (Rowley) | C62: Blandford Bloodstock 25th Anniversary EBF Maiden Fillies Stakes (GBB Race) | D62: Class 2 | E62: 7 | F62: Good To Firm | G62: 11 | H62: Miss Jane Hadley (IRE) | I62: Mitchell, Jack | J62: Varian, Roger | K62: 11 | L62: 0 | M62: 2 | O62: 4 | P62: 7.9730899 | Q62: 0.12542189 | R62: 9.5 | S62: =IF(AND(ISNUMBER(R62),R62>1,P62>0),R62/P62-1,"") -> 0.19150794 | T62: =IF(AND(ISNUMBER(P62),P62>0),P62*EXP('Read me'!$B$22),"") -> 9.7383541
A63: 4:15 | B63: Newmarket (Rowley) | C63: Blandford Bloodstock 25th Anniversary EBF Maiden Fillies Stakes (GBB Race) | D63: Class 2 | E63: 7 | F63: Good To Firm | G63: 11 | H63: Out Late (IRE) | I63: Dawson, R | J63: Varian, Roger | K63: 8 | L63: 0 | M63: 2 | O63: 5 | P63: 9.8741007 | Q63: 0.10127505 | R63: 8 | S63: =IF(AND(ISNUMBER(R63),R63>1,P63>0),R63/P63-1,"") -> -0.18979963 | T63: =IF(AND(ISNUMBER(P63),P63>0),P63*EXP('Read me'!$B$22),"") -> 12.060254
A64: 4:15 | B64: Newmarket (Rowley) | C64: Blandford Bloodstock 25th Anniversary EBF Maiden Fillies Stakes (GBB Race) | D64: Class 2 | E64: 7 | F64: Good To Firm | G64: 11 | H64: Queen Of The Gulf | I64: Loughnane, Billy | J64: Hughes, Richard | K64: 5 | L64: 0 | M64: 2 | O64: 6 | P64: 14.716009 | Q64: 0.067953205 | R64: 6 | S64: =IF(AND(ISNUMBER(R64),R64>1,P64>0),R64/P64-1,"") -> -0.59228077 | T64: =IF(AND(ISNUMBER(P64),P64>0),P64*EXP('Read me'!$B$22),"") -> 17.974174
...

Sheet Curragh
A1: Time | B1: Course | C1: Race | D1: Class | E1: Furlongs | F1: Going | G1: Runners | H1: Horse | I1: Jockey | J1: Trainer | K1: Draw | L1: OR | M1: Age | N1: Days since run | O1: Model rank | P1: Predicted BSP | Q1: Win probability | R1: Card odds (HRB) | S1: Card odds vs model | T1: Rule: back at Betfair ≥
A2: 1:30 | B2: Curragh | C2: Market Square Monasterevin Irish European Breeders Fund Maiden | E2: 6 | F2: Good | G2: 13 | H2: Benown (IRE) | I2: Sheridan, J M | J2: OBrien, Joseph Patrick | K2: 14 | L2: 0 | M2: 2 | N2: 48 | O2: 1 | P2: 1.9022607 | Q2: 0.52569029 | R2: 1.7272727 | S2: =IF(AND(ISNUMBER(R2),R2>1,P2>0),R2/P2-1,"") -> -0.091989498 | T2: =IF(AND(ISNUMBER(P2),P2>0),P2*EXP('Read me'!$B$22),"") -> 2.3234265
A3: 1:30 | B3: Curragh | C3: Market Square Monasterevin Irish European Breeders Fund Maiden | E3: 6 | F3: Good | G3: 13 | H3: Heralds March (IRE) | I3: Keane, C T | J3: Lyons, G M | K3: 12 | L3: 0 | M3: 2 | N3: 35 | O3: 2 | P3: 5.3234689 | Q3: 0.18784744 | R3: 5.5 | S3: =IF(AND(ISNUMBER(R3),R3>1,P3>0),R3/P3-1,"") -> 0.033160919 | T3: =IF(AND(ISNUMBER(P3),P3>0),P3*EXP('Read me'!$B$22),"") -> 6.5020996
A4: 1:30 | B4: Curragh | C4: Market Square Monasterevin Irish European Breeders Fund Maiden | E4: 6 | F4: Good | G4: 13 | H4: Controlla (IRE) | I4: OConnor, Donagh | J4: Aguiar, Robson | K4: 11 | L4: 96 | M4: 2 | N4: 13 | O4: 3 | P4: 8.4672894 | Q4: 0.11810155 | R4: 3.25 | S4: =IF(AND(ISNUMBER(R4),R4>1,P4>0),R4/P4-1,"") -> -0.61616996 | T4: =IF(AND(ISNUMBER(P4),P4>0),P4*EXP('Read me'!$B$22),"") -> 10.341971
A5: 1:30 | B5: Curragh | C5: Market Square Monasterevin Irish European Breeders Fund Maiden | E5: 6 | F5: Good | G5: 13 | H5: Jungle Wise (IRE) | I5: Coen, Ben M | J5: Murphy, Daniel | K5: 8 | L5: 0 | M5: 2 | N5: 17 | O5: 4 | P5: 11.692526 | Q5: 0.085524719 | R5: 11 | S5: =IF(AND(ISNUMBER(R5),R5>1,P5>0),R5/P5-1,"") -> -0.059228091 | T5: =IF(AND(ISNUMBER(P5),P5>0),P5*EXP('Read me'!$B$22),"") -> 14.281283
A6: 1:30 | B6: Curragh | C6: Market Square Monasterevin Irish European Breeders Fund Maiden | E6: 6 | F6: Good | G6: 13 | H6: Shake It Out | I6: Whelan, R P | J6: Cotter, Kieran P | K6: 10 | L6: 0 | M6: 2 | O6: 5 | P6: 53.338562 | Q6: 0.018748162 | R6: 51 | S6: =IF(AND(ISNUMBER(R6),R6>1,P6>0),R6/P6-1,"") -> -0.043843731 | T6: =IF(AND(ISNUMBER(P6),P6>0),P6*EXP('Read me'!$B$22),"") -> 65.147866
A7: 1:30 | B7: Curragh | C7: Market Square Monasterevin Irish European Breeders Fund Maiden | E7: 6 | F7: Good | G7: 13 | H7: Moon Gypsy (IRE) | I7: Mulligan, R M | J7: Burns, J G | K7: 9 | L7: 0 | M7: 2 | O7: 6 | P7: 59.575275 | Q7: 0.016785487 | R7: 201 | S7: =IF(AND(ISNUMBER(R7),R7>1,P7>0),R7/P7-1,"") -> 2.3738829 | T7: =IF(AND(ISNUMBER(P7),P7>0),P7*EXP('Read me'!$B$22),"") -> 72.765406
A8: 1:30 | B8: Curragh | C8: Market Square Monasterevin Irish European Breeders Fund Maiden | E8: 6 | F8: Good | G8: 13 | H8: Katty (IRE) | I8: Heffernan, J A | J8: Sexton, Adrian | K8: 5 | L8: 0 | M8: 2 | N8: 37 | O8: 7 | P8: 62.059397 | Q8: 0.016113595 | R8: 29 | S8: =IF(AND(ISNUMBER(R8),R8>1,P8>0),R8/P8-1,"") -> -0.53270574 | T8: =IF(AND(ISNUMBER(P8),P8>0),P8*EXP('Read me'!$B$22),"") -> 75.799519
A9: 1:30 | B9: Curragh | C9: Market Square Monasterevin Irish European Breeders Fund Maiden | E9: 6 | F9: Good | G9: 13 | H9: Royal Sovereign (IRE) | I9: Joyce, Wesley | J9: Mulvany, Michael | K9: 3 | L9: 0 | M9: 2 | O9: 8 | P9: 91.538823 | Q9: 0.010924327 | R9: 51 | S9: =IF(AND(ISNUMBER(R9),R9>1,P9>0),R9/P9-1,"") -> -0.44285935 | T9: =IF(AND(ISNUMBER(P9),P9>0),P9*EXP('Read me'!$B$22),"") -> 111.80577
A10: 1:30 | B10: Curragh | C10: Market Square Monasterevin Irish European Breeders Fund Maiden | E10: 6 | F10: Good | G10: 13 | H10: Starlit (IRE) | I10: Kennedy, K G | J10: Harrington, Mrs John | K10: 7 | L10: 0 | M10: 2 | N10: 42 | O10: 9 | P10: 105.08303 | Q10: 0.0095162848 | R10: 26 | S10: =IF(AND(ISNUMBER(R10),R10>1,P10>0),R10/P10-1,"") -> -0.75257659 | T10: =IF(AND(ISNUMBER(P10),P10>0),P10*EXP('Read me'!$B$22),"") -> 128.3487
A11: 1:30 | B11: Curragh | C11: Market Square Monasterevin Irish European Breeders Fund Maiden | E11: 6 | F11: Good | G11: 13 | H11: Champion Basma (IRE) | I11: Hayes, C D | J11: ONeill, E J | K11: 2 | L11: 0 | M11: 2 | N11: 9 | O11: 10 | P11: 213.77245 | Q11: 0.0046778712 | R11: 67 | S11: =IF(AND(ISNUMBER(R11),R11>1,P11>0),R11/P11-1,"") -> -0.68658263 | T11: =IF(AND(ISNUMBER(P11),P11>0),P11*EXP('Read me'!$B$22),"") -> 261.10226
A12: 1:30 | B12: Curragh | C12: Market Square Monasterevin Irish European Breeders Fund Maiden | E12: 6 | F12: Good | G12: 13 | H12: Fen Phasee (IRE) | I12: Cleary, R P | J12: Davis, Sean | K12: 4 | L12: 0 | M12: 2 | O12: 11 | P12: 393.51875 | Q12: 0.002541175 | R12: 126 | S12: =IF(AND(ISNUMBER(R12),R12>1,P12>0),R12/P12-1,"") -> -0.67981195 | T12: =IF(AND(ISNUMBER(P12),P12>0),P12*EXP('Read me'!$B$22),"") -> 480.64489
A13: 1:30 | B13: Curragh | C13: Market Square Monasterevin Irish European Breeders Fund Maiden | E13: 6 | F13: Good | G13: 13 | H13: Ar Son Na Cuise (IRE) | I13: McDonogh, D P | J13: OBrien, Joseph Patrick | K13: 13 | L13: 0 | M13: 2 | N13: 17 | O13: 12 | P13: 402.27202 | Q13: 0.0024858801 | R13: 101 | S13: =IF(AND(ISNUMBER(R13),R13>1,P13>0),R13/P13-1,"") -> -0.74892611 | T13: =IF(AND(ISNUMBER(P13),P13>0),P13*EXP('Read me'!$B$22),"") -> 491.33615
A14: 1:30 | B14: Curragh | C14: Market Square Monasterevin Irish European Breeders Fund Maiden | E14: 6 | F14: Good | G14: 13 | H14: Brageiro (IRE) | I14: McAteer, L T | J14: OSullivan, Ross | K14: 1 | L14: 0 | M14: 2 | N14: 9 | O14: 13 | P14: 958.57182 | Q14: 0.0010432186 | R14: 201 | S14: =IF(AND(ISNUMBER(R14),R14>1,P14>0),R14/P14-1,"") -> -0.79031305 | T14: =IF(AND(ISNUMBER(P14),P14>0),P14*EXP('Read me'!$B$22),"") -> 1170.8023
A15: 2:00 | B15: Curragh | C15: Kwiff More Bang For Your Bet Rated Race | E15: 7 | F15: Good | G15: 9 | H15: Oro Blanco (IRE) | I15: Kennedy, K G | J15: Harrington, Mrs John | K15: 7 | L15: 84 | M15: 3 | N15: 14 | O15: 1 | P15: 4.4337459 | Q15: 0.22554292 | R15: 3.75 | S15: =IF(AND(ISNUMBER(R15),R15>1,P15>0),R15/P15-1,"") -> -0.15421405 | T15: =IF(AND(ISNUMBER(P15),P15>0),P15*EXP('Read me'!$B$22),"") -> 5.4153895
A16: 2:00 | B16: Curragh | C16: Kwiff More Bang For Your Bet Rated Race | E16: 7 | F16: Good | G16: 9 | H16: Killashee Warrior | I16: Hayes, C D | J16: Harty, Edward and Patrick | K16: 8 | L16: 91 | M16: 3 | N16: 14 | O16: 2 | P16: 5.0561504 | Q16: 0.19777893 | R16: 6 | S16: =IF(AND(ISNUMBER(R16),R16>1,P16>0),R16/P16-1,"") -> 0.18667357 | T16: =IF(AND(ISNUMBER(P16),P16>0),P16*EXP('Read me'!$B$22),"") -> 6.175596
A17: 2:00 | B17: Curragh | C17: Kwiff More Bang For Your Bet Rated Race | E17: 7 | F17: Good | G17: 9 | H17: Lewis Carroll (IRE) | I17: Lordan, W M | J17: OBrien, A P | K17: 3 | L17: 87 | M17: 3 | N17: 182 | O17: 3 | P17: 5.8560056 | Q17: 0.17076486 | R17: 5.5 | S17: =IF(AND(ISNUMBER(R17),R17>1,P17>0),R17/P17-1,"") -> -0.060793244 | T17: =IF(AND(ISNUMBER(P17),P17>0),P17*EXP('Read me'!$B$22),"") -> 7.1525414
A18: 2:00 | B18: Curragh | C18: Kwiff More Bang For Your Bet Rated Race | E18: 7 | F18: Good | G18: 9 | H18: Invincible Will (IRE) | I18: Carroll, G F | J18: Cromwell, Gavin Patrick | K18: 5 | L18: 87 | M18: 3 | N18: 13 | O18: 4 | P18: 6.6813851 | Q18: 0.14966956 | R18: 4.3333333 | S18: =IF(AND(ISNUMBER(R18),R18>1,P18>0),R18/P18-1,"") -> -0.35143189 | T18: =IF(AND(ISNUMBER(P18),P18>0),P18*EXP('Read me'!$B$22),"") -> 8.1606622
A19: 2:00 | B19: Curragh | C19: Kwiff More Bang For Your Bet Rated Race | E19: 7 | F19: Good | G19: 9 | H19: Chapel Lane (IRE) | I19: Lee, W J | J19: McCreery, W | K19: 6 | L19: 81 | M19: 3 | N19: 24 | O19: 5 | P19: 8.5280476 | Q19: 0.11726013 | R19: 8 | S19: =IF(AND(ISNUMBER(R19),R19>1,P19>0),R19/P19-1,"") -> -0.061918928 | T19: =IF(AND(ISNUMBER(P19),P19>0),P19*EXP('Read me'!$B$22),"") -> 10.416181
A20: 2:00 | B20: Curragh | C20: Kwiff More Bang For Your Bet Rated Race | E20: 7 | F20: Good | G20: 9 | H20: Mumhan (IRE) | I20: McDonogh, D P | J20: Bolger, J S | K20: 4 | L20: 86 | M20: 3 | N20: 7 | O20: 6 | P20: 22.209543 | Q20: 0.04502569 | R20: 11 | S20: =IF(AND(ISNUMBER(R20),R20>1,P20>0),R20/P20-1,"") -> -0.5047174 | T20: =IF(AND(ISNUMBER(P20),P20>0),P20*EXP('Read me'!$B$22),"") -> 27.126797
A21: 2:00 | B21: Curragh | C21: Kwiff More Bang For Your Bet Rated Race | E21: 7 | F21: Good | G21: 9 | H21: Unauthorized (IRE) | I21: Holohan, Reese | J21: Melia, Aidan | K21: 1 | L21: 83 | M21: 3 | N21: 91 | O21: 7 | P21: 26.177001 | Q21: 0.038201474 | R21: 21 | S21: =IF(AND(ISNUMBER(R21),R21>1,P21>0),R21/P21-1,"") -> -0.19776905 | T21: =IF(AND(ISNUMBER(P21),P21>0),P21*EXP('Read me'!$B$22),"") -> 31.972661
A22: 2:00 | B22: Curragh | C22: Kwiff More Bang For Your Bet Rated Race | E22: 7 | F22: Good | G22: 9 | H22: Kindergarten (IRE) | I22: McCullagh, Scott | J22: Harrington, Mrs John | K22: 2 | L22: 87 | M22: 3 | N22: 113 | O22: 8 | P22: 31.761112 | Q22: 0.031485044 | R22: 26 | S22: =IF(AND(ISNUMBER(R22),R22>1,P22>0),R22/P22-1,"") -> -0.18138885 | T22: =IF(AND(ISNUMBER(P22),P22>0),P22*EXP('Read me'!$B$22),"") -> 38.793109
A23: 2:00 | B23: Curragh | C23: Kwiff More Bang For Your Bet Rated Race | E23: 7 | F23: Good | G23: 9 | H23: Lohoobb | I23: McCullagh, N G | J23: Grassick, M C | K23: 9 | L23: 78 | M23: 3 | N23: 13 | O23: 9 | P23: 41.200788 | Q23: 0.024271381 | R23: 29 | S23: =IF(AND(ISNUMBER(R23),R23>1,P23>0),R23/P23-1,"") -> -0.29612996 | T23: =IF(AND(ISNUMBER(P23),P23>0),P23*EXP('Read me'!$B$22),"") -> 50.322756
A24: 2:35 | B24: Curragh | C24: Kwiff Supercharged Joe McGrath Handicap (Premier Handicap) | E24: 5 | F24: Good | G24: 20 | H24: Red Evolution (IRE) | I24: Holohan, Reese | J24: OCallaghan, M D | K24: 20 | L24: 85 | M24: 4 | N24: 13 | O24: 1 | P24: 6.6003902 | Q24: 0.15150619 | R24: 5.5 | S24: =IF(AND(ISNUMBER(R24),R24>1,P24>0),R24/P24-1,"") -> -0.16671593 | T24: =IF(AND(ISNUMBER(P24),P24>0),P24*EXP('Read me'!$B$22),"") -> 8.0617348
... A63: 4:20 | B63: Curragh | C63: Goffs Million | E63: 7 | F63: Good | G63: 19 | H63: Dorigo (IRE) | I63: Stott, Kevin | J63: Ryan, K A | K63: 9 | L63: 95 | M63: 2 | N63: 16 | O63: 3 | P63: 9.9999383 | Q63: 0.10000062 | R63: 12 | S63: =IF(AND(ISNUMBER(R63),R63>1,P63>0),R63/P63-1,"") -> 0.2000074 | T63: =IF(AND(ISNUMBER(P63),P63>0),P63*EXP('Read me'!$B$22),"") -> 12.213952
A64: 4:20 | B64: Curragh | C64: Goffs Million | E64: 7 | F64: Good | G64: 19 | H64: Critical Reason (IRE) | I64: Keane, C T | J64: Lyons, G M | K64: 3 | L64: 0 | M64: 2 | O64: 4 | P64: 11.980279 | Q64: 0.083470508 | R64: 19 | S64: =IF(AND(ISNUMBER(R64),R64>1,P64>0),R64/P64-1,"") -> 0.58593964 | T64: =IF(AND(ISNUMBER(P64),P64>0),P64*EXP('Read me'!$B$22),"") -> 14.632746
A65: 4:20 | B65: Curragh | C65: Goffs Million | E65: 7 | F65: Good | G65: 19 | H65: Bayside View (IRE) | I65: Coen, Ben M | J65: Bell, M L W | K65: 13 | L65: 93 | M65: 2 | N65: 27 | O65: 5 | P65: 12.461388 | Q65: 0.080247884 | R65: 9 | S65: =IF(AND(ISNUMBER(R65),R65>1,P65>0),R65/P65-1,"") -> -0.27776904 | T65: =IF(AND(ISNUMBER(P65),P65>0),P65*EXP('Read me'!$B$22),"") -> 15.220373
A66: 4:20 | B66: Curragh | C66: Goffs Million | E66: 7 | F66: Good | G66: 19 | H66: King Of Cloughan (IRE) | I66: Sheridan, J M | J66: OBrien, Joseph Patrick | K66: 20 | L66: 102 | M66: 2 | N66: 48 | O66: 6 | P66: 14.633931 | Q66: 0.06833434 | R66: 9.5 | S66: =IF(AND(ISNUMBER(R66),R66>1,P66>0),R66/P66-1,"") -> -0.35082377 | T66: =IF(AND(ISNUMBER(P66),P66>0),P66*EXP('Read me'!$B$22),"") -> 17.873924
A67: 4:20 | B67: Curragh | C67: Goffs Million | E67: 7 | F67: Good | G67: 19 | H67: Carry The Flag (IRE) | I67: Lordan, W M | J67: OBrien, A P | K67: 10 | L67: 110 | M67: 2 | N67: 15 | O67: 7 | P67: 20.671917 | Q67: 0.048374808 | R67: 8.5 | S67: =IF(AND(ISNUMBER(R67),R67>1,P67>0),R67/P67-1,"") -> -0.58881413 | T67: =IF(AND(ISNUMBER(P67),P67>0),P67*EXP('Read me'!$B$22),"") -> 25.248736
A68: 4:20 | B68: Curragh | C68: Goffs Million | E68: 7 | F68: Good | G68: 19 | H68: Ballinea Star (IRE) | I68: OConnor, Donagh | J68: Aguiar, Robson | K68: 12 | L68: 100 | M68: 2 | N68: 13 | O68: 8 | P68: 26.341548 | Q68: 0.037962842 | R68: 12 | S68: =IF(AND(ISNUMBER(R68),R68>1,P68>0),R68/P68-1,"") -> -0.5444459 | T68: =IF(AND(ISNUMBER(P68),P68>0),P68*EXP('Read me'!$B$22),"") -> 32.173639
A69: 4:20 | B69: Curragh | C69: Goffs Million | E69: 7 | F69: Good | G69: 19 | H69: Thomas Chippendale (IRE) | I69: Cleary, Jack | J69: OBrien, A P | K69: 17 | L69: 0 | M69: 2 | N69: 41 | O69: 9 | P69: 27.498525 | Q69: 0.036365587 | R69: 26 | S69: =IF(AND(ISNUMBER(R69),R69>1,P69>0),R69/P69-1,"") -> -0.054494725 | T69: =IF(AND(ISNUMBER(P69),P69>0),P69*EXP('Read me'!$B$22),"") -> 33.586774
