Workbook

Sheet Read me
A1: Predictions for 2026-09-28
A3: Runners | B3: 434
A4: Races | B4: 45
A5: Meetings | B5: 6
A7: The model | B7: gated 13:43
A8: Features | B8: 993
A9: Trained through | B9: 2026-09-22
A10: Boosting rounds | B10: 12000
A11: Target | B11: logit_norm_prob
A12: Feature code hash | B12: f879b10c8369467a
A14: How to read it
A15: Predicted BSP | B15: The model's forecast of the Betfair Starting Price, from pre-race information only. The prices in each race make a book of exactly 100%.
A16: Win probability | B16: 1 / predicted BSP: the model's chance for the horse, normalised within the race.
A17: Model rank | B17: 1 = the model's shortest price in the race (highlighted green).
A18: Card odds (HRB) | B18: The odds printed on the horseracebase card when it was fetched: a bookmaker forecast, not the Betfair morning price the early-price rule was tested against.
A19: Card odds vs model | B19: Card odds / predicted BSP - 1. Positive: the card is longer than the model.
A21: The early-price rule
A22: Margin (log) | B22: 0.2
A23: Rule: back at Betfair ≥ | B23: Predicted BSP × e^margin: at 0.2, a Betfair price at least 1.22 times the model's (the model at least 22% shorter). The rule was fixed before it was first tested (reports/clv_betfair_2026q1.md): back at Betfair's morning volume-weighted price, where at least £100 has been matched in the morning, and close the position at BSP (lay at BSP to level the book). It is a trade on the price, not a bet held to the result. The margin (blue) is the one input: change it to see the prices at another threshold.
A25: Note | B25: The served model from 29 Sep (the complete-careers pair gated with race_xent), re-run in full on horseracebase's card as it stood at 13:43 UTC (predict-now run 34): 434 runners in 45 races, every one priced. Races already run are included for reference. Each non-runner's price and share of the book are from the last run that priced it (05:08 to 12:48 UTC). 34 non-runners since the prices were first made, in 20 races (sheet Non-runners). The prices here are without them, each race a book of 100%: a non-runner's share of the book goes to the rest of its race, whose prices shorten by about that share.

Sheet Top picks
A1: Time | B1: Course | C1: Race | D1: Runners | E1: Top pick | F1: Jockey | G1: Trainer | H1: Predicted BSP | I1: Win probability | J1: Second choice | K1: Second's BSP | L1: Second's probability | M1: Probability gap | N1: Card odds (HRB) | O1: Rule: back at Betfair ≥
A2: 1:24 | B2: Down Royal | C2: Molson Coors Beverage Company Nursery Handicap | D2: 6 | E2: Santo Parvenue (IRE) | F2: Lee, W J | G2: Harty, Edward and Patrick | H2: 2.2147676 | I2: 0.45151465 | J2: Premier View (IRE) | K2: 4.3596875 | L2: 0.22937424 | M2: =IF(AND(ISNUMBER(I2),ISNUMBER(L2)),I2-L2,"") -> 0.22214041 | N2: 1.8 | O2: =IF(AND(ISNUMBER(H2),H2>0),H2*EXP('Read me'!$B$22),"") -> 2.7051232
A3: 1:30 | B3: Brighton | C3: Matchbook SignUp - Get 20% Back On Losses Handicap | D3: 10 | E3: Bated Breeze (IRE) | F3: Marsh, Finley | G3: Moore, Gary and Josh | H3: 5.1776255 | I3: 0.19313873 | J3: Roman Spring (IRE) | K3: 6.3779397 | L3: 0.15679044 | M3: =IF(AND(ISNUMBER(I3),ISNUMBER(L3)),I3-L3,"") -> 0.036348283 | N3: 5.5 | O3: =IF(AND(ISNUMBER(H3),H3>0),H3*EXP('Read me'!$B$22),"") -> 6.3239661
A4: 1:35 | B4: Roscommon | C4: Athleague Maiden Hurdle | D4: 13 | E4: Direct Approach (IRE) | F4: Kennedy, J W | G4: Elliott, Gordon | H4: 3.1862358 | I4: 0.31384997 | J4: Telegram Sam (IRE) | K4: 3.1927228 | L4: 0.31321228 | M4: =IF(AND(ISNUMBER(I4),ISNUMBER(L4)),I4-L4,"") -> 0.00063768222 | N4: 5 | O4: =IF(AND(ISNUMBER(H4),H4>0),H4*EXP('Read me'!$B$22),"") -> 3.8916772
A5: 1:44 | B5: Hamilton | C5: Clearwater DC Ltd Environmental Solutions Amateur Jockeys Handicap | D5: 6 | E5: Annie Edson Taylor | F5: Brown, Pippa | G5: Makin, Phillip | H5: 3.1430511 | I5: 0.31816218 | J5: Bay Breeze | K5: 4.5721161 | L5: 0.21871711 | M5: =IF(AND(ISNUMBER(I5),ISNUMBER(L5)),I5-L5,"") -> 0.099445072 | N5: 2.5 | O5: =IF(AND(ISNUMBER(H5),H5>0),H5*EXP('Read me'!$B$22),"") -> 3.8389313
A6: 1:50 | B6: Newton Abbot | C6: Celebrating Devon Women In Business Handicap Chase (GBB Race) | D6: 3 | E6: Depalma (IRE) | F6: Skelton, Harry | G6: Skelton, Daniel | H6: 2.195562 | I6: 0.45546425 | J6: Muskerry Rock (IRE) | K6: 3.1859008 | L6: 0.31388297 | M6: =IF(AND(ISNUMBER(I6),ISNUMBER(L6)),I6-L6,"") -> 0.14158128 | N6: 1.6666667 | O6: =IF(AND(ISNUMBER(H6),H6>0),H6*EXP('Read me'!$B$22),"") -> 2.6816655
A7: 1:59 | B7: Down Royal | C7: Coors Fillies Handicap | D7: 10 | E7: Nellcote (IRE) | F7: McDonogh, D P | G7: OBrien, Joseph Patrick | H7: 4.9114672 | I7: 0.20360515 | J7: Stellar Moment (IRE) | K7: 5.3404808 | L7: 0.18724906 | M7: =IF(AND(ISNUMBER(I7),ISNUMBER(L7)),I7-L7,"") -> 0.01635609 | N7: 4.5 | O7: =IF(AND(ISNUMBER(H7),H7>0),H7*EXP('Read me'!$B$22),"") -> 5.9988796
A8: 2:05 | B8: Brighton | C8: Matchbook Betting Exchange Supporting UK Racing Maiden Stakes (GBB Race) | D8: 4 | E8: Galileo Star | F8: Ryan, Rossa | G8: Tate, James | H8: 2.5514401 | I8: 0.39193551 | J8: River Nile (IRE) | K8: 2.984331 | L8: 0.33508347 | M8: =IF(AND(ISNUMBER(I8),ISNUMBER(L8)),I8-L8,"") -> 0.056852042 | N8: 1.5714286 | O8: =IF(AND(ISNUMBER(H8),H8>0),H8*EXP('Read me'!$B$22),"") -> 3.116336
A9: 2:10 | B9: Roscommon | C9: Garys Gardening Services Handicap Hurdle (0-100) | D9: 16 | E9: Cool Summer (IRE) | F9: Enright, P T | G9: McLoughlin, Hilary | H9: 3.935622 | I9: 0.25408944 | J9: Colesberg (IRE) | K9: 8.6710864 | L9: 0.1153258 | M9: =IF(AND(ISNUMBER(I9),ISNUMBER(L9)),I9-L9,"") -> 0.13876364 | N9: 4 | O9: =IF(AND(ISNUMBER(H9),H9>0),H9*EXP('Read me'!$B$22),"") -> 4.8069796
A10: 2:19 | B10: Hamilton | C10: Moira Stein Memorial EBF Restricted Maiden Stakes (GBB Race) | D10: 6 | E10: Cyberspace | F10: Mulrennan, Paul | G10: Smart, B | H10: 2.0902903 | I10: 0.47840245 | J10: Ponte Carlo (IRE) | K10: 4.2862463 | L10: 0.23330437 | M10: =IF(AND(ISNUMBER(I10),ISNUMBER(L10)),I10-L10,"") -> 0.24509807 | N10: 2.75 | O10: =IF(AND(ISNUMBER(H10),H10>0),H10*EXP('Read me'!$B$22),"") -> 2.5530864
A11: 2:25 | B11: Newton Abbot | C11: Jodie Standings Point-To-Point Recruits Novices Hurdle (GBB Race) | D11: 6 | E11: Matiwo (FR) | F11: Gethings, Ciaran | G11: Williams, Mrs Jane | H11: 1.3053142 | I11: 0.7660991 | J11: Scotts Legacy (IRE) | K11: 5.188916 | L11: 0.19271848 | M11: =IF(AND(ISNUMBER(I11),ISNUMBER(L11)),I11-L11,"") -> 0.57338062 | N11: 1.2857143 | O11: =IF(AND(ISNUMBER(H11),H11>0),H11*EXP('Read me'!$B$22),"") -> 1.5943143
A12: 2:34 | B12: Down Royal | C12: Irish EBF Auction Series Fillies Maiden | D12: 9 | E12: Essence Of Time | F12: Lordan, W M | G12: Oliver, Andrew | H12: 2.308552 | I12: 0.43317196 | J12: Ladrona (IRE) | K12: 3.9612645 | L12: 0.25244464 | M12: =IF(AND(ISNUMBER(I12),ISNUMBER(L12)),I12-L12,"") -> 0.18072732 | N12: 2.2 | O12: =IF(AND(ISNUMBER(H12),H12>0),H12*EXP('Read me'!$B$22),"") -> 2.8196718
A13: 2:40 | B13: Brighton | C13: Follow Matchbook On X Nursery | D13: 13 | E13: Magical Life | F13: Ryan, Rossa | G13: Moore, J S | H13: 6.7963234 | I13: 0.14713838 | J13: Hello You Ten (IRE) | K13: 8.0427547 | L13: 0.12433551 | M13: =IF(AND(ISNUMBER(I13),ISNUMBER(L13)),I13-L13,"") -> 0.022802869 | N13: 5.5 | O13: =IF(AND(ISNUMBER(H13),H13>0),H13*EXP('Read me'!$B$22),"") -> 8.3010481
... A20: 3:29 | B20: Hamilton | C20: John MacKenzie And Hamish MacGregor Memorial Handicap | D20: 13 | E20: Impartiality | F20: Gray, S A | G20: Makin, Phillip | H20: 5.5218413 | I20: 0.18109901 | J20: El Matador (IRE) | K20: 7.3111805 | L20: 0.13677682 | M20: =IF(AND(ISNUMBER(I20),ISNUMBER(L20)),I20-L20,"") -> 0.044322195 | N20: 5 | O20: =IF(AND(ISNUMBER(H20),H20>0),H20*EXP('Read me'!$B$22),"") -> 6.7443922
A21: 3:35 | B21: Newton Abbot | C21: Final Furlong Before I Do Selling Handicap Hurdle | D21: 6 | E21: Berry Edge (IRE) | G21: Skelton, Daniel | H21: 2.6844746 | I21: 0.37251237 | J21: Saint Polo (FR) | K21: 3.6120282 | L21: 0.27685276 | M21: =IF(AND(ISNUMBER(I21),ISNUMBER(L21)),I21-L21,"") -> 0.095659611 | N21: 2.875 | O21: =IF(AND(ISNUMBER(H21),H21>0),H21*EXP('Read me'!$B$22),"") -> 3.2788247
A22: 3:44 | B22: Down Royal | C22: Molson Coors Beverage Company Handicap | D22: 14 | E22: Send Harry (IRE) | F22: Dalton, J S | G22: McCutcheon, Miss Evanna | H22: 6.9803971 | I22: 0.14325833 | J22: Barbapapa (IRE) | K22: 7.3739447 | L22: 0.13561263 | M22: =IF(AND(ISNUMBER(I22),ISNUMBER(L22)),I22-L22,"") -> 0.0076456995 | N22: 7 | O22: =IF(AND(ISNUMBER(H22),H22>0),H22*EXP('Read me'!$B$22),"") -> 8.5258763
A23: 3:50 | B23: Brighton | C23: Matchbook Monthly Bet-Builder Rebate Handicap | D23: 7 | E23: Love You Back (IRE) | F23: Fentiman, Warren | G23: Moore, Gary and Josh | H23: 5.3994012 | I23: 0.18520572 | J23: Darkest Red | K23: 5.5871826 | L23: 0.17898108 | M23: =IF(AND(ISNUMBER(I23),ISNUMBER(L23)),I23-L23,"") -> 0.0062246378 | N23: 4 | O23: =IF(AND(ISNUMBER(H23),H23>0),H23*EXP('Read me'!$B$22),"") -> 6.5948435
A24: 3:55 | B24: Roscommon | C24: Castlecoote Handicap Hurdle | D24: 11 | E24: Adaliz (GER) | F24: OKeeffe, Darragh | G24: Bromhead, Henry De | H24: 4.580431 | I24: 0.21832007 | J24: Ilbdare (IRE) | K24: 7.9562325 | L24: 0.12568763 | M24: =IF(AND(ISNUMBER(I24),ISNUMBER(L24)),I24-L24,"") -> 0.09263244 | N24: 5.5 | O24: =IF(AND(ISNUMBER(H24),H24>0),H24*EXP('Read me'!$B$22),"") -> 5.594551
A25: 4:04 | B25: Hamilton | C25: Barbara Ann Letham And Son Johnathan Memorial Handicap | D25: 9 | E25: City Captain | F25: Tudhope, Daniel | G25: Bethell, Harriet | H25: 2.6592292 | I25: 0.37604882 | J25: Franciscos Piece | K25: 6.1222196 | L25: 0.16333945 | M25: =IF(AND(ISNUMBER(I25),ISNUMBER(L25)),I25-L25,"") -> 0.21270937 | N25: 2.2 | O25: =IF(AND(ISNUMBER(H25),H25>0),H25*EXP('Read me'!$B$22),"") -> 3.2479899
A26: 4:10 | B26: Newton Abbot | C26: Paul Fergusons Jumpers To Follow Handicap Hurdle | D26: 4 | E26: Kom Tu Voudras (FR) | F26: Cobden, Harry | G26: Bramley, Faye | H26: 3.0587372 | I26: 0.3269323 | J26: Kilnew Supreme (IRE) | K26: 3.2802206 | L26: 0.30485755 | M26: =IF(AND(ISNUMBER(I26),ISNUMBER(L26)),I26-L26,"") -> 0.022074758 | N26: 3.5 | O26: =IF(AND(ISNUMBER(H26),H26>0),H26*EXP('Read me'!$B$22),"") -> 3.73595
A27: 4:19 | B27: Down Royal | C27: Pravha Handicap (0-60) (Div 1) | D27: 14 | E27: No More Hiding | F27: Lee, W J | G27: Oliver, Andrew | H27: 3.5675541 | I27: 0.28030409 | J27: Chapel Island (IRE) | K27: 6.9261387 | L27: 0.14438059 | M27: =IF(AND(ISNUMBER(I27),ISNUMBER(L27)),I27-L27,"") -> 0.1359235 | N27: 3.75 | O27: =IF(AND(ISNUMBER(H27),H27>0),H27*EXP('Read me'!$B$22),"") -> 4.3574204
A28: 4:22 | B28: Wolverhampton | C28: Free Tips On attheraces.com Amateur Jockeys Handicap | D28: 10 | E28: No Knee Never (IRE) | F28: Callan, Mr Henry | G28: Owen, J P | H28: 3.5076096 | I28: 0.28509444 | J28: Pursuit Of Truth (IRE) | K28: 6.5228194 | L28: 0.15330794 | M28: =IF(AND(ISNUMBER(I28),ISNUMBER(L28)),I28-L28,"") -> 0.1317865 | N28: 3.5 | O28: =IF(AND(ISNUMBER(H28),H28>0),H28*EXP('Read me'!$B$22),"") -> 4.2842041
A29: 4:27 | B29: Brighton | C29: Play Your Multiples At matchbook.com Handicap | D29: 11 | E29: Campani | F29: Muscutt, D | G29: Simcock, D M | H29: 4.4476212 | I29: 0.22483929 | J29: Royal County Glory (IRE) | K29: 4.6089462 | L29: 0.21696934 | M29: =IF(AND(ISNUMBER(I29),ISNUMBER(L29)),I29-L29,"") -> 0.0078699557 | N29: 5 | O29: =IF(AND(ISNUMBER(H29),H29>0),H29*EXP('Read me'!$B$22),"") -> 5.4323367
A30: 4:30 | B30: Roscommon | C30: Mon 28th Sep 2026 | D30: 4 | E30: Wild Bill Hickok (IRE) | F30: Finegan, Eoghan | G30: Murphy, Ciaran | H30: 1.8662594 | I30: 0.53583121 | J30: Femme Magnifique (IRE) | K30: 4.1708458 | L30: 0.23975952 | M30: =IF(AND(ISNUMBER(I30),ISNUMBER(L30)),I30-L30,"") -> 0.29607168 | N30: 2.5 | O30: =IF(AND(ISNUMBER(H30),H30>0),H30*EXP('Read me'!$B$22),"") -> 2.2794543
A31: 4:38 | B31: Hamilton | C31: Phoenix Drilling Ground Investigation Handicap | D31: 8 | E31: Roach Power (IRE) | F31: Mulrennan, Paul | G31: Wigham, M | H31: 5.6681008 | I31: 0.17642594 | J31: Thunderstorm Katie | K31: 5.8405577 | L31: 0.17121653 | M31: =IF(AND(ISNUMBER(I31),ISNUMBER(L31)),I31-L31,"") -> 0.0052094108 | N31: 3 | O31: =IF(AND(ISNUMBER(H31),H31>0),H31*EXP('Read me'!$B$22),"") -> 6.923034
A32: 4:43 | B32: Newton Abbot | C32: Par Inn Bulpin Cup Amateur Jockeys Handicap Hurdle | D32: 7 | E32: Pooroldmackley (IRE) | F32: Williams, Eleanor | G32: Williams, Mrs C | H32: 2.9188361 | I32: 0.34260231 | J32: Final Entry (IRE) | K32: 5.1859691 | L32: 0.19282799 | M32: =IF(AND(ISNUMBER(I32),ISNUMBER(L32)),I32-L32,"") -> 0.14977432 | N32: 3.25 | O32: =IF(AND(ISNUMBER(H32),H32>0),H32*EXP('Read me'!$B$22),"") -> 3.5650745
A33: 4:50 | B33: Down Royal | C33: Pravha Handicap (0-60) (Div 2) | D33: 14 | E33: Connecteo (IRE) | F33: Coen, Ben M | G33: Oliver, Andrew | H33: 4.4450288 | I33: 0.22497042 | J33: Flagstone Lady (IRE) | K33: 5.07356 | L33: 0.19710026 | M33: =IF(AND(ISNUMBER(I33),ISNUMBER(L33)),I33-L33,"") -> 0.027870158 | N33: 5 | O33: =IF(AND(ISNUMBER(H33),H33>0),H33*EXP('Read me'!$B$22),"") -> 5.4291705
... A46: 8:30 | B46: Wolverhampton | C46: Free Digital Racecard At raceday-ready.com Handicap | D46: 11 | E46: The Anthony Gover | F46: Loughnane, Billy | G46: Newland, Dr R D P | H46: 3.1856754 | I46: 0.31390518 | J46: Back At One (IRE) | K46: 5.1792391 | L46: 0.19307855 | M46: =IF(AND(ISNUMBER(I46),ISNUMBER(L46)),I46-L46,"") -> 0.12082662 | N46: 2.25 | O46: =IF(AND(ISNUMBER(H46),H46>0),H46*EXP('Read me'!$B$22),"") -> 3.8909927

Sheet Non-runners
A1: Time | B1: Course | C1: Horse | D1: Its predicted BSP | E1: Share of the book | F1: Others' prices ×
A2: 1:24 | B2: Down Royal | C2: Stellar Path (IRE) | D2: 21.296503 | E2: 0.046956066 | F2: =IF(ISNUMBER(E2),1-E2,"") -> 0.95304393
A3: 1:24 | B3: Down Royal | C3: The Drambling Man (IRE) | D3: 7.4336004 | E3: 0.13452432 | F3: =IF(ISNUMBER(E3),1-E3,"") -> 0.86547568
A4: 1:35 | B4: Roscommon | C4: Easy Listening (IRE) | D4: 107.62421 | E4: 0.0092915894 | F4: =IF(ISNUMBER(E4),1-E4,"") -> 0.99070841
A5: 1:35 | B5: Roscommon | C5: The Farmers Bar (IRE) | D5: 121.20971 | E5: 0.0082501642 | F5: =IF(ISNUMBER(E5),1-E5,"") -> 0.99174984
A6: 2:05 | B6: Brighton | C6: Poor Relation (FR) | D6: 12.491807 | E6: 0.080052469 | F6: =IF(ISNUMBER(E6),1-E6,"") -> 0.91994753
A7: 2:05 | B7: Brighton | C7: Sakura Impact (IRE) | D7: 90.401938 | E7: 0.01106171 | F7: =IF(ISNUMBER(E7),1-E7,"") -> 0.98893829
A8: 2:10 | B8: Roscommon | C8: Arctic Piper (IRE) | D8: 77.683457 | E8: 0.012872754 | F8: =IF(ISNUMBER(E8),1-E8,"") -> 0.98712725
A9: 2:10 | B9: Roscommon | C9: Colins Friend (IRE) | D9: 5.2303647 | E9: 0.19119126 | F9: =IF(ISNUMBER(E9),1-E9,"") -> 0.80880874
A10: 2:10 | B10: Roscommon | C10: Kome Dans Un Reve (FR) | D10: 91.885249 | E10: 0.01088314 | F10: =IF(ISNUMBER(E10),1-E10,"") -> 0.98911686
A11: 2:25 | B11: Newton Abbot | C11: Ride Like A Girl (FR) | D11: 4.1022518 | E11: 0.24376855 | F11: =IF(ISNUMBER(E11),1-E11,"") -> 0.75623145
A12: 2:34 | B12: Down Royal | C12: Star Glory (IRE) | D12: 3.4254285 | E12: 0.29193428 | F12: =IF(ISNUMBER(E12),1-E12,"") -> 0.70806572
A13: 2:45 | B13: Roscommon | C13: Bigcitydreams (IRE) | D13: 632.58721 | E13: 0.0015808097 | F13: =IF(ISNUMBER(E13),1-E13,"") -> 0.99841919
... A35: 8:30 | B35: Wolverhampton | C35: Vega Storm (IRE) | D35: 12.320136 | E35: 0.081167938 | F35: =IF(ISNUMBER(E35),1-E35,"") -> 0.91883206

Sheet gated 13.43 vs 12.48
A1: Time | B1: Course | C1: Race | D1: Runners (now) | E1: gated 13:43 top pick | F1: gated 13:43 BSP | G1: Its 12:48 BSP | H1: 12:48 top pick (runners still declared) | I1: 12:48 BSP | J1: Same pick? | K1: gated 13:43 vs 12:48 on the gated 13:43's pick
A2: 1:24 | B2: Down Royal | C2: Molson Coors Beverage Company Nursery Handicap | D2: 6 | E2: Santo Parvenue (IRE) | F2: 2.2147676 | G2: 2.2147676 | H2: Santo Parvenue (IRE) | I2: 2.2147676 | J2: =IF(E2=H2,"yes","no") -> yes | K2: =IF(AND(ISNUMBER(F2),ISNUMBER(G2)),F2/G2-1,"") -> 0
A3: 1:30 | B3: Brighton | C3: Matchbook SignUp - Get 20% Back On Losses Handicap | D3: 10 | E3: Bated Breeze (IRE) | F3: 5.1776255 | G3: 5.1776255 | H3: Bated Breeze (IRE) | I3: 5.1776255 | J3: =IF(E3=H3,"yes","no") -> yes | K3: =IF(AND(ISNUMBER(F3),ISNUMBER(G3)),F3/G3-1,"") -> 0
A4: 1:35 | B4: Roscommon | C4: Athleague Maiden Hurdle | D4: 13 | E4: Direct Approach (IRE) | F4: 3.1862358 | G4: 3.1862358 | H4: Direct Approach (IRE) | I4: 3.1862358 | J4: =IF(E4=H4,"yes","no") -> yes | K4: =IF(AND(ISNUMBER(F4),ISNUMBER(G4)),F4/G4-1,"") -> 0
A5: 1:44 | B5: Hamilton | C5: Clearwater DC Ltd Environmental Solutions Amateur Jockeys Handicap | D5: 6 | E5: Annie Edson Taylor | F5: 3.1430511 | G5: 3.1430511 | H5: Annie Edson Taylor | I5: 3.1430511 | J5: =IF(E5=H5,"yes","no") -> yes | K5: =IF(AND(ISNUMBER(F5),ISNUMBER(G5)),F5/G5-1,"") -> 0
A6: 1:50 | B6: Newton Abbot | C6: Celebrating Devon Women In Business Handicap Chase (GBB Race) | D6: 3 | E6: Depalma (IRE) | F6: 2.195562 | G6: 2.195562 | H6: Depalma (IRE) | I6: 2.195562 | J6: =IF(E6=H6,"yes","no") -> yes | K6: =IF(AND(ISNUMBER(F6),ISNUMBER(G6)),F6/G6-1,"") -> 0
A7: 1:59 | B7: Down Royal | C7: Coors Fillies Handicap | D7: 10 | E7: Nellcote (IRE) | F7: 4.9114672 | G7: 4.9114672 | H7: Nellcote (IRE) | I7: 4.9114672 | J7: =IF(E7=H7,"yes","no") -> yes | K7: =IF(AND(ISNUMBER(F7),ISNUMBER(G7)),F7/G7-1,"") -> 0
A8: 2:05 | B8: Brighton | C8: Matchbook Betting Exchange Supporting UK Racing Maiden Stakes (GBB Race) | D8: 4 | E8: Galileo Star | F8: 2.5514401 | G8: 2.4846291 | H8: Galileo Star | I8: 2.4846291 | J8: =IF(E8=H8,"yes","no") -> yes | K8: =IF(AND(ISNUMBER(F8),ISNUMBER(G8)),F8/G8-1,"") -> 0.026889735
A9: 2:10 | B9: Roscommon | C9: Garys Gardening Services Handicap Hurdle (0-100) | D9: 16 | E9: Cool Summer (IRE) | F9: 3.935622 | G9: 3.935622 | H9: Cool Summer (IRE) | I9: 3.935622 | J9: =IF(E9=H9,"yes","no") -> yes | K9: =IF(AND(ISNUMBER(F9),ISNUMBER(G9)),F9/G9-1,"") -> 0
A10: 2:19 | B10: Hamilton | C10: Moira Stein Memorial EBF Restricted Maiden Stakes (GBB Race) | D10: 6 | E10: Cyberspace | F10: 2.0902903 | G10: 2.0902903 | H10: Cyberspace | I10: 2.0902903 | J10: =IF(E10=H10,"yes","no") -> yes | K10: =IF(AND(ISNUMBER(F10),ISNUMBER(G10)),F10/G10-1,"") -> 0
A11: 2:25 | B11: Newton Abbot | C11: Jodie Standings Point-To-Point Recruits Novices Hurdle (GBB Race) | D11: 6 | E11: Matiwo (FR) | F11: 1.3053142 | G11: 1.3053142 | H11: Matiwo (FR) | I11: 1.3053142 | J11: =IF(E11=H11,"yes","no") -> yes | K11: =IF(AND(ISNUMBER(F11),ISNUMBER(G11)),F11/G11-1,"") -> 0
A12: 2:34 | B12: Down Royal | C12: Irish EBF Auction Series Fillies Maiden | D12: 9 | E12: Essence Of Time | F12: 2.308552 | G12: 2.3326166 | H12: Essence Of Time | I12: 2.3326166 | J12: =IF(E12=H12,"yes","no") -> yes | K12: =IF(AND(ISNUMBER(F12),ISNUMBER(G12)),F12/G12-1,"") -> -0.010316546
A13: 2:40 | B13: Brighton | C13: Follow Matchbook On X Nursery | D13: 13 | E13: Magical Life | F13: 6.7963234 | G13: 6.7963234 | H13: Magical Life | I13: 6.7963234 | J13: =IF(E13=H13,"yes","no") -> yes | K13: =IF(AND(ISNUMBER(F13),ISNUMBER(G13)),F13/G13-1,"") -> 0
... A46: 8:30 | B46: Wolverhampton | C46: Free Digital Racecard At raceday-ready.com Handicap | D46: 11 | E46: The Anthony Gover | F46: 3.1856754 | G46: 3.1856754 | H46: The Anthony Gover | I46: 3.1856754 | J46: =IF(E46=H46,"yes","no") -> yes | K46: =IF(AND(ISNUMBER(F46),ISNUMBER(G46)),F46/G46-1,"") -> 0
A48: Races with the same top pick | E48: =COUNTIF(J2:J46,"yes")&" of "&COUNTA(J2:J46) -> 45 of 45
A49: 12:48: the same model on horseracebase's card at 12:48 UTC (predict-now run 33), the workbook sent then. Since then one non-runner (Sakura Impact, Brighton 2:05, a race already run).

Sheet All runners
A1: Time | B1: Course | C1: Race | D1: Class | E1: Furlongs | F1: Going | G1: Runners | H1: Horse | I1: Jockey | J1: Trainer | K1: Draw | L1: OR | M1: Age | N1: Days since run | O1: Model rank | P1: Predicted BSP | Q1: Win probability | R1: Card odds (HRB) | S1: Card odds vs model | T1: Rule: back at Betfair ≥
A2: 1:24 | B2: Down Royal | C2: Molson Coors Beverage Company Nursery Handicap | E2: 5 | F2: Good | G2: 6 | H2: Santo Parvenue (IRE) | I2: Lee, W J | J2: Harty, Edward and Patrick | K2: 4 | L2: 59 | M2: 2 | N2: 11 | O2: 1 | P2: 2.2147676 | Q2: 0.45151465 | R2: 1.8 | S2: =IF(AND(ISNUMBER(R2),R2>1,P2>0),R2/P2-1,"") -> -0.18727363 | T2: =IF(AND(ISNUMBER(P2),P2>0),P2*EXP('Read me'!$B$22),"") -> 2.7051232
A3: 1:24 | B3: Down Royal | C3: Molson Coors Beverage Company Nursery Handicap | E3: 5 | F3: Good | G3: 6 | H3: Premier View (IRE) | I3: Cusack, C | J3: Bromhead, Henry De | K3: 2 | L3: 74 | M3: 2 | N3: 24 | O3: 2 | P3: 4.3596875 | Q3: 0.22937424 | R3: 4.3333333 | S3: =IF(AND(ISNUMBER(R3),R3>1,P3>0),R3/P3-1,"") -> -0.0060449714 | T3: =IF(AND(ISNUMBER(P3),P3>0),P3*EXP('Read me'!$B$22),"") -> 5.3249344
A4: 1:24 | B4: Down Royal | C4: Molson Coors Beverage Company Nursery Handicap | E4: 5 | F4: Good | G4: 6 | H4: Invincible Irish (IRE) | I4: Coen, Ben M | J4: McLoughlin, Daniel | K4: 1 | L4: 61 | M4: 2 | N4: 11 | O4: 3 | P4: 5.9340624 | Q4: 0.16851862 | R4: 6 | S4: =IF(AND(ISNUMBER(R4),R4>1,P4>0),R4/P4-1,"") -> 0.011111717 | T4: =IF(AND(ISNUMBER(P4),P4>0),P4*EXP('Read me'!$B$22),"") -> 7.2478802
A5: 1:24 | B5: Down Royal | C5: Molson Coors Beverage Company Nursery Handicap | E5: 5 | F5: Good | G5: 6 | H5: Rathbran Lady (IRE) | I5: Joyce, Wesley | J5: Mulvany, Michael | K5: 6 | L5: 47 | M5: 2 | N5: 11 | O5: 4 | P5: 15.302509 | Q5: 0.065348762 | R5: 13 | S5: =IF(AND(ISNUMBER(R5),R5>1,P5>0),R5/P5-1,"") -> -0.15046609 | T5: =IF(AND(ISNUMBER(P5),P5>0),P5*EXP('Read me'!$B$22),"") -> 18.690526
A6: 1:24 | B6: Down Royal | C6: Molson Coors Beverage Company Nursery Handicap | E6: 5 | F6: Good | G6: 6 | H6: Annie Tips (IRE) | I6: McAteer, L T | J6: Dowling, James | K6: 7 | L6: 67 | M6: 2 | N6: 36 | O6: 5 | P6: 19.343344 | Q6: 0.051697369 | R6: 19 | S6: =IF(AND(ISNUMBER(R6),R6>1,P6>0),R6/P6-1,"") -> -0.017749989 | T6: =IF(AND(ISNUMBER(P6),P6>0),P6*EXP('Read me'!$B$22),"") -> 23.626014
A7: 1:24 | B7: Down Royal | C7: Molson Coors Beverage Company Nursery Handicap | E7: 5 | F7: Good | G7: 6 | H7: Syrah (IRE) | I7: Mulligan, R M | J7: Weld, Charles | K7: 5 | L7: 58 | M7: 2 | N7: 11 | O7: 6 | P7: 29.809492 | Q7: 0.033546362 | R7: 23 | S7: =IF(AND(ISNUMBER(R7),R7>1,P7>0),R7/P7-1,"") -> -0.22843368 | T7: =IF(AND(ISNUMBER(P7),P7>0),P7*EXP('Read me'!$B$22),"") -> 36.409396
A8: 1:30 | B8: Brighton | C8: Matchbook SignUp - Get 20% Back On Losses Handicap | D8: Class 6 | F8: Good To Firm | G8: 10 | H8: Bated Breeze (IRE) | I8: Marsh, Finley | J8: Moore, Gary and Josh | K8: 3 | L8: 47 | M8: 5 | N8: 21 | O8: 1 | P8: 5.1776255 | Q8: 0.19313873 | R8: 5.5 | S8: =IF(AND(ISNUMBER(R8),R8>1,P8>0),R8/P8-1,"") -> 0.062263002 | T8: =IF(AND(ISNUMBER(P8),P8>0),P8*EXP('Read me'!$B$22),"") -> 6.3239661
A9: 1:30 | B9: Brighton | C9: Matchbook SignUp - Get 20% Back On Losses Handicap | D9: Class 6 | F9: Good To Firm | G9: 10 | H9: Roman Spring (IRE) | I9: ONeill, K T | J9: Bridger, J / Cook, R | K9: 9 | L9: 50 | M9: 6 | N9: 21 | O9: 2 | P9: 6.3779397 | Q9: 0.15679044 | R9: 5 | S9: =IF(AND(ISNUMBER(R9),R9>1,P9>0),R9/P9-1,"") -> -0.21604778 | T9: =IF(AND(ISNUMBER(P9),P9>0),P9*EXP('Read me'!$B$22),"") -> 7.7900331
A10: 1:30 | B10: Brighton | C10: Matchbook SignUp - Get 20% Back On Losses Handicap | D10: Class 6 | F10: Good To Firm | G10: 10 | H10: Dreambird Dolly | I10: Ryan, Rossa | J10: Gallagher, J | K10: 7 | L10: 53 | M10: 4 | N10: 21 | O10: 3 | P10: 6.7049693 | Q10: 0.14914311 | R10: 7.5 | S10: =IF(AND(ISNUMBER(R10),R10>1,P10>0),R10/P10-1,"") -> 0.11857336 | T10: =IF(AND(ISNUMBER(P10),P10>0),P10*EXP('Read me'!$B$22),"") -> 8.189468
A11: 1:30 | B11: Brighton | C11: Matchbook SignUp - Get 20% Back On Losses Handicap | D11: Class 6 | F11: Good To Firm | G11: 10 | H11: Danger Alert | I11: Langley, Taryn | J11: Kirby, Adam | K11: 1 | L11: 59 | M11: 6 | N11: 4 | O11: 4 | P11: 7.4440022 | Q11: 0.13433634 | R11: 4.5 | S11: =IF(AND(ISNUMBER(R11),R11>1,P11>0),R11/P11-1,"") -> -0.39548648 | T11: =IF(AND(ISNUMBER(P11),P11>0),P11*EXP('Read me'!$B$22),"") -> 9.0921248
A12: 1:30 | B12: Brighton | C12: Matchbook SignUp - Get 20% Back On Losses Handicap | D12: Class 6 | F12: Good To Firm | G12: 10 | H12: Beach Partee | I12: Howarth, Christian | J12: Dixon, Scott | K12: 4 | L12: 52 | M12: 3 | N12: 11 | O12: 5 | P12: 9.0419547 | Q12: 0.11059556 | R12: 10 | S12: =IF(AND(ISNUMBER(R12),R12>1,P12>0),R12/P12-1,"") -> 0.10595555 | T12: =IF(AND(ISNUMBER(P12),P12>0),P12*EXP('Read me'!$B$22),"") -> 11.043868
A13: 1:30 | B13: Brighton | C13: Matchbook SignUp - Get 20% Back On Losses Handicap | D13: Class 6 | F13: Good To Firm | G13: 10 | H13: Harry Brown | I13: Hornby, Rob | J13: Crate, Peter | K13: 2 | L13: 52 | M13: 6 | N13: 12 | O13: 6 | P13: 10.257453 | Q13: 0.097490092 | R13: 4 | S13: =IF(AND(ISNUMBER(R13),R13>1,P13>0),R13/P13-1,"") -> -0.61003963 | T13: =IF(AND(ISNUMBER(P13),P13>0),P13*EXP('Read me'!$B$22),"") -> 12.528481
A14: 1:30 | B14: Brighton | C14: Matchbook SignUp - Get 20% Back On Losses Handicap | D14: Class 6 | F14: Good To Firm | G14: 10 | H14: Diamond Dreamer | I14: Probert, David | J14: Chamings, P R | K14: 10 | L14: 58 | M14: 6 | N14: 41 | O14: 7 | P14: 16.868674 | Q14: 0.059281484 | R14: 23 | S14: =IF(AND(ISNUMBER(R14),R14>1,P14>0),R14/P14-1,"") -> 0.36347413 | T14: =IF(AND(ISNUMBER(P14),P14>0),P14*EXP('Read me'!$B$22),"") -> 20.603444
A15: 1:30 | B15: Brighton | C15: Matchbook SignUp - Get 20% Back On Losses Handicap | D15: Class 6 | F15: Good To Firm | G15: 10 | H15: Stapleford Park | I15: Fox, Kieren | J15: Attwater, M J | K15: 8 | L15: 49 | M15: 4 | N15: 26 | O15: 8 | P15: 22.816178 | Q15: 0.04382855 | R15: 34 | S15: =IF(AND(ISNUMBER(R15),R15>1,P15>0),R15/P15-1,"") -> 0.49017069 | T15: =IF(AND(ISNUMBER(P15),P15>0),P15*EXP('Read me'!$B$22),"") -> 27.867743
A16: 1:30 | B16: Brighton | C16: Matchbook SignUp - Get 20% Back On Losses Handicap | D16: Class 6 | F16: Good To Firm | G16: 10 | H16: Anglesey Lad (IRE) | I16: Cox, William | J16: Dixon, Scott | K16: 5 | L16: 45 | M16: 5 | N16: 138 | O16: 9 | P16: 27.754463 | Q16: 0.036030241 | R16: 34 | S16: =IF(AND(ISNUMBER(R16),R16>1,P16>0),R16/P16-1,"") -> 0.2250282 | T16: =IF(AND(ISNUMBER(P16),P16>0),P16*EXP('Read me'!$B$22),"") -> 33.899378
A17: 1:30 | B17: Brighton | C17: Matchbook SignUp - Get 20% Back On Losses Handicap | D17: Class 6 | F17: Good To Firm | G17: 10 | H17: Desdemona | J17: Attwater, M J | K17: 6 | L17: 56 | M17: 4 | N17: 35 | O17: 10 | P17: 51.638347 | Q17: 0.019365454 | R17: 81 | S17: =IF(AND(ISNUMBER(R17),R17>1,P17>0),R17/P17-1,"") -> 0.56860173 | T17: =IF(AND(ISNUMBER(P17),P17>0),P17*EXP('Read me'!$B$22),"") -> 63.071219
A18: 1:35 | B18: Roscommon | C18: Athleague Maiden Hurdle | E18: 15.5 | F18: Good | G18: 13 | H18: Direct Approach (IRE) | I18: Kennedy, J W | J18: Elliott, Gordon | K18: 2 | L18: 97 | M18: 4 | N18: 10 | O18: 1 | P18: 3.1862358 | Q18: 0.31384997 | R18: 5 | S18: =IF(AND(ISNUMBER(R18),R18>1,P18>0),R18/P18-1,"") -> 0.56924983 | T18: =IF(AND(ISNUMBER(P18),P18>0),P18*EXP('Read me'!$B$22),"") -> 3.8916772
A19: 1:35 | B19: Roscommon | C19: Athleague Maiden Hurdle | E19: 15.5 | F19: Good | G19: 13 | H19: Telegram Sam (IRE) | I19: Flanagan, S W | J19: Murray, Adrian | K19: 7 | L19: 0 | M19: 4 | N19: 25 | O19: 2 | P19: 3.1927228 | Q19: 0.31321228 | R19: 1.6153846 | S19: =IF(AND(ISNUMBER(R19),R19>1,P19>0),R19/P19-1,"") -> -0.49404169 | T19: =IF(AND(ISNUMBER(P19),P19>0),P19*EXP('Read me'!$B$22),"") -> 3.8996004
A20: 1:35 | B20: Roscommon | C20: Athleague Maiden Hurdle | E20: 15.5 | F20: Good | G20: 13 | H20: Sonas (IRE) | I20: OKeeffe, Darragh | J20: Bromhead, Henry De | K20: 15 | L20: 0 | M20: 4 | N20: 31 | O20: 3 | P20: 8.1237049 | Q20: 0.12309654 | R20: 10 | S20: =IF(AND(ISNUMBER(R20),R20>1,P20>0),R20/P20-1,"") -> 0.23096545 | T20: =IF(AND(ISNUMBER(P20),P20>0),P20*EXP('Read me'!$B$22),"") -> 9.9223155
A21: 1:35 | B21: Roscommon | C21: Athleague Maiden Hurdle | E21: 15.5 | F21: Good | G21: 13 | H21: God The Highness (IRE) | I21: Meyler, D | J21: Harrington, Mrs John | K21: 3 | L21: 0 | M21: 4 | N21: 54 | O21: 4 | P21: 10.014695 | Q21: 0.099853265 | R21: 7.5 | S21: =IF(AND(ISNUMBER(R21),R21>1,P21>0),R21/P21-1,"") -> -0.25110051 | T21: =IF(AND(ISNUMBER(P21),P21>0),P21*EXP('Read me'!$B$22),"") -> 12.231976
A22: 1:35 | B22: Roscommon | C22: Athleague Maiden Hurdle | E22: 15.5 | F22: Good | G22: 13 | H22: The Flying Rambler (IRE) | I22: King, D | J22: Dempsey, J P | K22: 9 | L22: 0 | M22: 4 | N22: 58 | O22: 5 | P22: 23.925484 | Q22: 0.041796438 | R22: 21 | S22: =IF(AND(ISNUMBER(R22),R22>1,P22>0),R22/P22-1,"") -> -0.12227481 | T22: =IF(AND(ISNUMBER(P22),P22>0),P22*EXP('Read me'!$B$22),"") -> 29.222652
A23: 1:35 | B23: Roscommon | C23: Athleague Maiden Hurdle | E23: 15.5 | F23: Good | G23: 13 | H23: Pallatine Hills (IRE) | I23: Buckley, Kieran | J23: Harty, Edward and Patrick | K23: 6 | L23: 0 | M23: 4 | N23: 23 | O23: 6 | P23: 26.155292 | Q23: 0.038233181 | R23: 15 | S23: =IF(AND(ISNUMBER(R23),R23>1,P23>0),R23/P23-1,"") -> -0.42650229 | T23: =IF(AND(ISNUMBER(P23),P23>0),P23*EXP('Read me'!$B$22),"") -> 31.946145
A24: 1:35 | B24: Roscommon | C24: Athleague Maiden Hurdle | E24: 15.5 | F24: Good | G24: 13 | H24: Abando (GER) | I24: Smith, James | J24: McCann, Anthony | K24: 1 | L24: 0 | M24: 4 | N24: 97 | O24: 7 | P24: 44.129249 | Q24: 0.022660707 | R24: 34 | S24: =IF(AND(ISNUMBER(R24),R24>1,P24>0),R24/P24-1,"") -> -0.22953595 | T24: =IF(AND(ISNUMBER(P24),P24>0),P24*EXP('Read me'!$B$22),"") -> 53.899587
A25: 1:35 | B25: Roscommon | C25: Athleague Maiden Hurdle | E25: 15.5 | F25: Good | G25: 13 | H25: Lucky Signal (FR) | I25: Ewing, Sam | J25: Elliott, Gordon | K25: 5 | L25: 0 | M25: 4 | N25: 25 | O25: 8 | P25: 75.723937 | Q25: 0.013205864 | R25: 101 | S25: =IF(AND(ISNUMBER(R25),R25>1,P25>0),R25/P25-1,"") -> 0.33379225 | T25: =IF(AND(ISNUMBER(P25),P25>0),P25*EXP('Read me'!$B$22),"") -> 92.489425
A26: 1:35 | B26: Roscommon | C26: Athleague Maiden Hurdle | E26: 15.5 | F26: Good | G26: 13 | H26: Gratitudeforgrace (FR) | I26: Gilligan, D J | J26: Elliott, Gordon | K26: 13 | L26: 0 | M26: 4 | N26: 67 | O26: 9 | P26: 85.68318 | Q26: 0.011670902 | R26: 101 | S26: =IF(AND(ISNUMBER(R26),R26>1,P26>0),R26/P26-1,"") -> 0.1787611 | T26: =IF(AND(ISNUMBER(P26),P26>0),P26*EXP('Read me'!$B$22),"") -> 104.65367
A27: 1:35 | B27: Roscommon | C27: Athleague Maiden Hurdle | E27: 15.5 | F27: Good | G27: 13 | H27: Hill Of Berries (IRE) | I27: Gainford, Jordan | J27: Dempsey, J P | K27: 4 | L27: 0 | M27: 4 | O27: 10 | P27: 131.32591 | Q27: 0.0076146435 | R27: 81 | S27: =IF(AND(ISNUMBER(R27),R27>1,P27>0),R27/P27-1,"") -> -0.38321388 | T27: =IF(AND(ISNUMBER(P27),P27>0),P27*EXP('Read me'!$B$22),"") -> 160.40183
A28: 1:35 | B28: Roscommon | C28: Athleague Maiden Hurdle | E28: 15.5 | F28: Good | G28: 13 | H28: Everin Dream (IRE) | I28: Smithers, P T | J28: Fahey, Jarlath P | K28: 12 | L28: 0 | M28: 4 | O28: 11 | P28: 159.93786 | Q28: 0.0062524284 | R28: 101 | S28: =IF(AND(ISNUMBER(R28),R28>1,P28>0),R28/P28-1,"") -> -0.36850473 | T28: =IF(AND(ISNUMBER(P28),P28>0),P28*EXP('Read me'!$B$22),"") -> 195.34854
A29: 1:35 | B29: Roscommon | C29: Athleague Maiden Hurdle | E29: 15.5 | F29: Good | G29: 13 | H29: Neat As A Pin (IRE) | I29: Lane, R J | J29: Bolger, E | K29: 14 | L29: 0 | M29: 4 | N29: 56 | O29: 12 | P29: 167.62823 | Q29: 0.0059655824 | R29: 151 | S29: =IF(AND(ISNUMBER(R29),R29>1,P29>0),R29/P29-1,"") -> -0.09919706 | T29: =IF(AND(ISNUMBER(P29),P29>0),P29*EXP('Read me'!$B$22),"") -> 204.74158
A30: 1:35 | B30: Roscommon | C30: Athleague Maiden Hurdle | E30: 15.5 | F30: Good | G30: 13 | H30: Emmamia (IRE) | I30: Enright, P T | J30: McNiff, Mark Michael | K30: 11 | L30: 0 | M30: 4 | N30: 69 | O30: 13 | P30: 386.36984 | Q30: 0.0025881937 | R30: 201 | S30: =IF(AND(ISNUMBER(R30),R30>1,P30>0),R30/P30-1,"") -> -0.47977306 | T30: =IF(AND(ISNUMBER(P30),P30>0),P30*EXP('Read me'!$B$22),"") -> 471.91319
A31: 1:44 | B31: Hamilton | C31: Clearwater DC Ltd Environmental Solutions Amateur Jockeys Handicap | D31: Class 5 | E31: 6 | F31: Soft | G31: 6 | H31: Annie Edson Taylor | I31: Brown, Pippa | J31: Makin, Phillip | K31: 2 | L31: 72 | M31: 5 | N31: 8 | O31: 1 | P31: 3.1430511 | Q31: 0.31816218 | R31: 2.5 | S31: =IF(AND(ISNUMBER(R31),R31>1,P31>0),R31/P31-1,"") -> -0.20459455 | T31: =IF(AND(ISNUMBER(P31),P31>0),P31*EXP('Read me'!$B$22),"") -> 3.8389313
A32: 1:44 | B32: Hamilton | C32: Clearwater DC Ltd Environmental Solutions Amateur Jockeys Handicap | D32: Class 5 | E32: 6 | F32: Soft | G32: 6 | H32: Bay Breeze | I32: Burley, Miss Rebecca | J32: Easterby, T D | K32: 1 | L32: 62 | M32: 7 | N32: 7 | O32: 2 | P32: 4.5721161 | Q32: 0.21871711 | R32: 3.75 | S32: =IF(AND(ISNUMBER(R32),R32>1,P32>0),R32/P32-1,"") -> -0.17981085 | T32: =IF(AND(ISNUMBER(P32),P32>0),P32*EXP('Read me'!$B$22),"") -> 5.5843952
A33: 1:44 | B33: Hamilton | C33: Clearwater DC Ltd Environmental Solutions Amateur Jockeys Handicap | D33: Class 5 | E33: 6 | F33: Soft | G33: 6 | H33: Lumenbourg | I33: Barlow, Patrick | J33: Camacho, Miss J A | K33: 6 | L33: 65 | M33: 5 | N33: 26 | O33: 3 | P33: 6.4457915 | Q33: 0.15513999 | R33: 6 | S33: =IF(AND(ISNUMBER(R33),R33>1,P33>0),R33/P33-1,"") -> -0.069160085 | T33: =IF(AND(ISNUMBER(P33),P33>0),P33*EXP('Read me'!$B$22),"") -> 7.8729075
A34: 1:44 | B34: Hamilton | C34: Clearwater DC Ltd Environmental Solutions Amateur Jockeys Handicap | D34: Class 5 | E34: 6 | F34: Soft | G34: 6 | H34: Thistle Nil (IRE) | I34: Cagney, Eireann | J34: Goldie, J S | K34: 3 | L34: 68 | M34: 4 | N34: 7 | O34: 4 | P34: 7.120566 | Q34: 0.14043827 | R34: 10 | S34: =IF(AND(ISNUMBER(R34),R34>1,P34>0),R34/P34-1,"") -> 0.40438275 | T34: =IF(AND(ISNUMBER(P34),P34>0),P34*EXP('Read me'!$B$22),"") -> 8.6970789
A35: 1:44 | B35: Hamilton | C35: Clearwater DC Ltd Environmental Solutions Amateur Jockeys Handicap | D35: Class 5 | E35: 6 | F35: Soft | G35: 6 | H35: Maldevious (IRE) | I35: Brown, Mr M W | J35: Ellison, B | K35: 4 | L35: 69 | M35: 4 | N35: 23 | O35: 5 | P35: 8.7790261 | Q35: 0.11390785 | R35: 8 | S35: =IF(AND(ISNUMBER(R35),R35>1,P35>0),R35/P35-1,"") -> -0.088737194 | T35: =IF(AND(ISNUMBER(P35),P35>0),P35*EXP('Read me'!$B$22),"") -> 10.722727
A36: 1:44 | B36: Hamilton | C36: Clearwater DC Ltd Environmental Solutions Amateur Jockeys Handicap | D36: Class 5 | E36: 6 | F36: Soft | G36: 6 | H36: Punchbowl Flyer (IRE) | I36: Hampson, Brodie | J36: Oshea, J G M | K36: 5 | L36: 64 | M36: 9 | N36: 21 | O36: 6 | P36: 18.64468 | Q36: 0.053634603 | R36: 15 | S36: =IF(AND(ISNUMBER(R36),R36>1,P36>0),R36/P36-1,"") -> -0.19548095 | T36: =IF(AND(ISNUMBER(P36),P36>0),P36*EXP('Read me'!$B$22),"") -> 22.772663
A37: 1:50 | B37: Newton Abbot | C37: Celebrating Devon Women In Business Handicap Chase (GBB Race) | D37: Class 3 | E37: 26 | F37: Good | G37: 3 | H37: Depalma (IRE) | I37: Skelton, Harry | J37: Skelton, Daniel | K37: 3 | L37: 102 | M37: 7 | N37: 10 | O37: 1 | P37: 2.195562 | Q37: 0.45546425 | R37: 1.6666667 | S37: =IF(AND(ISNUMBER(R37),R37>1,P37>0),R37/P37-1,"") -> -0.24089292 | T37: =IF(AND(ISNUMBER(P37),P37>0),P37*EXP('Read me'!$B$22),"") -> 2.6816655
A38: 1:50 | B38: Newton Abbot | C38: Celebrating Devon Women In Business Handicap Chase (GBB Race) | D38: Class 3 | E38: 26 | F38: Good | G38: 3 | H38: Muskerry Rock (IRE) | I38: Bowen, Sean P | J38: Bowen, Mickey | K38: 1 | L38: 120 | M38: 7 | N38: 40 | O38: 2 | P38: 3.1859008 | Q38: 0.31388297 | R38: 5.5 | S38: =IF(AND(ISNUMBER(R38),R38>1,P38>0),R38/P38-1,"") -> 0.72635634 | T38: =IF(AND(ISNUMBER(P38),P38>0),P38*EXP('Read me'!$B$22),"") -> 3.891268
A39: 1:50 | B39: Newton Abbot | C39: Celebrating Devon Women In Business Handicap Chase (GBB Race) | D39: Class 3 | E39: 26 | F39: Good | G39: 3 | H39: Limerick Leader (FR) | I39: Bowen, James C | J39: Scholfield, Nick | K39: 2 | L39: 110 | M39: 9 | N39: 12 | O39: 3 | P39: 4.3355211 | Q39: 0.23065278 | R39: 3.5 | S39: =IF(AND(ISNUMBER(R39),R39>1,P39>0),R39/P39-1,"") -> -0.19271526 | T39: =IF(AND(ISNUMBER(P39),P39>0),P39*EXP('Read me'!$B$22),"") -> 5.2954174
A40: 1:59 | B40: Down Royal | C40: Coors Fillies Handicap | E40: 13 | F40: Good | G40: 10 | H40: Nellcote (IRE) | I40: McDonogh, D P | J40: OBrien, Joseph Patrick | K40: 5 | L40: 82 | M40: 3 | N40: 37 | O40: 1 | P40: 4.9114672 | Q40: 0.20360515 | R40: 4.5 | S40: =IF(AND(ISNUMBER(R40),R40>1,P40>0),R40/P40-1,"") -> -0.083776841 | T40: =IF(AND(ISNUMBER(P40),P40>0),P40*EXP('Read me'!$B$22),"") -> 5.9988796
...

Sheet Down Royal
A1: Time | B1: Course | C1: Race | D1: Class | E1: Furlongs | F1: Going | G1: Runners | H1: Horse | I1: Jockey | J1: Trainer | K1: Draw | L1: OR | M1: Age | N1: Days since run | O1: Model rank | P1: Predicted BSP | Q1: Win probability | R1: Card odds (HRB) | S1: Card odds vs model | T1: Rule: back at Betfair ≥
A2: 1:24 | B2: Down Royal | C2: Molson Coors Beverage Company Nursery Handicap | E2: 5 | F2: Good | G2: 6 | H2: Santo Parvenue (IRE) | I2: Lee, W J | J2: Harty, Edward and Patrick | K2: 4 | L2: 59 | M2: 2 | N2: 11 | O2: 1 | P2: 2.2147676 | Q2: 0.45151465 | R2: 1.8 | S2: =IF(AND(ISNUMBER(R2),R2>1,P2>0),R2/P2-1,"") -> -0.18727363 | T2: =IF(AND(ISNUMBER(P2),P2>0),P2*EXP('Read me'!$B$22),"") -> 2.7051232
A3: 1:24 | B3: Down Royal | C3: Molson Coors Beverage Company Nursery Handicap | E3: 5 | F3: Good | G3: 6 | H3: Premier View (IRE) | I3: Cusack, C | J3: Bromhead, Henry De | K3: 2 | L3: 74 | M3: 2 | N3: 24 | O3: 2 | P3: 4.3596875 | Q3: 0.22937424 | R3: 4.3333333 | S3: =IF(AND(ISNUMBER(R3),R3>1,P3>0),R3/P3-1,"") -> -0.0060449714 | T3: =IF(AND(ISNUMBER(P3),P3>0),P3*EXP('Read me'!$B$22),"") -> 5.3249344
A4: 1:24 | B4: Down Royal | C4: Molson Coors Beverage Company Nursery Handicap | E4: 5 | F4: Good | G4: 6 | H4: Invincible Irish (IRE) | I4: Coen, Ben M | J4: McLoughlin, Daniel | K4: 1 | L4: 61 | M4: 2 | N4: 11 | O4: 3 | P4: 5.9340624 | Q4: 0.16851862 | R4: 6 | S4: =IF(AND(ISNUMBER(R4),R4>1,P4>0),R4/P4-1,"") -> 0.011111717 | T4: =IF(AND(ISNUMBER(P4),P4>0),P4*EXP('Read me'!$B$22),"") -> 7.2478802
A5: 1:24 | B5: Down Royal | C5: Molson Coors Beverage Company Nursery Handicap | E5: 5 | F5: Good | G5: 6 | H5: Rathbran Lady (IRE) | I5: Joyce, Wesley | J5: Mulvany, Michael | K5: 6 | L5: 47 | M5: 2 | N5: 11 | O5: 4 | P5: 15.302509 | Q5: 0.065348762 | R5: 13 | S5: =IF(AND(ISNUMBER(R5),R5>1,P5>0),R5/P5-1,"") -> -0.15046609 | T5: =IF(AND(ISNUMBER(P5),P5>0),P5*EXP('Read me'!$B$22),"") -> 18.690526
A6: 1:24 | B6: Down Royal | C6: Molson Coors Beverage Company Nursery Handicap | E6: 5 | F6: Good | G6: 6 | H6: Annie Tips (IRE) | I6: McAteer, L T | J6: Dowling, James | K6: 7 | L6: 67 | M6: 2 | N6: 36 | O6: 5 | P6: 19.343344 | Q6: 0.051697369 | R6: 19 | S6: =IF(AND(ISNUMBER(R6),R6>1,P6>0),R6/P6-1,"") -> -0.017749989 | T6: =IF(AND(ISNUMBER(P6),P6>0),P6*EXP('Read me'!$B$22),"") -> 23.626014
A7: 1:24 | B7: Down Royal | C7: Molson Coors Beverage Company Nursery Handicap | E7: 5 | F7: Good | G7: 6 | H7: Syrah (IRE) | I7: Mulligan, R M | J7: Weld, Charles | K7: 5 | L7: 58 | M7: 2 | N7: 11 | O7: 6 | P7: 29.809492 | Q7: 0.033546362 | R7: 23 | S7: =IF(AND(ISNUMBER(R7),R7>1,P7>0),R7/P7-1,"") -> -0.22843368 | T7: =IF(AND(ISNUMBER(P7),P7>0),P7*EXP('Read me'!$B$22),"") -> 36.409396
A8: 1:59 | B8: Down Royal | C8: Coors Fillies Handicap | E8: 13 | F8: Good | G8: 10 | H8: Nellcote (IRE) | I8: McDonogh, D P | J8: OBrien, Joseph Patrick | K8: 5 | L8: 82 | M8: 3 | N8: 37 | O8: 1 | P8: 4.9114672 | Q8: 0.20360515 | R8: 4.5 | S8: =IF(AND(ISNUMBER(R8),R8>1,P8>0),R8/P8-1,"") -> -0.083776841 | T8: =IF(AND(ISNUMBER(P8),P8>0),P8*EXP('Read me'!$B$22),"") -> 5.9988796
A9: 1:59 | B9: Down Royal | C9: Coors Fillies Handicap | E9: 13 | F9: Good | G9: 10 | H9: Stellar Moment (IRE) | I9: Whelan, R P | J9: ODonoghue, John | K9: 7 | L9: 79 | M9: 3 | N9: 28 | O9: 2 | P9: 5.3404808 | Q9: 0.18724906 | R9: 4.3333333 | S9: =IF(AND(ISNUMBER(R9),R9>1,P9>0),R9/P9-1,"") -> -0.18858742 | T9: =IF(AND(ISNUMBER(P9),P9>0),P9*EXP('Read me'!$B$22),"") -> 6.522878
A10: 1:59 | B10: Down Royal | C10: Coors Fillies Handicap | E10: 13 | F10: Good | G10: 10 | H10: Lady Plimsoll (IRE) | I10: Holohan, Reese | J10: OCallaghan, M D | K10: 9 | L10: 72 | M10: 4 | N10: 12 | O10: 3 | P10: 6.2110078 | Q10: 0.16100447 | R10: 5.5 | S10: =IF(AND(ISNUMBER(R10),R10>1,P10>0),R10/P10-1,"") -> -0.11447543 | T10: =IF(AND(ISNUMBER(P10),P10>0),P10*EXP('Read me'!$B$22),"") -> 7.5861421
A11: 1:59 | B11: Down Royal | C11: Coors Fillies Handicap | E11: 13 | F11: Good | G11: 10 | H11: Navy Waters (IRE) | I11: Lee, W J | J11: McCreery, W | K11: 2 | L11: 84 | M11: 5 | N11: 20 | O11: 4 | P11: 6.735345 | Q11: 0.14847049 | R11: 5.5 | S11: =IF(AND(ISNUMBER(R11),R11>1,P11>0),R11/P11-1,"") -> -0.18341229 | T11: =IF(AND(ISNUMBER(P11),P11>0),P11*EXP('Read me'!$B$22),"") -> 8.226569
A12: 1:59 | B12: Down Royal | C12: Coors Fillies Handicap | E12: 13 | F12: Good | G12: 10 | H12: Vanir (IRE) | I12: Coen, Ben M | J12: Murtagh, J P | K12: 1 | L12: 84 | M12: 3 | N12: 37 | O12: 5 | P12: 13.041516 | Q12: 0.076678201 | R12: 10 | S12: =IF(AND(ISNUMBER(R12),R12>1,P12>0),R12/P12-1,"") -> -0.23321799 | T12: =IF(AND(ISNUMBER(P12),P12>0),P12*EXP('Read me'!$B$22),"") -> 15.928944
A13: 1:59 | B13: Down Royal | C13: Coors Fillies Handicap | E13: 13 | F13: Good | G13: 10 | H13: Just Keep Flying (USA) | I13: Kennedy, K G | J13: Harrington, Mrs John | K13: 8 | L13: 78 | M13: 4 | N13: 108 | O13: 6 | P13: 13.805392 | Q13: 0.072435466 | R13: 12 | S13: =IF(AND(ISNUMBER(R13),R13>1,P13>0),R13/P13-1,"") -> -0.13077441 | T13: =IF(AND(ISNUMBER(P13),P13>0),P13*EXP('Read me'!$B$22),"") -> 16.861944
... A18: 2:34 | B18: Down Royal | C18: Irish EBF Auction Series Fillies Maiden | E18: 7 | F18: Good | G18: 9 | H18: Essence Of Time | I18: Lordan, W M | J18: Oliver, Andrew | K18: 3 | L18: 0 | M18: 2 | N18: 24 | O18: 1 | P18: 2.308552 | Q18: 0.43317196 | R18: 2.2 | S18: =IF(AND(ISNUMBER(R18),R18>1,P18>0),R18/P18-1,"") -> -0.047021693 | T18: =IF(AND(ISNUMBER(P18),P18>0),P18*EXP('Read me'!$B$22),"") -> 2.8196718
A19: 2:34 | B19: Down Royal | C19: Irish EBF Auction Series Fillies Maiden | E19: 7 | F19: Good | G19: 9 | H19: Ladrona (IRE) | I19: Lee, W J | J19: Twomey, P | K19: 9 | L19: 0 | M19: 2 | O19: 2 | P19: 3.9612645 | Q19: 0.25244464 | R19: 4 | S19: =IF(AND(ISNUMBER(R19),R19>1,P19>0),R19/P19-1,"") -> 0.0097785612 | T19: =IF(AND(ISNUMBER(P19),P19>0),P19*EXP('Read me'!$B$22),"") -> 4.8382994
A20: 2:34 | B20: Down Royal | C20: Irish EBF Auction Series Fillies Maiden | E20: 7 | F20: Good | G20: 9 | H20: Hip Hop Chrissy (IRE) | I20: Ryan, Gavin | J20: Obrien, Donnacha | K20: 8 | L20: 78 | M20: 2 | N20: 44 | O20: 3 | P20: 7.6601298 | Q20: 0.13054609 | R20: 6.5 | S20: =IF(AND(ISNUMBER(R20),R20>1,P20>0),R20/P20-1,"") -> -0.15145041 | T20: =IF(AND(ISNUMBER(P20),P20>0),P20*EXP('Read me'!$B$22),"") -> 9.3561037
A21: 2:34 | B21: Down Royal | C21: Irish EBF Auction Series Fillies Maiden | E21: 7 | F21: Good | G21: 9 | H21: Little Scotch (IRE) | I21: Carroll, G F | J21: Cromwell, Gavin Patrick | K21: 7 | L21: 0 | M21: 2 | O21: 4 | P21: 19.326009 | Q21: 0.051743742 | R21: 19 | S21: =IF(AND(ISNUMBER(R21),R21>1,P21>0),R21/P21-1,"") -> -0.016868907 | T21: =IF(AND(ISNUMBER(P21),P21>0),P21*EXP('Read me'!$B$22),"") -> 23.60484
A22: 2:34 | B22: Down Royal | C22: Irish EBF Auction Series Fillies Maiden | E22: 7 | F22: Good | G22: 9 | H22: Leap Of Light (IRE) | I22: Kennedy, K G | J22: Harrington, Mrs John | K22: 6 | L22: 0 | M22: 2 | N22: 11 | O22: 5 | P22: 21.851821 | Q22: 0.045762776 | R22: 7 | S22: =IF(AND(ISNUMBER(R22),R22>1,P22>0),R22/P22-1,"") -> -0.67966057 | T22: =IF(AND(ISNUMBER(P22),P22>0),P22*EXP('Read me'!$B$22),"") -> 26.689874
A23: 2:34 | B23: Down Royal | C23: Irish EBF Auction Series Fillies Maiden | E23: 7 | F23: Good | G23: 9 | H23: Shadowbelle (IRE) | J23: Oliver, Andrew | K23: 10 | L23: 0 | M23: 2 | N23: 11 | O23: 6 | P23: 37.70972 | Q23: 0.026518362 | R23: 51 | S23: =IF(AND(ISNUMBER(R23),R23>1,P23>0),R23/P23-1,"") -> 0.35243645 | T23: =IF(AND(ISNUMBER(P23),P23>0),P23*EXP('Read me'!$B$22),"") -> 46.058756
A24: 2:34 | B24: Down Royal | C24: Irish EBF Auction Series Fillies Maiden | E24: 7 | F24: Good | G24: 9 | H24: Handsoffshesmine (IRE) | I24: Dalton, J S | J24: Slattery, Andrew | K24: 1 | L24: 0 | M24: 2 | O24: 7 | P24: 39.972723 | Q24: 0.02501706 | R24: 34 | S24: =IF(AND(ISNUMBER(R24),R24>1,P24>0),R24/P24-1,"") -> -0.14941996 | T24: =IF(AND(ISNUMBER(P24),P24>0),P24*EXP('Read me'!$B$22),"") -> 48.822794
A25: 2:34 | B25: Down Royal | C25: Irish EBF Auction Series Fillies Maiden | E25: 7 | F25: Good | G25: 9 | H25: Spectrolyte (IRE) | I25: Slattery, A J | J25: Slattery, Andrew | K25: 5 | L25: 0 | M25: 2 | N25: 65 | O25: 8 | P25: 40.672638 | Q25: 0.024586554 | R25: 10 | S25: =IF(AND(ISNUMBER(R25),R25>1,P25>0),R25/P25-1,"") -> -0.75413446 | T25: =IF(AND(ISNUMBER(P25),P25>0),P25*EXP('Read me'!$B$22),"") -> 49.677672
A26: 2:34 | B26: Down Royal | C26: Irish EBF Auction Series Fillies Maiden | E26: 7 | F26: Good | G26: 9 | H26: Alpha Betty (IRE) | I26: Cleary, R P | J26: Farrell, C W J | K26: 2 | L26: 0 | M26: 2 | O26: 9 | P26: 97.954535 | Q26: 0.010208818 | R26: 67 | S26: =IF(AND(ISNUMBER(R26),R26>1,P26>0),R26/P26-1,"") -> -0.31600921 | T26: =IF(AND(ISNUMBER(P26),P26>0),P26*EXP('Read me'!$B$22),"") -> 119.64194
A27: 3:09 | B27: Down Royal | C27: Madri Excepcional Maiden | E27: 7 | F27: Good | G27: 9 | H27: Daring Heart (IRE) | I27: Carroll, G F | J27: Lyons, G M | K27: 2 | L27: 0 | M27: 3 | N27: 136 | O27: 1 | P27: 2.5919908 | Q27: 0.38580384 | R27: 2.1 | S27: =IF(AND(ISNUMBER(R27),R27>1,P27>0),R27/P27-1,"") -> -0.18981194 | T27: =IF(AND(ISNUMBER(P27),P27>0),P27*EXP('Read me'!$B$22),"") -> 3.1658647
A28: 3:09 | B28: Down Royal | C28: Madri Excepcional Maiden | E28: 7 | F28: Good | G28: 9 | H28: Blooming Rose (IRE) | I28: Sheridan, J M | J28: OBrien, Joseph Patrick | K28: 10 | L28: 0 | M28: 3 | N28: 109 | O28: 2 | P28: 4.82396 | Q28: 0.20729857 | R28: 5 | S28: =IF(AND(ISNUMBER(R28),R28>1,P28>0),R28/P28-1,"") -> 0.03649285 | T28: =IF(AND(ISNUMBER(P28),P28>0),P28*EXP('Read me'!$B$22),"") -> 5.891998
A29: 3:09 | B29: Down Royal | C29: Madri Excepcional Maiden | E29: 7 | F29: Good | G29: 9 | H29: Monmouth (IRE) | I29: Lordan, W M | J29: OBrien, A P | K29: 1 | L29: 74 | M29: 3 | N29: 101 | O29: 3 | P29: 5.1813018 | Q29: 0.19300169 | R29: 4.5 | S29: =IF(AND(ISNUMBER(R29),R29>1,P29>0),R29/P29-1,"") -> -0.1314924 | T29: =IF(AND(ISNUMBER(P29),P29>0),P29*EXP('Read me'!$B$22),"") -> 6.3284563
A30: 3:09 | B30: Down Royal | C30: Madri Excepcional Maiden | E30: 7 | F30: Good | G30: 9 | H30: Orellana (IRE) | I30: Rutledge, Siobhan | J30: Rogers, H | K30: 4 | L30: 75 | M30: 3 | N30: 7 | O30: 4 | P30: 6.8158325 | Q30: 0.14671722 | R30: 4.5 | S30: =IF(AND(ISNUMBER(R30),R30>1,P30>0),R30/P30-1,"") -> -0.3397725 | T30: =IF(AND(ISNUMBER(P30),P30>0),P30*EXP('Read me'!$B$22),"") -> 8.3248766
A31: 3:09 | B31: Down Royal | C31: Madri Excepcional Maiden | E31: 7 | F31: Good | G31: 9 | H31: Mac An Luais (IRE) | I31: McAteer, L T | J31: Foley, Patrick T | K31: 6 | L31: 0 | M31: 3 | N31: 101 | O31: 5 | P31: 15.928027 | Q31: 0.062782413 | R31: 21 | S31: =IF(AND(ISNUMBER(R31),R31>1,P31>0),R31/P31-1,"") -> 0.31843068 | T31: =IF(AND(ISNUMBER(P31),P31>0),P31*EXP('Read me'!$B$22),"") -> 19.454537
A32: 3:09 | B32: Down Royal | C32: Madri Excepcional Maiden | E32: 7 | F32: Good | G32: 9 | H32: Monty Bear (IRE) | I32: Holohan, Reese | J32: Fahey, Mark | K32: 3 | L32: 0 | M32: 3 | N32: 283 | O32: 6 | P32: 479.8726 | Q32: 0.0020838864 | R32: 151 | S32: =IF(AND(ISNUMBER(R32),R32>1,P32>0),R32/P32-1,"") -> -0.68533315 | T32: =IF(AND(ISNUMBER(P32),P32>0),P32*EXP('Read me'!$B$22),"") -> 586.11772
A33: 3:09 | B33: Down Royal | C33: Madri Excepcional Maiden | E33: 7 | F33: Good | G33: 9 | H33: Caption This (IRE) | I33: Colgan, R C | J33: Nash, J A | K33: 9 | L33: 0 | M33: 3 | N33: 19 | O33: 7 | P33: 1013.4055 | Q33: 0.00098677184 | R33: 126 | S33: =IF(AND(ISNUMBER(R33),R33>1,P33>0),R33/P33-1,"") -> -0.87566675 | T33: =IF(AND(ISNUMBER(P33),P33>0),P33*EXP('Read me'!$B$22),"") -> 1237.7763
A34: 3:09 | B34: Down Royal | C34: Madri Excepcional Maiden | E34: 7 | F34: Good | G34: 9 | H34: Freddiesadienray (IRE) | I34: Burns, Nicola | J34: Keane, Gerard | K34: 7 | L34: 0 | M34: 3 | N34: 7 | O34: 8 | P34: 1491.7045 | Q34: 0.00067037406 | R34: 126 | S34: =IF(AND(ISNUMBER(R34),R34>1,P34>0),R34/P34-1,"") -> -0.91553287 | T34: =IF(AND(ISNUMBER(P34),P34>0),P34*EXP('Read me'!$B$22),"") -> 1821.972
A35: 3:09 | B35: Down Royal | C35: Madri Excepcional Maiden | E35: 7 | F35: Good | G35: 9 | H35: Notahairoutofplace | I35: Ryan, J J G | J35: Watson, R K | K35: 5 | L35: 0 | M35: 3 | N35: 73 | O35: 9 | P35: 1526.1733 | Q35: 0.00065523356 | R35: 201 | S35: =IF(AND(ISNUMBER(R35),R35>1,P35>0),R35/P35-1,"") -> -0.86829805 | T35: =IF(AND(ISNUMBER(P35),P35>0),P35*EXP('Read me'!$B$22),"") -> 1864.0723
A36: 3:44 | B36: Down Royal | C36: Molson Coors Beverage Company Handicap | E36: 7 | F36: Good | G36: 14 | H36: Send Harry (IRE) | I36: Dalton, J S | J36: McCutcheon, Miss Evanna | K36: 7 | L36: 70 | M36: 4 | N36: 10 | O36: 1 | P36: 6.9803971 | Q36: 0.14325833 | R36: 7 | S36: =IF(AND(ISNUMBER(R36),R36>1,P36>0),R36/P36-1,"") -> 0.0028082771 | T36: =IF(AND(ISNUMBER(P36),P36>0),P36*EXP('Read me'!$B$22),"") -> 8.5258763
A37: 3:44 | B37: Down Royal | C37: Molson Coors Beverage Company Handicap | E37: 7 | F37: Good | G37: 14 | H37: Barbapapa (IRE) | I37: Grant, A S | J37: Bromhead, Henry De | K37: 2 | L37: 74 | M37: 7 | N37: 68 | O37: 2 | P37: 7.3739447 | Q37: 0.13561263 | R37: 7.5 | S37: =IF(AND(ISNUMBER(R37),R37>1,P37>0),R37/P37-1,"") -> 0.017094694 | T37: =IF(AND(ISNUMBER(P37),P37>0),P37*EXP('Read me'!$B$22),"") -> 9.0065564
A38: 3:44 | B38: Down Royal | C38: Molson Coors Beverage Company Handicap | E38: 7 | F38: Good | G38: 14 | H38: Faoladh (IRE) | I38: Coen, S | J38: Slattery, Andrew | K38: 9 | L38: 68 | M38: 4 | N38: 7 | O38: 3 | P38: 7.863027 | Q38: 0.12717749 | R38: 8 | S38: =IF(AND(ISNUMBER(R38),R38>1,P38>0),R38/P38-1,"") -> 0.017419884 | T38: =IF(AND(ISNUMBER(P38),P38>0),P38*EXP('Read me'!$B$22),"") -> 9.6039228
... A91: 5:25 | B91: Down Royal | C91: Molson Coors Beverage Handicap | E91: 13 | F91: Good | G91: 14 | H91: Michinaga (IRE) | I91: McAteer, L T | J91: Weld, Charles | K91: 3 | L91: 76 | M91: 3 | N91: 23 | O91: 14 | P91: 98.132695 | Q91: 0.010190284 | R91: 29 | S91: =IF(AND(ISNUMBER(R91),R91>1,P91>0),R91/P91-1,"") -> -0.70448177 | T91: =IF(AND(ISNUMBER(P91),P91>0),P91*EXP('Read me'!$B$22),"") -> 119.85954

Sheet Brighton
A1: Time | B1: Course | C1: Race | D1: Class | E1: Furlongs | F1: Going | G1: Runners | H1: Horse | I1: Jockey | J1: Trainer | K1: Draw | L1: OR | M1: Age | N1: Days since run | O1: Model rank | P1: Predicted BSP | Q1: Win probability | R1: Card odds (HRB) | S1: Card odds vs model | T1: Rule: back at Betfair ≥
A2: 1:30 | B2: Brighton | C2: Matchbook SignUp - Get 20% Back On Losses Handicap | D2: Class 6 | F2: Good To Firm | G2: 10 | H2: Bated Breeze (IRE) | I2: Marsh, Finley | J2: Moore, Gary and Josh | K2: 3 | L2: 47 | M2: 5 | N2: 21 | O2: 1 | P2: 5.1776255 | Q2: 0.19313873 | R2: 5.5 | S2: =IF(AND(ISNUMBER(R2),R2>1,P2>0),R2/P2-1,"") -> 0.062263002 | T2: =IF(AND(ISNUMBER(P2),P2>0),P2*EXP('Read me'!$B$22),"") -> 6.3239661
A3: 1:30 | B3: Brighton | C3: Matchbook SignUp - Get 20% Back On Losses Handicap | D3: Class 6 | F3: Good To Firm | G3: 10 | H3: Roman Spring (IRE) | I3: ONeill, K T | J3: Bridger, J / Cook, R | K3: 9 | L3: 50 | M3: 6 | N3: 21 | O3: 2 | P3: 6.3779397 | Q3: 0.15679044 | R3: 5 | S3: =IF(AND(ISNUMBER(R3),R3>1,P3>0),R3/P3-1,"") -> -0.21604778 | T3: =IF(AND(ISNUMBER(P3),P3>0),P3*EXP('Read me'!$B$22),"") -> 7.7900331
A4: 1:30 | B4: Brighton | C4: Matchbook SignUp - Get 20% Back On Losses Handicap | D4: Class 6 | F4: Good To Firm | G4: 10 | H4: Dreambird Dolly | I4: Ryan, Rossa | J4: Gallagher, J | K4: 7 | L4: 53 | M4: 4 | N4: 21 | O4: 3 | P4: 6.7049693 | Q4: 0.14914311 | R4: 7.5 | S4: =IF(AND(ISNUMBER(R4),R4>1,P4>0),R4/P4-1,"") -> 0.11857336 | T4: =IF(AND(ISNUMBER(P4),P4>0),P4*EXP('Read me'!$B$22),"") -> 8.189468
A5: 1:30 | B5: Brighton | C5: Matchbook SignUp - Get 20% Back On Losses Handicap | D5: Class 6 | F5: Good To Firm | G5: 10 | H5: Danger Alert | I5: Langley, Taryn | J5: Kirby, Adam | K5: 1 | L5: 59 | M5: 6 | N5: 4 | O5: 4 | P5: 7.4440022 | Q5: 0.13433634 | R5: 4.5 | S5: =IF(AND(ISNUMBER(R5),R5>1,P5>0),R5/P5-1,"") -> -0.39548648 | T5: =IF(AND(ISNUMBER(P5),P5>0),P5*EXP('Read me'!$B$22),"") -> 9.0921248
A6: 1:30 | B6: Brighton | C6: Matchbook SignUp - Get 20% Back On Losses Handicap | D6: Class 6 | F6: Good To Firm | G6: 10 | H6: Beach Partee | I6: Howarth, Christian | J6: Dixon, Scott | K6: 4 | L6: 52 | M6: 3 | N6: 11 | O6: 5 | P6: 9.0419547 | Q6: 0.11059556 | R6: 10 | S6: =IF(AND(ISNUMBER(R6),R6>1,P6>0),R6/P6-1,"") -> 0.10595555 | T6: =IF(AND(ISNUMBER(P6),P6>0),P6*EXP('Read me'!$B$22),"") -> 11.043868
A7: 1:30 | B7: Brighton | C7: Matchbook SignUp - Get 20% Back On Losses Handicap | D7: Class 6 | F7: Good To Firm | G7: 10 | H7: Harry Brown | I7: Hornby, Rob | J7: Crate, Peter | K7: 2 | L7: 52 | M7: 6 | N7: 12 | O7: 6 | P7: 10.257453 | Q7: 0.097490092 | R7: 4 | S7: =IF(AND(ISNUMBER(R7),R7>1,P7>0),R7/P7-1,"") -> -0.61003963 | T7: =IF(AND(ISNUMBER(P7),P7>0),P7*EXP('Read me'!$B$22),"") -> 12.528481
A8: 1:30 | B8: Brighton | C8: Matchbook SignUp - Get 20% Back On Losses Handicap | D8: Class 6 | F8: Good To Firm | G8: 10 | H8: Diamond Dreamer | I8: Probert, David | J8: Chamings, P R | K8: 10 | L8: 58 | M8: 6 | N8: 41 | O8: 7 | P8: 16.868674 | Q8: 0.059281484 | R8: 23 | S8: =IF(AND(ISNUMBER(R8),R8>1,P8>0),R8/P8-1,"") -> 0.36347413 | T8: =IF(AND(ISNUMBER(P8),P8>0),P8*EXP('Read me'!$B$22),"") -> 20.603444
A9: 1:30 | B9: Brighton | C9: Matchbook SignUp - Get 20% Back On Losses Handicap | D9: Class 6 | F9: Good To Firm | G9: 10 | H9: Stapleford Park | I9: Fox, Kieren | J9: Attwater, M J | K9: 8 | L9: 49 | M9: 4 | N9: 26 | O9: 8 | P9: 22.816178 | Q9: 0.04382855 | R9: 34 | S9: =IF(AND(ISNUMBER(R9),R9>1,P9>0),R9/P9-1,"") -> 0.49017069 | T9: =IF(AND(ISNUMBER(P9),P9>0),P9*EXP('Read me'!$B$22),"") -> 27.867743
A10: 1:30 | B10: Brighton | C10: Matchbook SignUp - Get 20% Back On Losses Handicap | D10: Class 6 | F10: Good To Firm | G10: 10 | H10: Anglesey Lad (IRE) | I10: Cox, William | J10: Dixon, Scott | K10: 5 | L10: 45 | M10: 5 | N10: 138 | O10: 9 | P10: 27.754463 | Q10: 0.036030241 | R10: 34 | S10: =IF(AND(ISNUMBER(R10),R10>1,P10>0),R10/P10-1,"") -> 0.2250282 | T10: =IF(AND(ISNUMBER(P10),P10>0),P10*EXP('Read me'!$B$22),"") -> 33.899378
A11: 1:30 | B11: Brighton | C11: Matchbook SignUp - Get 20% Back On Losses Handicap | D11: Class 6 | F11: Good To Firm | G11: 10 | H11: Desdemona | J11: Attwater, M J | K11: 6 | L11: 56 | M11: 4 | N11: 35 | O11: 10 | P11: 51.638347 | Q11: 0.019365454 | R11: 81 | S11: =IF(AND(ISNUMBER(R11),R11>1,P11>0),R11/P11-1,"") -> 0.56860173 | T11: =IF(AND(ISNUMBER(P11),P11>0),P11*EXP('Read me'!$B$22),"") -> 63.071219
A12: 2:05 | B12: Brighton | C12: Matchbook Betting Exchange Supporting UK Racing Maiden Stakes (GBB Race) | D12: Class 4 | E12: 7 | F12: Good To Firm | G12: 4 | H12: Galileo Star | I12: Ryan, Rossa | J12: Tate, James | K12: 6 | L12: 0 | M12: 3 | O12: 1 | P12: 2.5514401 | Q12: 0.39193551 | R12: 1.5714286 | S12: =IF(AND(ISNUMBER(R12),R12>1,P12>0),R12/P12-1,"") -> -0.38410134 | T12: =IF(AND(ISNUMBER(P12),P12>0),P12*EXP('Read me'!$B$22),"") -> 3.116336
A13: 2:05 | B13: Brighton | C13: Matchbook Betting Exchange Supporting UK Racing Maiden Stakes (GBB Race) | D13: Class 4 | E13: 7 | F13: Good To Firm | G13: 4 | H13: River Nile (IRE) | I13: Watson, Jason | J13: Balding, A M | K13: 3 | L13: 74 | M13: 3 | N13: 11 | O13: 2 | P13: 2.984331 | Q13: 0.33508347 | R13: 3 | S13: =IF(AND(ISNUMBER(R13),R13>1,P13>0),R13/P13-1,"") -> 0.0052504123 | T13: =IF(AND(ISNUMBER(P13),P13>0),P13*EXP('Read me'!$B$22),"") -> 3.6450702
A14: 2:05 | B14: Brighton | C14: Matchbook Betting Exchange Supporting UK Racing Maiden Stakes (GBB Race) | D14: Class 4 | E14: 7 | F14: Good To Firm | G14: 4 | H14: All Shall Be Well | I14: Shoemark, Kieran | J14: Jones, Jack | K14: 1 | L14: 0 | M14: 3 | N14: 25 | O14: 3 | P14: 3.807163 | Q14: 0.26266277 | R14: 7 | S14: =IF(AND(ISNUMBER(R14),R14>1,P14>0),R14/P14-1,"") -> 0.83863942 | T14: =IF(AND(ISNUMBER(P14),P14>0),P14*EXP('Read me'!$B$22),"") -> 4.6500794
A15: 2:05 | B15: Brighton | C15: Matchbook Betting Exchange Supporting UK Racing Maiden Stakes (GBB Race) | D15: Class 4 | E15: 7 | F15: Good To Firm | G15: 4 | H15: Irish Spring | I15: Hogan, D E | J15: Jewell, Karen | K15: 5 | L15: 0 | M15: 4 | N15: 32 | O15: 4 | P15: 96.91573 | Q15: 0.010318242 | R15: 101 | S15: =IF(AND(ISNUMBER(R15),R15>1,P15>0),R15/P15-1,"") -> 0.042142488 | T15: =IF(AND(ISNUMBER(P15),P15>0),P15*EXP('Read me'!$B$22),"") -> 118.37314
A16: 2:40 | B16: Brighton | C16: Follow Matchbook On X Nursery | D16: Class 6 | E16: 8 | F16: Good To Firm | G16: 13 | H16: Magical Life | I16: Ryan, Rossa | J16: Moore, J S | K16: 5 | L16: 57 | M16: 2 | N16: 15 | O16: 1 | P16: 6.7963234 | Q16: 0.14713838 | R16: 5.5 | S16: =IF(AND(ISNUMBER(R16),R16>1,P16>0),R16/P16-1,"") -> -0.19073892 | T16: =IF(AND(ISNUMBER(P16),P16>0),P16*EXP('Read me'!$B$22),"") -> 8.3010481
A17: 2:40 | B17: Brighton | C17: Follow Matchbook On X Nursery | D17: Class 6 | E17: 8 | F17: Good To Firm | G17: 13 | H17: Hello You Ten (IRE) | I17: Osborne, Saffie | J17: Osborne, J A | K17: 3 | L17: 63 | M17: 2 | N17: 17 | O17: 2 | P17: 8.0427547 | Q17: 0.12433551 | R17: 5 | S17: =IF(AND(ISNUMBER(R17),R17>1,P17>0),R17/P17-1,"") -> -0.37832245 | T17: =IF(AND(ISNUMBER(P17),P17>0),P17*EXP('Read me'!$B$22),"") -> 9.8234428
A18: 2:40 | B18: Brighton | C18: Follow Matchbook On X Nursery | D18: Class 6 | E18: 8 | F18: Good To Firm | G18: 13 | H18: Banged Up | I18: Bishop, Charles | J18: Houghton, Eve Johnson | K18: 13 | L18: 63 | M18: 2 | N18: 35 | O18: 3 | P18: 8.7848286 | Q18: 0.11383261 | R18: 15 | S18: =IF(AND(ISNUMBER(R18),R18>1,P18>0),R18/P18-1,"") -> 0.7074892 | T18: =IF(AND(ISNUMBER(P18),P18>0),P18*EXP('Read me'!$B$22),"") -> 10.729814
A19: 2:40 | B19: Brighton | C19: Follow Matchbook On X Nursery | D19: Class 6 | E19: 8 | F19: Good To Firm | G19: 13 | H19: Wild Orchid | I19: Callan, Jack | J19: Johnston, Charlie | K19: 11 | L19: 50 | M19: 2 | N19: 11 | O19: 4 | P19: 10.888916 | Q19: 0.091836504 | R19: 8 | S19: =IF(AND(ISNUMBER(R19),R19>1,P19>0),R19/P19-1,"") -> -0.26530797 | T19: =IF(AND(ISNUMBER(P19),P19>0),P19*EXP('Read me'!$B$22),"") -> 13.299752
A20: 2:40 | B20: Brighton | C20: Follow Matchbook On X Nursery | D20: Class 6 | E20: 8 | F20: Good To Firm | G20: 13 | H20: Blue Skies Above | I20: Shoemark, Kieran | J20: Cole, Oliver | K20: 12 | L20: 62 | M20: 2 | N20: 21 | O20: 5 | P20: 11.739505 | Q20: 0.085182468 | R20: 6.5 | S20: =IF(AND(ISNUMBER(R20),R20>1,P20>0),R20/P20-1,"") -> -0.44631396 | T20: =IF(AND(ISNUMBER(P20),P20>0),P20*EXP('Read me'!$B$22),"") -> 14.338664
A21: 2:40 | B21: Brighton | C21: Follow Matchbook On X Nursery | D21: Class 6 | E21: 8 | F21: Good To Firm | G21: 13 | H21: Mandolin Rain (IRE) | I21: Probert, David | J21: Cunha, Dylan | K21: 6 | L21: 65 | M21: 2 | N21: 13 | O21: 6 | P21: 12.353536 | Q21: 0.080948485 | R21: 13 | S21: =IF(AND(ISNUMBER(R21),R21>1,P21>0),R21/P21-1,"") -> 0.052330303 | T21: =IF(AND(ISNUMBER(P21),P21>0),P21*EXP('Read me'!$B$22),"") -> 15.088643
A22: 2:40 | B22: Brighton | C22: Follow Matchbook On X Nursery | D22: Class 6 | E22: 8 | F22: Good To Firm | G22: 13 | H22: Allaboutthelunch | I22: Chalmers, Isobelle | J22: Smyth-Osbourne, Edward | K22: 9 | L22: 46 | M22: 2 | N22: 15 | O22: 7 | P22: 14.861761 | Q22: 0.067286778 | R22: 8.5 | S22: =IF(AND(ISNUMBER(R22),R22>1,P22>0),R22/P22-1,"") -> -0.42806239 | T22: =IF(AND(ISNUMBER(P22),P22>0),P22*EXP('Read me'!$B$22),"") -> 18.152196
A23: 2:40 | B23: Brighton | C23: Follow Matchbook On X Nursery | D23: Class 6 | E23: 8 | F23: Good To Firm | G23: 13 | H23: Enhancing | I23: Fallon, Cieren | J23: Palmer, Hugo | K23: 1 | L23: 62 | M23: 2 | N23: 84 | O23: 8 | P23: 16.328806 | Q23: 0.061241465 | R23: 15 | S23: =IF(AND(ISNUMBER(R23),R23>1,P23>0),R23/P23-1,"") -> -0.081378027 | T23: =IF(AND(ISNUMBER(P23),P23>0),P23*EXP('Read me'!$B$22),"") -> 19.944049
