Workbook

Sheet Read me
A1: Predictions for 2026-09-29
A3: Runners | B3: 364
A4: Races | B4: 38
A5: Meetings | B5: 5
A7: The model | B7: gated 10:53
A8: Features | B8: 993
A9: Trained through | B9: 2026-09-22
A10: Boosting rounds | B10: 12000
A11: Target | B11: logit_norm_prob
A12: Feature code hash | B12: f879b10c8369467a
A14: How to read it
A15: Predicted BSP | B15: The model's forecast of the Betfair Starting Price, from pre-race information only. The prices in each race make a book of exactly 100%.
A16: Win probability | B16: 1 / predicted BSP: the model's chance for the horse, normalised within the race.
A17: Model rank | B17: 1 = the model's shortest price in the race (highlighted green).
A18: Card odds (HRB) | B18: The odds printed on the horseracebase card when it was fetched: a bookmaker forecast, not the Betfair morning price the early-price rule was tested against.
A19: Card odds vs model | B19: Card odds / predicted BSP - 1. Positive: the card is longer than the model.
A21: The early-price rule
A22: Margin (log) | B22: 0.2
A23: Rule: back at Betfair ≥ | B23: Predicted BSP × e^margin: at 0.2, a Betfair price at least 1.22 times the model's (the model at least 22% shorter). The rule was fixed before it was first tested (reports/clv_betfair_2026q1.md): back at Betfair's morning volume-weighted price, where at least £100 has been matched in the morning, and close the position at BSP (lay at BSP to level the book). It is a trade on the price, not a bet held to the result. The margin (blue) is the one input: change it to see the prices at another threshold.
A25: Note | B25: The served model (the complete-careers pair gated with race_xent), re-run in full on horseracebase's card as it stood at 10:53 UTC (predict-now run 38): 364 runners in 38 races, every one priced, each race a book of 100%. All 11 of the day's non-runners are out (sheet Non-runners, each with its share of the book in the last run that priced it), and every price is compared with the 09:37 re-run. 11 non-runners since the prices were first made, in 9 races (sheet Non-runners). The prices here are without them, each race a book of 100%: a non-runner's share of the book goes to the rest of its race, whose prices shorten by about that share.

Sheet Top picks
A1: Time | B1: Course | C1: Race | D1: Runners | E1: Top pick | F1: Jockey | G1: Trainer | H1: Predicted BSP | I1: Win probability | J1: Second choice | K1: Second's BSP | L1: Second's probability | M1: Probability gap | N1: Card odds (HRB) | O1: Rule: back at Betfair ≥
A2: 1:55 | B2: Cork | C2: Irish Stallion Farms EBF Maiden | D2: 13 | E2: Bold Commander (IRE) | F2: Lordan, W M | G2: OBrien, A P | H2: 4.6201822 | I2: 0.21644168 | J2: Sonny Hayes (IRE) | K2: 5.1099387 | L2: 0.19569706 | M2: =IF(AND(ISNUMBER(I2),ISNUMBER(L2)),I2-L2,"") -> 0.020744618 | N2: 2.5 | O2: =IF(AND(ISNUMBER(H2),H2>0),H2*EXP('Read me'!$B$22),"") -> 5.6431032
A3: 2:02 | B3: Bath | C3: JDL Consultants Ltd Apprentice Handicap | D3: 11 | E3: Decalogue (USA) | F3: Paetel, Mason | G3: Osborne, J A | H3: 5.5561386 | I3: 0.17998111 | J3: Pangbourne | K3: 6.4064338 | L3: 0.15609308 | M3: =IF(AND(ISNUMBER(I3),ISNUMBER(L3)),I3-L3,"") -> 0.023888028 | N3: 4.5 | O3: =IF(AND(ISNUMBER(H3),H3>0),H3*EXP('Read me'!$B$22),"") -> 6.786283
A4: 2:08 | B4: Ayr | C4: Christmas Party Day Dancing At Ayr Racecourse Apprentice Handicap | D4: 8 | E4: Empirestateofmind (IRE) | F4: Callan, Jack | G4: Quinn, J J | H4: 3.2135037 | I4: 0.31118682 | J4: Motawaared | K4: 5.1649624 | L4: 0.19361225 | M4: =IF(AND(ISNUMBER(I4),ISNUMBER(L4)),I4-L4,"") -> 0.11757457 | N4: 2.75 | O4: =IF(AND(ISNUMBER(H4),H4>0),H4*EXP('Read me'!$B$22),"") -> 3.9249823
A5: 2:15 | B5: Sedgefield | C5: Happy 96th Birthday John Conditional Jockeys Handicap Hurdle | D5: 7 | E5: Spartan Times | F5: Scott, Luke | G5: Candlish, Jennie | H5: 3.3706659 | I5: 0.29667728 | J5: Jolie Coeur Allen (FR) | K5: 5.2106078 | L5: 0.19191619 | M5: =IF(AND(ISNUMBER(I5),ISNUMBER(L5)),I5-L5,"") -> 0.10476109 | N5: 2.875 | O5: =IF(AND(ISNUMBER(H5),H5>0),H5*EXP('Read me'!$B$22),"") -> 4.1169407
A6: 2:25 | B6: Cork | C6: Irish Stallion Farms EBF Nursery Handicap (Birdcatcher Series) | D6: 7 | E6: Pink Venom (IRE) | F6: Coen, Ben M | G6: Murtagh, J P | H6: 2.9968914 | I6: 0.33367909 | J6: Fine Line (IRE) | K6: 5.8739402 | L6: 0.17024348 | M6: =IF(AND(ISNUMBER(I6),ISNUMBER(L6)),I6-L6,"") -> 0.16343561 | N6: 2 | O6: =IF(AND(ISNUMBER(H6),H6>0),H6*EXP('Read me'!$B$22),"") -> 3.6604114
A7: 2:32 | B7: Bath | C7: MJ Church Handicap | D7: 13 | E7: Cosmo Brown (IRE) | F7: Edmunds, Lewis | G7: Muir, W R & Grassick, C | H7: 6.0547482 | I7: 0.16515963 | J7: Zarco | K7: 7.0423239 | L7: 0.14199858 | M7: =IF(AND(ISNUMBER(I7),ISNUMBER(L7)),I7-L7,"") -> 0.023161053 | N7: 6 | O7: =IF(AND(ISNUMBER(H7),H7>0),H7*EXP('Read me'!$B$22),"") -> 7.3952862
A8: 2:38 | B8: Ayr | C8: Weddings At Western House Hotel Maiden Stakes (GBB Race) | D8: 6 | E8: Melody Man | F8: Hart, Jason | G8: Quinn, J J | H8: 3.0885181 | I8: 0.32377987 | J8: What A Girl Wants (IRE) | K8: 3.9448211 | L8: 0.25349692 | M8: =IF(AND(ISNUMBER(I8),ISNUMBER(L8)),I8-L8,"") -> 0.070282951 | N8: 7 | O8: =IF(AND(ISNUMBER(H8),H8>0),H8*EXP('Read me'!$B$22),"") -> 3.7723246
A9: 2:45 | B9: Sedgefield | C9: Roxyfet Sports Lounge For Private Hire Juvenile Maiden Hurdle (GBB Race) | D9: 7 | E9: Steel Raven (IRE) | F9: Hughes, Brian | G9: Keatley, Adrian Paul | H9: 1.3730685 | I9: 0.72829576 | J9: Jerseygeordie | K9: 9.9272015 | L9: 0.10073332 | M9: =IF(AND(ISNUMBER(I9),ISNUMBER(L9)),I9-L9,"") -> 0.62756244 | N9: 1.6153846 | O9: =IF(AND(ISNUMBER(H9),H9>0),H9*EXP('Read me'!$B$22),"") -> 1.6770697
A10: 2:55 | B10: Cork | C10: Irish Stallion Farms EBF Fillies Handicap | D10: 9 | E10: By The Lake (IRE) | F10: Keane, C T | G10: McCormack, Derek | H10: 4.7378235 | I10: 0.21106738 | J10: Forza Magico | K10: 6.5293068 | L10: 0.15315562 | M10: =IF(AND(ISNUMBER(I10),ISNUMBER(L10)),I10-L10,"") -> 0.057911764 | N10: 7.5 | O10: =IF(AND(ISNUMBER(H10),H10>0),H10*EXP('Read me'!$B$22),"") -> 5.7867907
A11: 3:02 | B11: Bath | C11: AEL Solutions Handicap | D11: 12 | E11: Buckland Belle | F11: Marquand, Tom | G11: Sangster, Ollie | H11: 3.2266287 | I11: 0.309921 | J11: Rating (IRE) | K11: 6.9381041 | L11: 0.14413159 | M11: =IF(AND(ISNUMBER(I11),ISNUMBER(L11)),I11-L11,"") -> 0.16578941 | N11: 2.875 | O11: =IF(AND(ISNUMBER(H11),H11>0),H11*EXP('Read me'!$B$22),"") -> 3.9410132
A12: 3:08 | B12: Ayr | C12: Nairnss Oatcakes Handicap (GBBPlus Race) | D12: 9 | E12: Star Cast | F12: Dickson, Jake | G12: Tutty, Gemma | H12: 5.2588233 | I12: 0.19015661 | J12: Keep An Eye On It | K12: 5.3288144 | L12: 0.187659 | M12: =IF(AND(ISNUMBER(I12),ISNUMBER(L12)),I12-L12,"") -> 0.0024976039 | N12: 4 | O12: =IF(AND(ISNUMBER(H12),H12>0),H12*EXP('Read me'!$B$22),"") -> 6.4231413
A13: 3:15 | B13: Sedgefield | C13: Paxtons No1 CaseIH Dealer Handicap Chase (GBB Race) | D13: 4 | E13: Passengerontheship (IRE) | F13: England, Jonathan | G13: England, Sam | H13: 2.5505 | I13: 0.39207999 | J13: Thank You Blue | K13: 3.5014656 | L13: 0.2855947 | M13: =IF(AND(ISNUMBER(I13),ISNUMBER(L13)),I13-L13,"") -> 0.10648529 | N13: 2.5 | O13: =IF(AND(ISNUMBER(H13),H13>0),H13*EXP('Read me'!$B$22),"") -> 3.1151877
... A39: 8:30 | B39: Wolverhampton | C39: Sky Sports Racing Sky 415 Handicap (Div 2) | D39: 8 | E39: African Spirit (IRE) | F39: Loughnane, Billy | G39: Williams, Ian | H39: 2.6247749 | I39: 0.38098505 | J39: Dumfries | K39: 5.0308556 | L39: 0.19877335 | M39: =IF(AND(ISNUMBER(I39),ISNUMBER(L39)),I39-L39,"") -> 0.1822117 | N39: 3.5 | O39: =IF(AND(ISNUMBER(H39),H39>0),H39*EXP('Read me'!$B$22),"") -> 3.2059073

Sheet Non-runners
A1: Time | B1: Course | C1: Horse | D1: Its predicted BSP | E1: Share of the book | F1: Others' prices ×
A2: 3:02 | B2: Bath | C2: Mayberry Moon | D2: 45.456645 | E2: 0.021998984 | F2: =IF(ISNUMBER(E2),1-E2,"") -> 0.97800102
A3: 3:25 | B3: Cork | C3: Ukiyo (IRE) | D3: 16.090698 | E3: 0.062147708 | F3: =IF(ISNUMBER(E3),1-E3,"") -> 0.93785229
A4: 4:25 | B4: Cork | C4: Knightlight | D4: 102.98665 | E4: 0.0097099967 | F4: =IF(ISNUMBER(E4),1-E4,"") -> 0.99029
A5: 5:25 | B5: Cork | C5: Blue Orquidea (IRE) | D5: 84.053113 | E5: 0.011897239 | F5: =IF(ISNUMBER(E5),1-E5,"") -> 0.98810276
A6: 5:25 | B6: Cork | C6: Cause I Like You (IRE) | D6: 8.1881084 | E6: 0.12212833 | F6: =IF(ISNUMBER(E6),1-E6,"") -> 0.87787167
A7: 5:25 | B7: Cork | C7: Jazz Dreamers (IRE) | D7: 57.396099 | E7: 0.017422787 | F7: =IF(ISNUMBER(E7),1-E7,"") -> 0.98257721
A8: 5:30 | B8: Wolverhampton | C8: Arabian Summer (IRE) | D8: 4.2894501 | E8: 0.23313011 | F8: =IF(ISNUMBER(E8),1-E8,"") -> 0.76686989
A9: 6:00 | B9: Wolverhampton | C9: Venetian Romance (IRE) | D9: 348.91062 | E9: 0.0028660635 | F9: =IF(ISNUMBER(E9),1-E9,"") -> 0.99713394
A10: 7:00 | B10: Wolverhampton | C10: Cosmic Clarets (IRE) | D10: 12.451783 | E10: 0.080309786 | F10: =IF(ISNUMBER(E10),1-E10,"") -> 0.91969021
A11: 8:00 | B11: Wolverhampton | C11: Tortola (IRE) | D11: 9.8599752 | E11: 0.10142013 | F11: =IF(ISNUMBER(E11),1-E11,"") -> 0.89857987
A12: 8:30 | B12: Wolverhampton | C12: Book Of Life | D12: 4.3426933 | E12: 0.23027184 | F12: =IF(ISNUMBER(E12),1-E12,"") -> 0.76972816

Sheet gated 10.53 vs 09.37
A1: Time | B1: Course | C1: Race | D1: Runners (now) | E1: gated 10:53 top pick | F1: gated 10:53 BSP | G1: Its 09:37 BSP | H1: 09:37 top pick (runners still declared) | I1: 09:37 BSP | J1: Same pick? | K1: gated 10:53 vs 09:37 on the gated 10:53's pick
A2: 1:55 | B2: Cork | C2: Irish Stallion Farms EBF Maiden | D2: 13 | E2: Bold Commander (IRE) | F2: 4.6201822 | G2: 4.6201822 | H2: Bold Commander (IRE) | I2: 4.6201822 | J2: =IF(E2=H2,"yes","no") -> yes | K2: =IF(AND(ISNUMBER(F2),ISNUMBER(G2)),F2/G2-1,"") -> 0
A3: 2:02 | B3: Bath | C3: JDL Consultants Ltd Apprentice Handicap | D3: 11 | E3: Decalogue (USA) | F3: 5.5561386 | G3: 5.5561386 | H3: Decalogue (USA) | I3: 5.5561386 | J3: =IF(E3=H3,"yes","no") -> yes | K3: =IF(AND(ISNUMBER(F3),ISNUMBER(G3)),F3/G3-1,"") -> 0
A4: 2:08 | B4: Ayr | C4: Christmas Party Day Dancing At Ayr Racecourse Apprentice Handicap | D4: 8 | E4: Empirestateofmind (IRE) | F4: 3.2135037 | G4: 3.2135037 | H4: Empirestateofmind (IRE) | I4: 3.2135037 | J4: =IF(E4=H4,"yes","no") -> yes | K4: =IF(AND(ISNUMBER(F4),ISNUMBER(G4)),F4/G4-1,"") -> 0
A5: 2:15 | B5: Sedgefield | C5: Happy 96th Birthday John Conditional Jockeys Handicap Hurdle | D5: 7 | E5: Spartan Times | F5: 3.3706659 | G5: 3.3706659 | H5: Spartan Times | I5: 3.3706659 | J5: =IF(E5=H5,"yes","no") -> yes | K5: =IF(AND(ISNUMBER(F5),ISNUMBER(G5)),F5/G5-1,"") -> 0
A6: 2:25 | B6: Cork | C6: Irish Stallion Farms EBF Nursery Handicap (Birdcatcher Series) | D6: 7 | E6: Pink Venom (IRE) | F6: 2.9968914 | G6: 2.9977529 | H6: Pink Venom (IRE) | I6: 2.9977529 | J6: =IF(E6=H6,"yes","no") -> yes | K6: =IF(AND(ISNUMBER(F6),ISNUMBER(G6)),F6/G6-1,"") -> -0.00028736794
A7: 2:32 | B7: Bath | C7: MJ Church Handicap | D7: 13 | E7: Cosmo Brown (IRE) | F7: 6.0547482 | G7: 6.0547482 | H7: Cosmo Brown (IRE) | I7: 6.0547482 | J7: =IF(E7=H7,"yes","no") -> yes | K7: =IF(AND(ISNUMBER(F7),ISNUMBER(G7)),F7/G7-1,"") -> 0
A8: 2:38 | B8: Ayr | C8: Weddings At Western House Hotel Maiden Stakes (GBB Race) | D8: 6 | E8: Melody Man | F8: 3.0885181 | G8: 3.0885181 | H8: Melody Man | I8: 3.0885181 | J8: =IF(E8=H8,"yes","no") -> yes | K8: =IF(AND(ISNUMBER(F8),ISNUMBER(G8)),F8/G8-1,"") -> 0
A9: 2:45 | B9: Sedgefield | C9: Roxyfet Sports Lounge For Private Hire Juvenile Maiden Hurdle (GBB Race) | D9: 7 | E9: Steel Raven (IRE) | F9: 1.3730685 | G9: 1.3730685 | H9: Steel Raven (IRE) | I9: 1.3730685 | J9: =IF(E9=H9,"yes","no") -> yes | K9: =IF(AND(ISNUMBER(F9),ISNUMBER(G9)),F9/G9-1,"") -> 0
A10: 2:55 | B10: Cork | C10: Irish Stallion Farms EBF Fillies Handicap | D10: 9 | E10: By The Lake (IRE) | F10: 4.7378235 | G10: 4.7378235 | H10: By The Lake (IRE) | I10: 4.7378235 | J10: =IF(E10=H10,"yes","no") -> yes | K10: =IF(AND(ISNUMBER(F10),ISNUMBER(G10)),F10/G10-1,"") -> 0
A11: 3:02 | B11: Bath | C11: AEL Solutions Handicap | D11: 12 | E11: Buckland Belle | F11: 3.2266287 | G11: 3.2266287 | H11: Buckland Belle | I11: 3.2266287 | J11: =IF(E11=H11,"yes","no") -> yes | K11: =IF(AND(ISNUMBER(F11),ISNUMBER(G11)),F11/G11-1,"") -> 0
A12: 3:08 | B12: Ayr | C12: Nairnss Oatcakes Handicap (GBBPlus Race) | D12: 9 | E12: Star Cast | F12: 5.2588233 | G12: 5.2588233 | H12: Star Cast | I12: 5.2588233 | J12: =IF(E12=H12,"yes","no") -> yes | K12: =IF(AND(ISNUMBER(F12),ISNUMBER(G12)),F12/G12-1,"") -> 0
A13: 3:15 | B13: Sedgefield | C13: Paxtons No1 CaseIH Dealer Handicap Chase (GBB Race) | D13: 4 | E13: Passengerontheship (IRE) | F13: 2.5505 | G13: 2.5505 | H13: Passengerontheship (IRE) | I13: 2.5505 | J13: =IF(E13=H13,"yes","no") -> yes | K13: =IF(AND(ISNUMBER(F13),ISNUMBER(G13)),F13/G13-1,"") -> 0
... A39: 8:30 | B39: Wolverhampton | C39: Sky Sports Racing Sky 415 Handicap (Div 2) | D39: 8 | E39: African Spirit (IRE) | F39: 2.6247749 | G39: 3.3404251 | H39: African Spirit (IRE) | I39: 3.3404251 | J39: =IF(E39=H39,"yes","no") -> yes | K39: =IF(AND(ISNUMBER(F39),ISNUMBER(G39)),F39/G39-1,"") -> -0.21423926
A41: Races with the same top pick | E41: =COUNTIF(J2:J39,"yes")&" of "&COUNTA(J2:J39) -> 38 of 38

Sheet All runners
A1: Time | B1: Course | C1: Race | D1: Class | E1: Furlongs | F1: Going | G1: Runners | H1: Horse | I1: Jockey | J1: Trainer | K1: Draw | L1: OR | M1: Age | N1: Days since run | O1: Model rank | P1: Predicted BSP | Q1: Win probability | R1: Card odds (HRB) | S1: Card odds vs model | T1: Rule: back at Betfair ≥
A2: 1:55 | B2: Cork | C2: Irish Stallion Farms EBF Maiden | E2: 5 | F2: Yielding | G2: 13 | H2: Bold Commander (IRE) | I2: Lordan, W M | J2: OBrien, A P | K2: 4 | L2: 78 | M2: 2 | N2: 12 | O2: 1 | P2: 4.6201822 | Q2: 0.21644168 | R2: 2.5 | S2: =IF(AND(ISNUMBER(R2),R2>1,P2>0),R2/P2-1,"") -> -0.45889579 | T2: =IF(AND(ISNUMBER(P2),P2>0),P2*EXP('Read me'!$B$22),"") -> 5.6431032
A3: 1:55 | B3: Cork | C3: Irish Stallion Farms EBF Maiden | E3: 5 | F3: Yielding | G3: 13 | H3: Sonny Hayes (IRE) | I3: OConnor, Donagh | J3: Aguiar, Robson | K3: 7 | L3: 0 | M3: 2 | O3: 2 | P3: 5.1099387 | Q3: 0.19569706 | R3: 6 | S3: =IF(AND(ISNUMBER(R3),R3>1,P3>0),R3/P3-1,"") -> 0.17418239 | T3: =IF(AND(ISNUMBER(P3),P3>0),P3*EXP('Read me'!$B$22),"") -> 6.2412932
A4: 1:55 | B4: Cork | C4: Irish Stallion Farms EBF Maiden | E4: 5 | F4: Yielding | G4: 13 | H4: El Domino | I4: Slattery, A J | J4: Slattery, Andrew | K4: 9 | L4: 75 | M4: 2 | N4: 20 | O4: 3 | P4: 6.8919554 | Q4: 0.1450967 | R4: 5.5 | S4: =IF(AND(ISNUMBER(R4),R4>1,P4>0),R4/P4-1,"") -> -0.20196814 | T4: =IF(AND(ISNUMBER(P4),P4>0),P4*EXP('Read me'!$B$22),"") -> 8.4178533
A5: 1:55 | B5: Cork | C5: Irish Stallion Farms EBF Maiden | E5: 5 | F5: Yielding | G5: 13 | H5: Alfresco (IRE) | I5: Ryan, Gavin | J5: Obrien, Donnacha | K5: 5 | L5: 0 | M5: 2 | N5: 12 | O5: 4 | P5: 8.3317733 | Q5: 0.12002247 | R5: 7 | S5: =IF(AND(ISNUMBER(R5),R5>1,P5>0),R5/P5-1,"") -> -0.15984272 | T5: =IF(AND(ISNUMBER(P5),P5>0),P5*EXP('Read me'!$B$22),"") -> 10.176451
A6: 1:55 | B6: Cork | C6: Irish Stallion Farms EBF Maiden | E6: 5 | F6: Yielding | G6: 13 | H6: Anthony Of Lisbon | I6: Frain, Freya | J6: OBrien, A P | K6: 12 | L6: 0 | M6: 2 | N6: 109 | O6: 5 | P6: 9.9724355 | Q6: 0.10027641 | R6: 7 | S6: =IF(AND(ISNUMBER(R6),R6>1,P6>0),R6/P6-1,"") -> -0.29806515 | T6: =IF(AND(ISNUMBER(P6),P6>0),P6*EXP('Read me'!$B$22),"") -> 12.18036
A7: 1:55 | B7: Cork | C7: Irish Stallion Farms EBF Maiden | E7: 5 | F7: Yielding | G7: 13 | H7: Sapphire Sun (IRE) | J7: Murtagh, J P | K7: 3 | L7: 0 | M7: 2 | N7: 16 | O7: 6 | P7: 10.852561 | Q7: 0.092144149 | R7: 4 | S7: =IF(AND(ISNUMBER(R7),R7>1,P7>0),R7/P7-1,"") -> -0.6314234 | T7: =IF(AND(ISNUMBER(P7),P7>0),P7*EXP('Read me'!$B$22),"") -> 13.255348
A8: 1:55 | B8: Cork | C8: Irish Stallion Farms EBF Maiden | E8: 5 | F8: Yielding | G8: 13 | H8: Lion Of Fortune (IRE) | I8: Whelan, R P | J8: Cotter, Kieran P | K8: 8 | L8: 0 | M8: 2 | N8: 44 | O8: 7 | P8: 16.182722 | Q8: 0.061794301 | R8: 12 | S8: =IF(AND(ISNUMBER(R8),R8>1,P8>0),R8/P8-1,"") -> -0.25846838 | T8: =IF(AND(ISNUMBER(P8),P8>0),P8*EXP('Read me'!$B$22),"") -> 19.765621
A9: 1:55 | B9: Cork | C9: Irish Stallion Farms EBF Maiden | E9: 5 | F9: Yielding | G9: 13 | H9: Spirit Of The Nite (IRE) | I9: Ryan, J J G | J9: McCourt, T G | K9: 11 | L9: 0 | M9: 2 | N9: 11 | O9: 8 | P9: 30.375508 | Q9: 0.032921261 | R9: 11 | S9: =IF(AND(ISNUMBER(R9),R9>1,P9>0),R9/P9-1,"") -> -0.63786613 | T9: =IF(AND(ISNUMBER(P9),P9>0),P9*EXP('Read me'!$B$22),"") -> 37.100729
A10: 1:55 | B10: Cork | C10: Irish Stallion Farms EBF Maiden | E10: 5 | F10: Yielding | G10: 13 | H10: Sorrento Sunset (IRE) | I10: Powell, J A | J10: McLoughlin, Daniel | K10: 6 | L10: 0 | M10: 2 | N10: 25 | O10: 9 | P10: 58.116284 | Q10: 0.017206881 | R10: 51 | S10: =IF(AND(ISNUMBER(R10),R10>1,P10>0),R10/P10-1,"") -> -0.12244906 | T10: =IF(AND(ISNUMBER(P10),P10>0),P10*EXP('Read me'!$B$22),"") -> 70.98339
A11: 1:55 | B11: Cork | C11: Irish Stallion Farms EBF Maiden | E11: 5 | F11: Yielding | G11: 13 | H11: Lolapipa (IRE) | I11: Persse, A C | J11: Cahill, Mark | K11: 1 | L11: 0 | M11: 2 | O11: 10 | P11: 99.062393 | Q11: 0.010094648 | R11: 151 | S11: =IF(AND(ISNUMBER(R11),R11>1,P11>0),R11/P11-1,"") -> 0.52429187 | T11: =IF(AND(ISNUMBER(P11),P11>0),P11*EXP('Read me'!$B$22),"") -> 120.99508
A12: 1:55 | B12: Cork | C12: Irish Stallion Farms EBF Maiden | E12: 5 | F12: Yielding | G12: 13 | H12: Habu (IRE) | I12: Tynan, Orla | J12: Tynan, M J | K12: 2 | L12: 0 | M12: 2 | N12: 12 | O12: 11 | P12: 334.04285 | Q12: 0.0029936279 | R12: 81 | S12: =IF(AND(ISNUMBER(R12),R12>1,P12>0),R12/P12-1,"") -> -0.75751614 | T12: =IF(AND(ISNUMBER(P12),P12>0),P12*EXP('Read me'!$B$22),"") -> 408.00086
A13: 1:55 | B13: Cork | C13: Irish Stallion Farms EBF Maiden | E13: 5 | F13: Yielding | G13: 13 | H13: Imply (IRE) | I13: Mulligan, R M | J13: Weld, Charles | K13: 10 | L13: 0 | M13: 2 | N13: 12 | O13: 12 | P13: 361.67997 | Q13: 0.0027648752 | R13: 151 | S13: =IF(AND(ISNUMBER(R13),R13>1,P13>0),R13/P13-1,"") -> -0.58250384 | T13: =IF(AND(ISNUMBER(P13),P13>0),P13*EXP('Read me'!$B$22),"") -> 441.75692
A14: 1:55 | B14: Cork | C14: Irish Stallion Farms EBF Maiden | E14: 5 | F14: Yielding | G14: 13 | H14: Bettercalltheboss (IRE) | I14: Cleary, R P | J14: Lynch, Miss Jennifer Anne | K14: 13 | L14: 0 | M14: 2 | N14: 69 | O14: 13 | P14: 392.78351 | Q14: 0.0025459318 | R14: 151 | S14: =IF(AND(ISNUMBER(R14),R14>1,P14>0),R14/P14-1,"") -> -0.61556431 | T14: =IF(AND(ISNUMBER(P14),P14>0),P14*EXP('Read me'!$B$22),"") -> 479.74686
A15: 2:02 | B15: Bath | C15: JDL Consultants Ltd Apprentice Handicap | D15: Class 5 | E15: 10 | F15: Good To Firm | G15: 11 | H15: Decalogue (USA) | I15: Paetel, Mason | J15: Osborne, J A | K15: 1 | L15: 73 | M15: 3 | N15: 15 | O15: 1 | P15: 5.5561386 | Q15: 0.17998111 | R15: 4.5 | S15: =IF(AND(ISNUMBER(R15),R15>1,P15>0),R15/P15-1,"") -> -0.190085 | T15: =IF(AND(ISNUMBER(P15),P15>0),P15*EXP('Read me'!$B$22),"") -> 6.786283
A16: 2:02 | B16: Bath | C16: JDL Consultants Ltd Apprentice Handicap | D16: Class 5 | E16: 10 | F16: Good To Firm | G16: 11 | H16: Pangbourne | I16: Haines, Olivia | J16: Teal, R A | K16: 3 | L16: 56 | M16: 3 | N16: 13 | O16: 2 | P16: 6.4064338 | Q16: 0.15609308 | R16: 6 | S16: =IF(AND(ISNUMBER(R16),R16>1,P16>0),R16/P16-1,"") -> -0.063441498 | T16: =IF(AND(ISNUMBER(P16),P16>0),P16*EXP('Read me'!$B$22),"") -> 7.8248359
A17: 2:02 | B17: Bath | C17: JDL Consultants Ltd Apprentice Handicap | D17: Class 5 | E17: 10 | F17: Good To Firm | G17: 11 | H17: Shady Bay (IRE) | I17: Lewis, Ashley | J17: Ward, Tom | K17: 4 | L17: 74 | M17: 5 | N17: 32 | O17: 3 | P17: 6.6128169 | Q17: 0.15122149 | R17: 4 | S17: =IF(AND(ISNUMBER(R17),R17>1,P17>0),R17/P17-1,"") -> -0.39511406 | T17: =IF(AND(ISNUMBER(P17),P17>0),P17*EXP('Read me'!$B$22),"") -> 8.0769128
A18: 2:02 | B18: Bath | C18: JDL Consultants Ltd Apprentice Handicap | D18: Class 5 | E18: 10 | F18: Good To Firm | G18: 11 | H18: Oman (IRE) | I18: Coppins, Myla | J18: Carroll, A W | K18: 2 | L18: 68 | M18: 8 | N18: 18 | O18: 4 | P18: 10.638227 | Q18: 0.094000622 | R18: 7.5 | S18: =IF(AND(ISNUMBER(R18),R18>1,P18>0),R18/P18-1,"") -> -0.29499533 | T18: =IF(AND(ISNUMBER(P18),P18>0),P18*EXP('Read me'!$B$22),"") -> 12.99356
A19: 2:02 | B19: Bath | C19: JDL Consultants Ltd Apprentice Handicap | D19: Class 5 | E19: 10 | F19: Good To Firm | G19: 11 | H19: Dryburgh (IRE) | I19: Catton, Luke | J19: Rix, Oli | K19: 6 | L19: 75 | M19: 3 | N19: 52 | O19: 5 | P19: 11.172339 | Q19: 0.089506772 | R19: 8 | S19: =IF(AND(ISNUMBER(R19),R19>1,P19>0),R19/P19-1,"") -> -0.28394583 | T19: =IF(AND(ISNUMBER(P19),P19>0),P19*EXP('Read me'!$B$22),"") -> 13.645926
A20: 2:02 | B20: Bath | C20: JDL Consultants Ltd Apprentice Handicap | D20: Class 5 | E20: 10 | F20: Good To Firm | G20: 11 | H20: Captain Fox (IRE) | I20: Murphy, D J | J20: Hughes, Richard | K20: 11 | L20: 72 | M20: 3 | N20: 17 | O20: 6 | P20: 12.059594 | Q20: 0.082921534 | R20: 8.5 | S20: =IF(AND(ISNUMBER(R20),R20>1,P20>0),R20/P20-1,"") -> -0.29516696 | T20: =IF(AND(ISNUMBER(P20),P20>0),P20*EXP('Read me'!$B$22),"") -> 14.729621
A21: 2:02 | B21: Bath | C21: JDL Consultants Ltd Apprentice Handicap | D21: Class 5 | E21: 10 | F21: Good To Firm | G21: 11 | H21: Its Life | J21: Turner, Kathy | K21: 5 | L21: 56 | M21: 4 | N21: 36 | O21: 7 | P21: 13.008317 | Q21: 0.076873894 | R21: 13 | S21: =IF(AND(ISNUMBER(R21),R21>1,P21>0),R21/P21-1,"") -> -0.0006393754 | T21: =IF(AND(ISNUMBER(P21),P21>0),P21*EXP('Read me'!$B$22),"") -> 15.888395
A22: 2:02 | B22: Bath | C22: JDL Consultants Ltd Apprentice Handicap | D22: Class 5 | E22: 10 | F22: Good To Firm | G22: 11 | H22: Pomme Pomme (IRE) | I22: Dace, Jack | J22: Channon, Jack | K22: 7 | L22: 72 | M22: 4 | N22: 26 | O22: 8 | P22: 14.159192 | Q22: 0.070625499 | R22: 13 | S22: =IF(AND(ISNUMBER(R22),R22>1,P22>0),R22/P22-1,"") -> -0.081868507 | T22: =IF(AND(ISNUMBER(P22),P22>0),P22*EXP('Read me'!$B$22),"") -> 17.294076
A23: 2:02 | B23: Bath | C23: JDL Consultants Ltd Apprentice Handicap | D23: Class 5 | E23: 10 | F23: Good To Firm | G23: 11 | H23: Gallant Pioneer (IRE) | I23: Vigors, Harry | J23: Pike, Charlie | K23: 8 | L23: 64 | M23: 3 | N23: 43 | O23: 9 | P23: 18.845741 | Q23: 0.053062388 | R23: 17 | S23: =IF(AND(ISNUMBER(R23),R23>1,P23>0),R23/P23-1,"") -> -0.09793941 | T23: =IF(AND(ISNUMBER(P23),P23>0),P23*EXP('Read me'!$B$22),"") -> 23.01824
A24: 2:02 | B24: Bath | C24: JDL Consultants Ltd Apprentice Handicap | D24: Class 5 | E24: 10 | F24: Good To Firm | G24: 11 | H24: Rascallion (FR) | I24: Langley, Taryn | J24: Knight, Miss H C | K24: 10 | L24: 70 | M24: 7 | N24: 508 | O24: 10 | P24: 43.218903 | Q24: 0.023138024 | R24: 26 | S24: =IF(AND(ISNUMBER(R24),R24>1,P24>0),R24/P24-1,"") -> -0.39841139 | T24: =IF(AND(ISNUMBER(P24),P24>0),P24*EXP('Read me'!$B$22),"") -> 52.787687
A25: 2:02 | B25: Bath | C25: JDL Consultants Ltd Apprentice Handicap | D25: Class 5 | E25: 10 | F25: Good To Firm | G25: 11 | H25: Arcadian Nights | I25: Regan, Hope | J25: Loughnane, Daniel Mark | K25: 9 | L25: 72 | M25: 8 | N25: 26 | O25: 11 | P25: 44.295637 | Q25: 0.022575587 | R25: 51 | S25: =IF(AND(ISNUMBER(R25),R25>1,P25>0),R25/P25-1,"") -> 0.15135492 | T25: =IF(AND(ISNUMBER(P25),P25>0),P25*EXP('Read me'!$B$22),"") -> 54.102814
A26: 2:08 | B26: Ayr | C26: Christmas Party Day Dancing At Ayr Racecourse Apprentice Handicap | D26: Class 5 | E26: 8 | F26: Heavy | G26: 8 | H26: Empirestateofmind (IRE) | I26: Callan, Jack | J26: Quinn, J J | K26: 2 | L26: 71 | M26: 8 | N26: 9 | O26: 1 | P26: 3.2135037 | Q26: 0.31118682 | R26: 2.75 | S26: =IF(AND(ISNUMBER(R26),R26>1,P26>0),R26/P26-1,"") -> -0.14423624 | T26: =IF(AND(ISNUMBER(P26),P26>0),P26*EXP('Read me'!$B$22),"") -> 3.9249823
A27: 2:08 | B27: Ayr | C27: Christmas Party Day Dancing At Ayr Racecourse Apprentice Handicap | D27: Class 5 | E27: 8 | F27: Heavy | G27: 8 | H27: Motawaared | I27: Young, Lauren | J27: Goldie, J S | K27: 3 | L27: 60 | M27: 4 | N27: 9 | O27: 2 | P27: 5.1649624 | Q27: 0.19361225 | R27: 3.75 | S27: =IF(AND(ISNUMBER(R27),R27>1,P27>0),R27/P27-1,"") -> -0.27395405 | T27: =IF(AND(ISNUMBER(P27),P27>0),P27*EXP('Read me'!$B$22),"") -> 6.3084993
A28: 2:08 | B28: Ayr | C28: Christmas Party Day Dancing At Ayr Racecourse Apprentice Handicap | D28: Class 5 | E28: 8 | F28: Heavy | G28: 8 | H28: Penelopes Sister (IRE) | I28: Farmer, Shay | J28: Goldie, J S | K28: 6 | L28: 57 | M28: 6 | N28: 11 | O28: 3 | P28: 7.8295143 | Q28: 0.12772184 | R28: 5 | S28: =IF(AND(ISNUMBER(R28),R28>1,P28>0),R28/P28-1,"") -> -0.36139078 | T28: =IF(AND(ISNUMBER(P28),P28>0),P28*EXP('Read me'!$B$22),"") -> 9.5629903
A29: 2:08 | B29: Ayr | C29: Christmas Party Day Dancing At Ayr Racecourse Apprentice Handicap | D29: Class 5 | E29: 8 | F29: Heavy | G29: 8 | H29: Leopards Rock | I29: Horgan, C | J29: Bethell, Ed | K29: 8 | L29: 72 | M29: 3 | N29: 20 | O29: 4 | P29: 9.9009327 | Q29: 0.10100059 | R29: 7.5 | S29: =IF(AND(ISNUMBER(R29),R29>1,P29>0),R29/P29-1,"") -> -0.24249561 | T29: =IF(AND(ISNUMBER(P29),P29>0),P29*EXP('Read me'!$B$22),"") -> 12.093026
A30: 2:08 | B30: Ayr | C30: Christmas Party Day Dancing At Ayr Racecourse Apprentice Handicap | D30: Class 5 | E30: 8 | F30: Heavy | G30: 8 | H30: Kindest Nation (IRE) | I30: Nicholls, Jack | J30: Palmer, Hugo | K30: 5 | L30: 69 | M30: 5 | N30: 17 | O30: 5 | P30: 11.509629 | Q30: 0.086883773 | R30: 26 | S30: =IF(AND(ISNUMBER(R30),R30>1,P30>0),R30/P30-1,"") -> 1.2589781 | T30: =IF(AND(ISNUMBER(P30),P30>0),P30*EXP('Read me'!$B$22),"") -> 14.057893
A31: 2:08 | B31: Ayr | C31: Christmas Party Day Dancing At Ayr Racecourse Apprentice Handicap | D31: Class 5 | E31: 8 | F31: Heavy | G31: 8 | H31: Swift Salian (IRE) | I31: Pyle, William | J31: Barron, T D | K31: 1 | L31: 72 | M31: 5 | N31: 20 | O31: 6 | P31: 12.682362 | Q31: 0.078849665 | R31: 13 | S31: =IF(AND(ISNUMBER(R31),R31>1,P31>0),R31/P31-1,"") -> 0.02504565 | T31: =IF(AND(ISNUMBER(P31),P31>0),P31*EXP('Read me'!$B$22),"") -> 15.490272
A32: 2:08 | B32: Ayr | C32: Christmas Party Day Dancing At Ayr Racecourse Apprentice Handicap | D32: Class 5 | E32: 8 | F32: Heavy | G32: 8 | H32: Runninsonofagun (IRE) | I32: Jary, Alex | J32: Davidson, Tristan | K32: 4 | L32: 70 | M32: 4 | N32: 12 | O32: 7 | P32: 13.851606 | Q32: 0.072193794 | R32: 19 | S32: =IF(AND(ISNUMBER(R32),R32>1,P32>0),R32/P32-1,"") -> 0.3716821 | T32: =IF(AND(ISNUMBER(P32),P32>0),P32*EXP('Read me'!$B$22),"") -> 16.91839
A33: 2:08 | B33: Ayr | C33: Christmas Party Day Dancing At Ayr Racecourse Apprentice Handicap | D33: Class 5 | E33: 8 | F33: Heavy | G33: 8 | H33: Arkenstaar | I33: Elliott, Rhys | J33: Dods, M | K33: 7 | L33: 69 | M33: 6 | N33: 20 | O33: 8 | P33: 35.024721 | Q33: 0.028551262 | R33: 23 | S33: =IF(AND(ISNUMBER(R33),R33>1,P33>0),R33/P33-1,"") -> -0.34332097 | T33: =IF(AND(ISNUMBER(P33),P33>0),P33*EXP('Read me'!$B$22),"") -> 42.779291
... A40: 2:15 | B40: Sedgefield | C40: Happy 96th Birthday John Conditional Jockeys Handicap Hurdle | D40: Class 5 | E40: 16.5 | F40: Good | G40: 7 | H40: Mr Globalist (IRE) | I40: Noreci, Leah | J40: Quinlan, Elizabeth | K40: 7 | L40: 79 | M40: 7 | N40: 15 | O40: 7 | P40: 20.530267 | Q40: 0.048708573 | R40: 21 | S40: =IF(AND(ISNUMBER(R40),R40>1,P40>0),R40/P40-1,"") -> 0.022880042 | T40: =IF(AND(ISNUMBER(P40),P40>0),P40*EXP('Read me'!$B$22),"") -> 25.075724
A41: 2:25 | B41: Cork | C41: Irish Stallion Farms EBF Nursery Handicap (Birdcatcher Series) | E41: 6 | F41: Yielding | G41: 7 | H41: Pink Venom (IRE) | I41: Coen, Ben M | J41: Murtagh, J P | K41: 5 | L41: 76 | M41: 2 | N41: 8 | O41: 1 | P41: 2.9968914 | Q41: 0.33367909 | R41: 2 | S41: =IF(AND(ISNUMBER(R41),R41>1,P41>0),R41/P41-1,"") -> -0.33264182 | T41: =IF(AND(ISNUMBER(P41),P41>0),P41*EXP('Read me'!$B$22),"") -> 3.6604114
A42: 2:25 | B42: Cork | C42: Irish Stallion Farms EBF Nursery Handicap (Birdcatcher Series) | E42: 6 | F42: Yielding | G42: 7 | H42: Fine Line (IRE) | J42: Hogan, Denis Gerard | K42: 6 | L42: 79 | M42: 2 | N42: 2 | O42: 2 | P42: 5.8739402 | Q42: 0.17024348 | R42: 9.5 | S42: =IF(AND(ISNUMBER(R42),R42>1,P42>0),R42/P42-1,"") -> 0.61731302 | T42: =IF(AND(ISNUMBER(P42),P42>0),P42*EXP('Read me'!$B$22),"") -> 7.1744468
A43: 2:25 | B43: Cork | C43: Irish Stallion Farms EBF Nursery Handicap (Birdcatcher Series) | E43: 6 | F43: Yielding | G43: 7 | H43: Howlin Wolf (IRE) | I43: Ryan, J J G | J43: Davison, Jack W | K43: 4 | L43: 75 | M43: 2 | N43: 24 | O43: 3 | P43: 7.1324058 | Q43: 0.14020515 | R43: 6 | S43: =IF(AND(ISNUMBER(R43),R43>1,P43>0),R43/P43-1,"") -> -0.15876912 | T43: =IF(AND(ISNUMBER(P43),P43>0),P43*EXP('Read me'!$B$22),"") -> 8.7115401
A44: 2:25 | B44: Cork | C44: Irish Stallion Farms EBF Nursery Handicap (Birdcatcher Series) | E44: 6 | F44: Yielding | G44: 7 | H44: Captain James Cook | I44: Lordan, W M | J44: OBrien, A P | K44: 7 | L44: 63 | M44: 2 | N44: 8 | O44: 4 | P44: 8.4926245 | Q44: 0.11774923 | R44: 5.5 | S44: =IF(AND(ISNUMBER(R44),R44>1,P44>0),R44/P44-1,"") -> -0.35237923 | T44: =IF(AND(ISNUMBER(P44),P44>0),P44*EXP('Read me'!$B$22),"") -> 10.372915
A45: 2:25 | B45: Cork | C45: Irish Stallion Farms EBF Nursery Handicap (Birdcatcher Series) | E45: 6 | F45: Yielding | G45: 7 | H45: Best Love (IRE) | I45: McDonogh, D P | J45: Harty, Edward and Patrick | K45: 3 | L45: 75 | M45: 2 | N45: 27 | O45: 5 | P45: 10.211733 | Q45: 0.097926567 | R45: 12 | S45: =IF(AND(ISNUMBER(R45),R45>1,P45>0),R45/P45-1,"") -> 0.1751188 | T45: =IF(AND(ISNUMBER(P45),P45>0),P45*EXP('Read me'!$B$22),"") -> 12.472639
A46: 2:25 | B46: Cork | C46: Irish Stallion Farms EBF Nursery Handicap (Birdcatcher Series) | E46: 6 | F46: Yielding | G46: 7 | H46: Whosinterviewinwho (IRE) | I46: Coen, S | J46: Slattery, Andrew | K46: 1 | L46: 79 | M46: 2 | N46: 25 | O46: 6 | P46: 10.700093 | Q46: 0.093457129 | R46: 6 | S46: =IF(AND(ISNUMBER(R46),R46>1,P46>0),R46/P46-1,"") -> -0.43925723 | T46: =IF(AND(ISNUMBER(P46),P46>0),P46*EXP('Read me'!$B$22),"") -> 13.069123
...

Sheet Cork
A1: Time | B1: Course | C1: Race | D1: Class | E1: Furlongs | F1: Going | G1: Runners | H1: Horse | I1: Jockey | J1: Trainer | K1: Draw | L1: OR | M1: Age | N1: Days since run | O1: Model rank | P1: Predicted BSP | Q1: Win probability | R1: Card odds (HRB) | S1: Card odds vs model | T1: Rule: back at Betfair ≥
A2: 1:55 | B2: Cork | C2: Irish Stallion Farms EBF Maiden | E2: 5 | F2: Yielding | G2: 13 | H2: Bold Commander (IRE) | I2: Lordan, W M | J2: OBrien, A P | K2: 4 | L2: 78 | M2: 2 | N2: 12 | O2: 1 | P2: 4.6201822 | Q2: 0.21644168 | R2: 2.5 | S2: =IF(AND(ISNUMBER(R2),R2>1,P2>0),R2/P2-1,"") -> -0.45889579 | T2: =IF(AND(ISNUMBER(P2),P2>0),P2*EXP('Read me'!$B$22),"") -> 5.6431032
A3: 1:55 | B3: Cork | C3: Irish Stallion Farms EBF Maiden | E3: 5 | F3: Yielding | G3: 13 | H3: Sonny Hayes (IRE) | I3: OConnor, Donagh | J3: Aguiar, Robson | K3: 7 | L3: 0 | M3: 2 | O3: 2 | P3: 5.1099387 | Q3: 0.19569706 | R3: 6 | S3: =IF(AND(ISNUMBER(R3),R3>1,P3>0),R3/P3-1,"") -> 0.17418239 | T3: =IF(AND(ISNUMBER(P3),P3>0),P3*EXP('Read me'!$B$22),"") -> 6.2412932
A4: 1:55 | B4: Cork | C4: Irish Stallion Farms EBF Maiden | E4: 5 | F4: Yielding | G4: 13 | H4: El Domino | I4: Slattery, A J | J4: Slattery, Andrew | K4: 9 | L4: 75 | M4: 2 | N4: 20 | O4: 3 | P4: 6.8919554 | Q4: 0.1450967 | R4: 5.5 | S4: =IF(AND(ISNUMBER(R4),R4>1,P4>0),R4/P4-1,"") -> -0.20196814 | T4: =IF(AND(ISNUMBER(P4),P4>0),P4*EXP('Read me'!$B$22),"") -> 8.4178533
A5: 1:55 | B5: Cork | C5: Irish Stallion Farms EBF Maiden | E5: 5 | F5: Yielding | G5: 13 | H5: Alfresco (IRE) | I5: Ryan, Gavin | J5: Obrien, Donnacha | K5: 5 | L5: 0 | M5: 2 | N5: 12 | O5: 4 | P5: 8.3317733 | Q5: 0.12002247 | R5: 7 | S5: =IF(AND(ISNUMBER(R5),R5>1,P5>0),R5/P5-1,"") -> -0.15984272 | T5: =IF(AND(ISNUMBER(P5),P5>0),P5*EXP('Read me'!$B$22),"") -> 10.176451
A6: 1:55 | B6: Cork | C6: Irish Stallion Farms EBF Maiden | E6: 5 | F6: Yielding | G6: 13 | H6: Anthony Of Lisbon | I6: Frain, Freya | J6: OBrien, A P | K6: 12 | L6: 0 | M6: 2 | N6: 109 | O6: 5 | P6: 9.9724355 | Q6: 0.10027641 | R6: 7 | S6: =IF(AND(ISNUMBER(R6),R6>1,P6>0),R6/P6-1,"") -> -0.29806515 | T6: =IF(AND(ISNUMBER(P6),P6>0),P6*EXP('Read me'!$B$22),"") -> 12.18036
A7: 1:55 | B7: Cork | C7: Irish Stallion Farms EBF Maiden | E7: 5 | F7: Yielding | G7: 13 | H7: Sapphire Sun (IRE) | J7: Murtagh, J P | K7: 3 | L7: 0 | M7: 2 | N7: 16 | O7: 6 | P7: 10.852561 | Q7: 0.092144149 | R7: 4 | S7: =IF(AND(ISNUMBER(R7),R7>1,P7>0),R7/P7-1,"") -> -0.6314234 | T7: =IF(AND(ISNUMBER(P7),P7>0),P7*EXP('Read me'!$B$22),"") -> 13.255348
A8: 1:55 | B8: Cork | C8: Irish Stallion Farms EBF Maiden | E8: 5 | F8: Yielding | G8: 13 | H8: Lion Of Fortune (IRE) | I8: Whelan, R P | J8: Cotter, Kieran P | K8: 8 | L8: 0 | M8: 2 | N8: 44 | O8: 7 | P8: 16.182722 | Q8: 0.061794301 | R8: 12 | S8: =IF(AND(ISNUMBER(R8),R8>1,P8>0),R8/P8-1,"") -> -0.25846838 | T8: =IF(AND(ISNUMBER(P8),P8>0),P8*EXP('Read me'!$B$22),"") -> 19.765621
A9: 1:55 | B9: Cork | C9: Irish Stallion Farms EBF Maiden | E9: 5 | F9: Yielding | G9: 13 | H9: Spirit Of The Nite (IRE) | I9: Ryan, J J G | J9: McCourt, T G | K9: 11 | L9: 0 | M9: 2 | N9: 11 | O9: 8 | P9: 30.375508 | Q9: 0.032921261 | R9: 11 | S9: =IF(AND(ISNUMBER(R9),R9>1,P9>0),R9/P9-1,"") -> -0.63786613 | T9: =IF(AND(ISNUMBER(P9),P9>0),P9*EXP('Read me'!$B$22),"") -> 37.100729
A10: 1:55 | B10: Cork | C10: Irish Stallion Farms EBF Maiden | E10: 5 | F10: Yielding | G10: 13 | H10: Sorrento Sunset (IRE) | I10: Powell, J A | J10: McLoughlin, Daniel | K10: 6 | L10: 0 | M10: 2 | N10: 25 | O10: 9 | P10: 58.116284 | Q10: 0.017206881 | R10: 51 | S10: =IF(AND(ISNUMBER(R10),R10>1,P10>0),R10/P10-1,"") -> -0.12244906 | T10: =IF(AND(ISNUMBER(P10),P10>0),P10*EXP('Read me'!$B$22),"") -> 70.98339
A11: 1:55 | B11: Cork | C11: Irish Stallion Farms EBF Maiden | E11: 5 | F11: Yielding | G11: 13 | H11: Lolapipa (IRE) | I11: Persse, A C | J11: Cahill, Mark | K11: 1 | L11: 0 | M11: 2 | O11: 10 | P11: 99.062393 | Q11: 0.010094648 | R11: 151 | S11: =IF(AND(ISNUMBER(R11),R11>1,P11>0),R11/P11-1,"") -> 0.52429187 | T11: =IF(AND(ISNUMBER(P11),P11>0),P11*EXP('Read me'!$B$22),"") -> 120.99508
A12: 1:55 | B12: Cork | C12: Irish Stallion Farms EBF Maiden | E12: 5 | F12: Yielding | G12: 13 | H12: Habu (IRE) | I12: Tynan, Orla | J12: Tynan, M J | K12: 2 | L12: 0 | M12: 2 | N12: 12 | O12: 11 | P12: 334.04285 | Q12: 0.0029936279 | R12: 81 | S12: =IF(AND(ISNUMBER(R12),R12>1,P12>0),R12/P12-1,"") -> -0.75751614 | T12: =IF(AND(ISNUMBER(P12),P12>0),P12*EXP('Read me'!$B$22),"") -> 408.00086
A13: 1:55 | B13: Cork | C13: Irish Stallion Farms EBF Maiden | E13: 5 | F13: Yielding | G13: 13 | H13: Imply (IRE) | I13: Mulligan, R M | J13: Weld, Charles | K13: 10 | L13: 0 | M13: 2 | N13: 12 | O13: 12 | P13: 361.67997 | Q13: 0.0027648752 | R13: 151 | S13: =IF(AND(ISNUMBER(R13),R13>1,P13>0),R13/P13-1,"") -> -0.58250384 | T13: =IF(AND(ISNUMBER(P13),P13>0),P13*EXP('Read me'!$B$22),"") -> 441.75692
A14: 1:55 | B14: Cork | C14: Irish Stallion Farms EBF Maiden | E14: 5 | F14: Yielding | G14: 13 | H14: Bettercalltheboss (IRE) | I14: Cleary, R P | J14: Lynch, Miss Jennifer Anne | K14: 13 | L14: 0 | M14: 2 | N14: 69 | O14: 13 | P14: 392.78351 | Q14: 0.0025459318 | R14: 151 | S14: =IF(AND(ISNUMBER(R14),R14>1,P14>0),R14/P14-1,"") -> -0.61556431 | T14: =IF(AND(ISNUMBER(P14),P14>0),P14*EXP('Read me'!$B$22),"") -> 479.74686
A15: 2:25 | B15: Cork | C15: Irish Stallion Farms EBF Nursery Handicap (Birdcatcher Series) | E15: 6 | F15: Yielding | G15: 7 | H15: Pink Venom (IRE) | I15: Coen, Ben M | J15: Murtagh, J P | K15: 5 | L15: 76 | M15: 2 | N15: 8 | O15: 1 | P15: 2.9968914 | Q15: 0.33367909 | R15: 2 | S15: =IF(AND(ISNUMBER(R15),R15>1,P15>0),R15/P15-1,"") -> -0.33264182 | T15: =IF(AND(ISNUMBER(P15),P15>0),P15*EXP('Read me'!$B$22),"") -> 3.6604114
A16: 2:25 | B16: Cork | C16: Irish Stallion Farms EBF Nursery Handicap (Birdcatcher Series) | E16: 6 | F16: Yielding | G16: 7 | H16: Fine Line (IRE) | J16: Hogan, Denis Gerard | K16: 6 | L16: 79 | M16: 2 | N16: 2 | O16: 2 | P16: 5.8739402 | Q16: 0.17024348 | R16: 9.5 | S16: =IF(AND(ISNUMBER(R16),R16>1,P16>0),R16/P16-1,"") -> 0.61731302 | T16: =IF(AND(ISNUMBER(P16),P16>0),P16*EXP('Read me'!$B$22),"") -> 7.1744468
A17: 2:25 | B17: Cork | C17: Irish Stallion Farms EBF Nursery Handicap (Birdcatcher Series) | E17: 6 | F17: Yielding | G17: 7 | H17: Howlin Wolf (IRE) | I17: Ryan, J J G | J17: Davison, Jack W | K17: 4 | L17: 75 | M17: 2 | N17: 24 | O17: 3 | P17: 7.1324058 | Q17: 0.14020515 | R17: 6 | S17: =IF(AND(ISNUMBER(R17),R17>1,P17>0),R17/P17-1,"") -> -0.15876912 | T17: =IF(AND(ISNUMBER(P17),P17>0),P17*EXP('Read me'!$B$22),"") -> 8.7115401
A18: 2:25 | B18: Cork | C18: Irish Stallion Farms EBF Nursery Handicap (Birdcatcher Series) | E18: 6 | F18: Yielding | G18: 7 | H18: Captain James Cook | I18: Lordan, W M | J18: OBrien, A P | K18: 7 | L18: 63 | M18: 2 | N18: 8 | O18: 4 | P18: 8.4926245 | Q18: 0.11774923 | R18: 5.5 | S18: =IF(AND(ISNUMBER(R18),R18>1,P18>0),R18/P18-1,"") -> -0.35237923 | T18: =IF(AND(ISNUMBER(P18),P18>0),P18*EXP('Read me'!$B$22),"") -> 10.372915
A19: 2:25 | B19: Cork | C19: Irish Stallion Farms EBF Nursery Handicap (Birdcatcher Series) | E19: 6 | F19: Yielding | G19: 7 | H19: Best Love (IRE) | I19: McDonogh, D P | J19: Harty, Edward and Patrick | K19: 3 | L19: 75 | M19: 2 | N19: 27 | O19: 5 | P19: 10.211733 | Q19: 0.097926567 | R19: 12 | S19: =IF(AND(ISNUMBER(R19),R19>1,P19>0),R19/P19-1,"") -> 0.1751188 | T19: =IF(AND(ISNUMBER(P19),P19>0),P19*EXP('Read me'!$B$22),"") -> 12.472639
A20: 2:25 | B20: Cork | C20: Irish Stallion Farms EBF Nursery Handicap (Birdcatcher Series) | E20: 6 | F20: Yielding | G20: 7 | H20: Whosinterviewinwho (IRE) | I20: Coen, S | J20: Slattery, Andrew | K20: 1 | L20: 79 | M20: 2 | N20: 25 | O20: 6 | P20: 10.700093 | Q20: 0.093457129 | R20: 6 | S20: =IF(AND(ISNUMBER(R20),R20>1,P20>0),R20/P20-1,"") -> -0.43925723 | T20: =IF(AND(ISNUMBER(P20),P20>0),P20*EXP('Read me'!$B$22),"") -> 13.069123
A21: 2:25 | B21: Cork | C21: Irish Stallion Farms EBF Nursery Handicap (Birdcatcher Series) | E21: 6 | F21: Yielding | G21: 7 | H21: Cyclone Code (IRE) | I21: OConnor, Donagh | J21: Cavanagh, S | K21: 2 | L21: 77 | M21: 2 | N21: 12 | O21: 7 | P21: 21.395243 | Q21: 0.046739361 | R21: 17 | S21: =IF(AND(ISNUMBER(R21),R21>1,P21>0),R21/P21-1,"") -> -0.20543087 | T21: =IF(AND(ISNUMBER(P21),P21>0),P21*EXP('Read me'!$B$22),"") -> 26.132209
A22: 2:55 | B22: Cork | C22: Irish Stallion Farms EBF Fillies Handicap | E22: 6 | F22: Yielding | G22: 9 | H22: By The Lake (IRE) | I22: Keane, C T | J22: McCormack, Derek | K22: 6 | L22: 79 | M22: 3 | N22: 33 | O22: 1 | P22: 4.7378235 | Q22: 0.21106738 | R22: 7.5 | S22: =IF(AND(ISNUMBER(R22),R22>1,P22>0),R22/P22-1,"") -> 0.58300535 | T22: =IF(AND(ISNUMBER(P22),P22>0),P22*EXP('Read me'!$B$22),"") -> 5.7867907
A23: 2:55 | B23: Cork | C23: Irish Stallion Farms EBF Fillies Handicap | E23: 6 | F23: Yielding | G23: 9 | H23: Forza Magico | I23: Whelan, R P | J23: Feane, John James | K23: 5 | L23: 70 | M23: 3 | N23: 25 | O23: 2 | P23: 6.5293068 | Q23: 0.15315562 | R23: 5 | S23: =IF(AND(ISNUMBER(R23),R23>1,P23>0),R23/P23-1,"") -> -0.23422192 | T23: =IF(AND(ISNUMBER(P23),P23>0),P23*EXP('Read me'!$B$22),"") -> 7.9749133
A24: 2:55 | B24: Cork | C24: Irish Stallion Farms EBF Fillies Handicap | E24: 6 | F24: Yielding | G24: 9 | H24: Motta Alta (IRE) | I24: McCullagh, Scott | J24: Harrington, Mrs John | K24: 9 | L24: 77 | M24: 3 | N24: 14 | O24: 3 | P24: 8.7498092 | Q24: 0.11428821 | R24: 5 | S24: =IF(AND(ISNUMBER(R24),R24>1,P24>0),R24/P24-1,"") -> -0.42855897 | T24: =IF(AND(ISNUMBER(P24),P24>0),P24*EXP('Read me'!$B$22),"") -> 10.687041
A25: 2:55 | B25: Cork | C25: Irish Stallion Farms EBF Fillies Handicap | E25: 6 | F25: Yielding | G25: 9 | H25: Baiana (GER) | I25: Sheridan, J M | J25: OBrien, Joseph Patrick | K25: 2 | L25: 71 | M25: 3 | N25: 124 | O25: 4 | P25: 9.3177277 | Q25: 0.1073223 | R25: 11 | S25: =IF(AND(ISNUMBER(R25),R25>1,P25>0),R25/P25-1,"") -> 0.18054534 | T25: =IF(AND(ISNUMBER(P25),P25>0),P25*EXP('Read me'!$B$22),"") -> 11.380698
A26: 2:55 | B26: Cork | C26: Irish Stallion Farms EBF Fillies Handicap | E26: 6 | F26: Yielding | G26: 9 | H26: Staysound Susie (IRE) | I26: Dalton, J S | J26: Slattery, Andrew | K26: 3 | L26: 84 | M26: 5 | N26: 16 | O26: 5 | P26: 9.7754413 | Q26: 0.10229717 | R26: 4.5 | S26: =IF(AND(ISNUMBER(R26),R26>1,P26>0),R26/P26-1,"") -> -0.53966272 | T26: =IF(AND(ISNUMBER(P26),P26>0),P26*EXP('Read me'!$B$22),"") -> 11.939751
A27: 2:55 | B27: Cork | C27: Irish Stallion Farms EBF Fillies Handicap | E27: 6 | F27: Yielding | G27: 9 | H27: Rosato (IRE) | I27: Mulligan, R M | J27: Weld, Charles | K27: 1 | L27: 58 | M27: 5 | N27: 24 | O27: 6 | P27: 10.038118 | Q27: 0.099620266 | R27: 7.5 | S27: =IF(AND(ISNUMBER(R27),R27>1,P27>0),R27/P27-1,"") -> -0.25284801 | T27: =IF(AND(ISNUMBER(P27),P27>0),P27*EXP('Read me'!$B$22),"") -> 12.260585
A28: 2:55 | B28: Cork | C28: Irish Stallion Farms EBF Fillies Handicap | E28: 6 | F28: Yielding | G28: 9 | H28: Flash Of Fire | I28: Coen, Ben M | J28: Murtagh, J P | K28: 8 | L28: 79 | M28: 3 | N28: 14 | O28: 7 | P28: 11.929759 | Q28: 0.083823991 | R28: 8.5 | S28: =IF(AND(ISNUMBER(R28),R28>1,P28>0),R28/P28-1,"") -> -0.28749607 | T28: =IF(AND(ISNUMBER(P28),P28>0),P28*EXP('Read me'!$B$22),"") -> 14.57104
... A53: 3:55 | B53: Cork | C53: Irish Stallion Farms EBF Navigation Stakes (Listed) | E53: 10.5 | F53: Yielding | G53: 12 | H53: Shaihaan (IRE) | I53: Hayes, C D | J53: Obrien, Donnacha | K53: 6 | L53: 102 | M53: 3 | N53: 61 | O53: 4 | P53: 9.5513545 | Q53: 0.10469719 | R53: 6.5 | S53: =IF(AND(ISNUMBER(R53),R53>1,P53>0),R53/P53-1,"") -> -0.31946825 | T53: =IF(AND(ISNUMBER(P53),P53>0),P53*EXP('Read me'!$B$22),"") -> 11.666051
A54: 3:55 | B54: Cork | C54: Irish Stallion Farms EBF Navigation Stakes (Listed) | E54: 10.5 | F54: Yielding | G54: 12 | H54: Magnum Cor (IRE) | J54: OBrien, Joseph Patrick | K54: 8 | L54: 95 | M54: 3 | N54: 42 | O54: 5 | P54: 10.84934 | Q54: 0.092171509 | R54: 10 | S54: =IF(AND(ISNUMBER(R54),R54>1,P54>0),R54/P54-1,"") -> -0.078284912 | T54: =IF(AND(ISNUMBER(P54),P54>0),P54*EXP('Read me'!$B$22),"") -> 13.251413
A55: 3:55 | B55: Cork | C55: Irish Stallion Farms EBF Navigation Stakes (Listed) | E55: 10.5 | F55: Yielding | G55: 12 | H55: Latin America (IRE) | I55: Coen, Ben M | J55: Murtagh, J P | K55: 1 | L55: 95 | M55: 3 | N55: 135 | O55: 6 | P55: 12.351965 | Q55: 0.080958776 | R55: 9.5 | S55: =IF(AND(ISNUMBER(R55),R55>1,P55>0),R55/P55-1,"") -> -0.23089163 | T55: =IF(AND(ISNUMBER(P55),P55>0),P55*EXP('Read me'!$B$22),"") -> 15.086725
A56: 3:55 | B56: Cork | C56: Irish Stallion Farms EBF Navigation Stakes (Listed) | E56: 10.5 | F56: Yielding | G56: 12 | H56: Back Straight | I56: Heffernan, J A | J56: OCallaghan, M D | K56: 4 | L56: 88 | M56: 3 | N56: 14 | O56: 7 | P56: 14.034531 | Q56: 0.071252829 | R56: 21 | S56: =IF(AND(ISNUMBER(R56),R56>1,P56>0),R56/P56-1,"") -> 0.4963094 | T56: =IF(AND(ISNUMBER(P56),P56>0),P56*EXP('Read me'!$B$22),"") -> 17.141814
A57: 3:55 | B57: Cork | C57: Irish Stallion Farms EBF Navigation Stakes (Listed) | E57: 10.5 | F57: Yielding | G57: 12 | H57: Action (IRE) | I57: Lordan, W M | J57: OBrien, A P | K57: 12 | L57: 109 | M57: 3 | N57: 17 | O57: 8 | P57: 17.176746 | Q57: 0.058218243 | R57: 3.25 | S57: =IF(AND(ISNUMBER(R57),R57>1,P57>0),R57/P57-1,"") -> -0.81079071 | T57: =IF(AND(ISNUMBER(P57),P57>0),P57*EXP('Read me'!$B$22),"") -> 20.979725
A58: 3:55 | B58: Cork | C58: Irish Stallion Farms EBF Navigation Stakes (Listed) | E58: 10.5 | F58: Yielding | G58: 12 | H58: Alphecca (IRE) | I58: Carroll, G F | J58: Murphy, Joseph G | K58: 2 | L58: 91 | M58: 3 | N58: 8 | O58: 9 | P58: 30.859873 | Q58: 0.03240454 | R58: 26 | S58: =IF(AND(ISNUMBER(R58),R58>1,P58>0),R58/P58-1,"") -> -0.15748195 | T58: =IF(AND(ISNUMBER(P58),P58>0),P58*EXP('Read me'!$B$22),"") -> 37.692334
A59: 3:55 | B59: Cork | C59: Irish Stallion Farms EBF Navigation Stakes (Listed) | E59: 10.5 | F59: Yielding | G59: 12 | H59: Garden Party (IRE) | I59: Whelan, R P | J59: OBrien, A P | K59: 5 | L59: 85 | M59: 3 | N59: 31 | O59: 10 | P59: 33.593562 | Q59: 0.029767609 | R59: 41 | S59: =IF(AND(ISNUMBER(R59),R59>1,P59>0),R59/P59-1,"") -> 0.22047196 | T59: =IF(AND(ISNUMBER(P59),P59>0),P59*EXP('Read me'!$B$22),"") -> 41.031269
A60: 3:55 | B60: Cork | C60: Irish Stallion Farms EBF Navigation Stakes (Listed) | E60: 10.5 | F60: Yielding | G60: 12 | H60: Mr Vettori (IRE) | I60: McCullagh, Scott | J60: Harrington, Mrs John | K60: 3 | L60: 98 | M60: 3 | N60: 60 | O60: 11 | P60: 42.757596 | Q60: 0.023387657 | R60: 41 | S60: =IF(AND(ISNUMBER(R60),R60>1,P60>0),R60/P60-1,"") -> -0.041106045 | T60: =IF(AND(ISNUMBER(P60),P60>0),P60*EXP('Read me'!$B$22),"") -> 52.224245
A61: 3:55 | B61: Cork | C61: Irish Stallion Farms EBF Navigation Stakes (Listed) | E61: 10.5 | F61: Yielding | G61: 12 | H61: Fallacy (USA) | I61: Slattery, A J | J61: Slattery, Andrew | K61: 11 | L61: 84 | M61: 3 | N61: 109 | O61: 12 | P61: 64.827228 | Q61: 0.015425617 | R61: 26 | S61: =IF(AND(ISNUMBER(R61),R61>1,P61>0),R61/P61-1,"") -> -0.59893395 | T61: =IF(AND(ISNUMBER(P61),P61>0),P61*EXP('Read me'!$B$22),"") -> 79.180155
A62: 4:25 | B62: Cork | C62: Irish EBF Fillies Maiden (Smullen Series) | E62: 8 | F62: Yielding | G62: 14 | H62: Golden Ring (IRE) | I62: Lordan, W M | J62: OBrien, A P | K62: 12 | L62: 0 | M62: 2 | N62: 20 | O62: 1 | P62: 4.1816566 | Q62: 0.23913967 | R62: 2.2 | S62: =IF(AND(ISNUMBER(R62),R62>1,P62>0),R62/P62-1,"") -> -0.47389272 | T62: =IF(AND(ISNUMBER(P62),P62>0),P62*EXP('Read me'!$B$22),"") -> 5.107487
A63: 4:25 | B63: Cork | C63: Irish EBF Fillies Maiden (Smullen Series) | E63: 8 | F63: Yielding | G63: 14 | H63: Duchessofaquitaine (IRE) | I63: Lee, W J | J63: Twomey, P | K63: 8 | L63: 0 | M63: 2 | O63: 2 | P63: 4.3883636 | Q63: 0.22787537 | R63: 5 | S63: =IF(AND(ISNUMBER(R63),R63>1,P63>0),R63/P63-1,"") -> 0.13937687 | T63: =IF(AND(ISNUMBER(P63),P63>0),P63*EXP('Read me'!$B$22),"") -> 5.3599594
A64: 4:25 | B64: Cork | C64: Irish EBF Fillies Maiden (Smullen Series) | E64: 8 | F64: Yielding | G64: 14 | H64: Gods Love | I64: Keane, C T | J64: Lyons, G M | K64: 2 | L64: 0 | M64: 2 | O64: 3 | P64: 7.193698 | Q64: 0.13901056 | R64: 6 | S64: =IF(AND(ISNUMBER(R64),R64>1,P64>0),R64/P64-1,"") -> -0.16593663 | T64: =IF(AND(ISNUMBER(P64),P64>0),P64*EXP('Read me'!$B$22),"") -> 8.7864026
...

Sheet Bath
A1: Time | B1: Course | C1: Race | D1: Class | E1: Furlongs | F1: Going | G1: Runners | H1: Horse | I1: Jockey | J1: Trainer | K1: Draw | L1: OR | M1: Age | N1: Days since run | O1: Model rank | P1: Predicted BSP | Q1: Win probability | R1: Card odds (HRB) | S1: Card odds vs model | T1: Rule: back at Betfair ≥
A2: 2:02 | B2: Bath | C2: JDL Consultants Ltd Apprentice Handicap | D2: Class 5 | E2: 10 | F2: Good To Firm | G2: 11 | H2: Decalogue (USA) | I2: Paetel, Mason | J2: Osborne, J A | K2: 1 | L2: 73 | M2: 3 | N2: 15 | O2: 1 | P2: 5.5561386 | Q2: 0.17998111 | R2: 4.5 | S2: =IF(AND(ISNUMBER(R2),R2>1,P2>0),R2/P2-1,"") -> -0.190085 | T2: =IF(AND(ISNUMBER(P2),P2>0),P2*EXP('Read me'!$B$22),"") -> 6.786283
A3: 2:02 | B3: Bath | C3: JDL Consultants Ltd Apprentice Handicap | D3: Class 5 | E3: 10 | F3: Good To Firm | G3: 11 | H3: Pangbourne | I3: Haines, Olivia | J3: Teal, R A | K3: 3 | L3: 56 | M3: 3 | N3: 13 | O3: 2 | P3: 6.4064338 | Q3: 0.15609308 | R3: 6 | S3: =IF(AND(ISNUMBER(R3),R3>1,P3>0),R3/P3-1,"") -> -0.063441498 | T3: =IF(AND(ISNUMBER(P3),P3>0),P3*EXP('Read me'!$B$22),"") -> 7.8248359
A4: 2:02 | B4: Bath | C4: JDL Consultants Ltd Apprentice Handicap | D4: Class 5 | E4: 10 | F4: Good To Firm | G4: 11 | H4: Shady Bay (IRE) | I4: Lewis, Ashley | J4: Ward, Tom | K4: 4 | L4: 74 | M4: 5 | N4: 32 | O4: 3 | P4: 6.6128169 | Q4: 0.15122149 | R4: 4 | S4: =IF(AND(ISNUMBER(R4),R4>1,P4>0),R4/P4-1,"") -> -0.39511406 | T4: =IF(AND(ISNUMBER(P4),P4>0),P4*EXP('Read me'!$B$22),"") -> 8.0769128
A5: 2:02 | B5: Bath | C5: JDL Consultants Ltd Apprentice Handicap | D5: Class 5 | E5: 10 | F5: Good To Firm | G5: 11 | H5: Oman (IRE) | I5: Coppins, Myla | J5: Carroll, A W | K5: 2 | L5: 68 | M5: 8 | N5: 18 | O5: 4 | P5: 10.638227 | Q5: 0.094000622 | R5: 7.5 | S5: =IF(AND(ISNUMBER(R5),R5>1,P5>0),R5/P5-1,"") -> -0.29499533 | T5: =IF(AND(ISNUMBER(P5),P5>0),P5*EXP('Read me'!$B$22),"") -> 12.99356
A6: 2:02 | B6: Bath | C6: JDL Consultants Ltd Apprentice Handicap | D6: Class 5 | E6: 10 | F6: Good To Firm | G6: 11 | H6: Dryburgh (IRE) | I6: Catton, Luke | J6: Rix, Oli | K6: 6 | L6: 75 | M6: 3 | N6: 52 | O6: 5 | P6: 11.172339 | Q6: 0.089506772 | R6: 8 | S6: =IF(AND(ISNUMBER(R6),R6>1,P6>0),R6/P6-1,"") -> -0.28394583 | T6: =IF(AND(ISNUMBER(P6),P6>0),P6*EXP('Read me'!$B$22),"") -> 13.645926
A7: 2:02 | B7: Bath | C7: JDL Consultants Ltd Apprentice Handicap | D7: Class 5 | E7: 10 | F7: Good To Firm | G7: 11 | H7: Captain Fox (IRE) | I7: Murphy, D J | J7: Hughes, Richard | K7: 11 | L7: 72 | M7: 3 | N7: 17 | O7: 6 | P7: 12.059594 | Q7: 0.082921534 | R7: 8.5 | S7: =IF(AND(ISNUMBER(R7),R7>1,P7>0),R7/P7-1,"") -> -0.29516696 | T7: =IF(AND(ISNUMBER(P7),P7>0),P7*EXP('Read me'!$B$22),"") -> 14.729621
A8: 2:02 | B8: Bath | C8: JDL Consultants Ltd Apprentice Handicap | D8: Class 5 | E8: 10 | F8: Good To Firm | G8: 11 | H8: Its Life | J8: Turner, Kathy | K8: 5 | L8: 56 | M8: 4 | N8: 36 | O8: 7 | P8: 13.008317 | Q8: 0.076873894 | R8: 13 | S8: =IF(AND(ISNUMBER(R8),R8>1,P8>0),R8/P8-1,"") -> -0.0006393754 | T8: =IF(AND(ISNUMBER(P8),P8>0),P8*EXP('Read me'!$B$22),"") -> 15.888395
A9: 2:02 | B9: Bath | C9: JDL Consultants Ltd Apprentice Handicap | D9: Class 5 | E9: 10 | F9: Good To Firm | G9: 11 | H9: Pomme Pomme (IRE) | I9: Dace, Jack | J9: Channon, Jack | K9: 7 | L9: 72 | M9: 4 | N9: 26 | O9: 8 | P9: 14.159192 | Q9: 0.070625499 | R9: 13 | S9: =IF(AND(ISNUMBER(R9),R9>1,P9>0),R9/P9-1,"") -> -0.081868507 | T9: =IF(AND(ISNUMBER(P9),P9>0),P9*EXP('Read me'!$B$22),"") -> 17.294076
A10: 2:02 | B10: Bath | C10: JDL Consultants Ltd Apprentice Handicap | D10: Class 5 | E10: 10 | F10: Good To Firm | G10: 11 | H10: Gallant Pioneer (IRE) | I10: Vigors, Harry | J10: Pike, Charlie | K10: 8 | L10: 64 | M10: 3 | N10: 43 | O10: 9 | P10: 18.845741 | Q10: 0.053062388 | R10: 17 | S10: =IF(AND(ISNUMBER(R10),R10>1,P10>0),R10/P10-1,"") -> -0.09793941 | T10: =IF(AND(ISNUMBER(P10),P10>0),P10*EXP('Read me'!$B$22),"") -> 23.01824
A11: 2:02 | B11: Bath | C11: JDL Consultants Ltd Apprentice Handicap | D11: Class 5 | E11: 10 | F11: Good To Firm | G11: 11 | H11: Rascallion (FR) | I11: Langley, Taryn | J11: Knight, Miss H C | K11: 10 | L11: 70 | M11: 7 | N11: 508 | O11: 10 | P11: 43.218903 | Q11: 0.023138024 | R11: 26 | S11: =IF(AND(ISNUMBER(R11),R11>1,P11>0),R11/P11-1,"") -> -0.39841139 | T11: =IF(AND(ISNUMBER(P11),P11>0),P11*EXP('Read me'!$B$22),"") -> 52.787687
A12: 2:02 | B12: Bath | C12: JDL Consultants Ltd Apprentice Handicap | D12: Class 5 | E12: 10 | F12: Good To Firm | G12: 11 | H12: Arcadian Nights | I12: Regan, Hope | J12: Loughnane, Daniel Mark | K12: 9 | L12: 72 | M12: 8 | N12: 26 | O12: 11 | P12: 44.295637 | Q12: 0.022575587 | R12: 51 | S12: =IF(AND(ISNUMBER(R12),R12>1,P12>0),R12/P12-1,"") -> 0.15135492 | T12: =IF(AND(ISNUMBER(P12),P12>0),P12*EXP('Read me'!$B$22),"") -> 54.102814
A13: 2:32 | B13: Bath | C13: MJ Church Handicap | D13: Class 5 | E13: 13 | F13: Good To Firm | G13: 13 | H13: Cosmo Brown (IRE) | I13: Edmunds, Lewis | J13: Muir, W R & Grassick, C | K13: 13 | L13: 69 | M13: 3 | N13: 34 | O13: 1 | P13: 6.0547482 | Q13: 0.16515963 | R13: 6 | S13: =IF(AND(ISNUMBER(R13),R13>1,P13>0),R13/P13-1,"") -> -0.0090421993 | T13: =IF(AND(ISNUMBER(P13),P13>0),P13*EXP('Read me'!$B$22),"") -> 7.3952862
A14: 2:32 | B14: Bath | C14: MJ Church Handicap | D14: Class 5 | E14: 13 | F14: Good To Firm | G14: 13 | H14: Zarco | I14: Cosgrave, Pat | J14: Eustace, Harry | K14: 14 | L14: 67 | M14: 3 | N14: 17 | O14: 2 | P14: 7.0423239 | Q14: 0.14199858 | R14: 6.5 | S14: =IF(AND(ISNUMBER(R14),R14>1,P14>0),R14/P14-1,"") -> -0.07700923 | T14: =IF(AND(ISNUMBER(P14),P14>0),P14*EXP('Read me'!$B$22),"") -> 8.6015139
A15: 2:32 | B15: Bath | C15: MJ Church Handicap | D15: Class 5 | E15: 13 | F15: Good To Firm | G15: 13 | H15: Moab (IRE) | I15: Marquand, Tom | J15: Knight, Miss H C | K15: 6 | L15: 62 | M15: 6 | N15: 23 | O15: 3 | P15: 7.2670325 | Q15: 0.13760775 | R15: 7 | S15: =IF(AND(ISNUMBER(R15),R15>1,P15>0),R15/P15-1,"") -> -0.036745743 | T15: =IF(AND(ISNUMBER(P15),P15>0),P15*EXP('Read me'!$B$22),"") -> 8.8759735
A16: 2:32 | B16: Bath | C16: MJ Church Handicap | D16: Class 5 | E16: 13 | F16: Good To Firm | G16: 13 | H16: Society Girl | I16: Shoemark, Kieran | J16: Walker, Ed | K16: 1 | L16: 70 | M16: 3 | N16: 40 | O16: 4 | P16: 8.0548454 | Q16: 0.12414888 | R16: 7 | S16: =IF(AND(ISNUMBER(R16),R16>1,P16>0),R16/P16-1,"") -> -0.13095787 | T16: =IF(AND(ISNUMBER(P16),P16>0),P16*EXP('Read me'!$B$22),"") -> 9.8382104
A17: 2:32 | B17: Bath | C17: MJ Church Handicap | D17: Class 5 | E17: 13 | F17: Good To Firm | G17: 13 | H17: Percy Jones | I17: Fisher, Taylor | J17: Loughnane, Daniel Mark | K17: 10 | L17: 70 | M17: 7 | N17: 16 | O17: 5 | P17: 11.515531 | Q17: 0.086839244 | R17: 10 | S17: =IF(AND(ISNUMBER(R17),R17>1,P17>0),R17/P17-1,"") -> -0.13160756 | T17: =IF(AND(ISNUMBER(P17),P17>0),P17*EXP('Read me'!$B$22),"") -> 14.065101
A18: 2:32 | B18: Bath | C18: MJ Church Handicap | D18: Class 5 | E18: 13 | F18: Good To Firm | G18: 13 | H18: Two Plus Two (IRE) | I18: Ryan, Rossa | J18: De Giles, Ed | K18: 7 | L18: 59 | M18: 6 | N18: 16 | O18: 6 | P18: 12.208096 | Q18: 0.081912857 | R18: 8 | S18: =IF(AND(ISNUMBER(R18),R18>1,P18>0),R18/P18-1,"") -> -0.34469715 | T18: =IF(AND(ISNUMBER(P18),P18>0),P18*EXP('Read me'!$B$22),"") -> 14.911002
A19: 2:32 | B19: Bath | C19: MJ Church Handicap | D19: Class 5 | E19: 13 | F19: Good To Firm | G19: 13 | H19: Belle Of Kt | I19: Wonnacott, Millie | J19: Moore, J S | K19: 8 | L19: 68 | M19: 5 | N19: 16 | O19: 7 | P19: 13.011534 | Q19: 0.07685489 | R19: 10 | S19: =IF(AND(ISNUMBER(R19),R19>1,P19>0),R19/P19-1,"") -> -0.2314511 | T19: =IF(AND(ISNUMBER(P19),P19>0),P19*EXP('Read me'!$B$22),"") -> 15.892323
A20: 2:32 | B20: Bath | C20: MJ Church Handicap | D20: Class 5 | E20: 13 | F20: Good To Firm | G20: 13 | H20: Hebridean Nomad | I20: Tucker, Charlie | J20: Balding, A M | K20: 5 | L20: 67 | M20: 5 | N20: 17 | O20: 8 | P20: 13.019335 | Q20: 0.076808841 | R20: 7 | S20: =IF(AND(ISNUMBER(R20),R20>1,P20>0),R20/P20-1,"") -> -0.46233812 | T20: =IF(AND(ISNUMBER(P20),P20>0),P20*EXP('Read me'!$B$22),"") -> 15.901851
... A39: 3:32 | B39: Bath | C39: British EBF Future Stayers Novice Stakes (GBB/GBBPlus Race) | D39: Class 3 | E39: 8 | F39: Good To Firm | G39: 6 | H39: Al Qayed (IRE) | I39: Marquand, Tom | J39: Haggas, W J | K39: 3 | L39: 82 | M39: 2 | N39: 21 | O39: 2 | P39: 3.7044469 | Q39: 0.26994583 | R39: 5 | S39: =IF(AND(ISNUMBER(R39),R39>1,P39>0),R39/P39-1,"") -> 0.34972917 | T39: =IF(AND(ISNUMBER(P39),P39>0),P39*EXP('Read me'!$B$22),"") -> 4.5246216
A40: 3:32 | B40: Bath | C40: British EBF Future Stayers Novice Stakes (GBB/GBBPlus Race) | D40: Class 3 | E40: 8 | F40: Good To Firm | G40: 6 | H40: Political Resident | I40: Probert, David | J40: Balding, A M | K40: 4 | L40: 0 | M40: 2 | O40: 3 | P40: 11.938033 | Q40: 0.083765895 | R40: 11 | S40: =IF(AND(ISNUMBER(R40),R40>1,P40>0),R40/P40-1,"") -> -0.078575155 | T40: =IF(AND(ISNUMBER(P40),P40>0),P40*EXP('Read me'!$B$22),"") -> 14.581146
A41: 3:32 | B41: Bath | C41: British EBF Future Stayers Novice Stakes (GBB/GBBPlus Race) | D41: Class 3 | E41: 8 | F41: Good To Firm | G41: 6 | H41: Next Best | I41: Bishop, Charles | J41: Houghton, Eve Johnson | K41: 6 | L41: 0 | M41: 2 | O41: 4 | P41: 19.001702 | Q41: 0.052626864 | R41: 21 | S41: =IF(AND(ISNUMBER(R41),R41>1,P41>0),R41/P41-1,"") -> 0.10516413 | T41: =IF(AND(ISNUMBER(P41),P41>0),P41*EXP('Read me'!$B$22),"") -> 23.208732
A42: 3:32 | B42: Bath | C42: British EBF Future Stayers Novice Stakes (GBB/GBBPlus Race) | D42: Class 3 | E42: 8 | F42: Good To Firm | G42: 6 | H42: First Class Lad | I42: Carson, William | J42: Evans, P D | K42: 5 | L42: 0 | M42: 2 | N42: 8 | O42: 5 | P42: 329.74691 | Q42: 0.0030326289 | R42: 101 | S42: =IF(AND(ISNUMBER(R42),R42>1,P42>0),R42/P42-1,"") -> -0.69370448 | T42: =IF(AND(ISNUMBER(P42),P42>0),P42*EXP('Read me'!$B$22),"") -> 402.75379
A43: 3:32 | B43: Bath | C43: British EBF Future Stayers Novice Stakes (GBB/GBBPlus Race) | D43: Class 3 | E43: 8 | F43: Good To Firm | G43: 6 | H43: Dust My Broom | I43: ONeill, K T | J43: Attwater, M J | K43: 1 | L43: 0 | M43: 2 | N43: 40 | O43: 6 | P43: 579.32652 | Q43: 0.0017261423 | R43: 201 | S43: =IF(AND(ISNUMBER(R43),R43>1,P43>0),R43/P43-1,"") -> -0.6530454 | T43: =IF(AND(ISNUMBER(P43),P43>0),P43*EXP('Read me'!$B$22),"") -> 707.59101
A44: 4:02 | B44: Bath | C44: SW Hire Handicap | D44: Class 4 | E44: 5 | F44: Good To Firm | G44: 12 | H44: Maharajas Express | I44: Probert, David | J44: Williams, Ian | K44: 8 | L44: 72 | M44: 6 | N44: 16 | O44: 1 | P44: 4.95019 | Q44: 0.20201245 | R44: 5 | S44: =IF(AND(ISNUMBER(R44),R44>1,P44>0),R44/P44-1,"") -> 0.010062239 | T44: =IF(AND(ISNUMBER(P44),P44>0),P44*EXP('Read me'!$B$22),"") -> 6.0461757
A45: 4:02 | B45: Bath | C45: SW Hire Handicap | D45: Class 4 | E45: 5 | F45: Good To Firm | G45: 12 | H45: South Shore | I45: Marquand, Tom | J45: Cowell, R M H | K45: 2 | L45: 75 | M45: 5 | N45: 32 | O45: 2 | P45: 5.2990735 | Q45: 0.18871223 | R45: 4 | S45: =IF(AND(ISNUMBER(R45),R45>1,P45>0),R45/P45-1,"") -> -0.24515107 | T45: =IF(AND(ISNUMBER(P45),P45>0),P45*EXP('Read me'!$B$22),"") -> 6.472303
A46: 4:02 | B46: Bath | C46: SW Hire Handicap | D46: Class 4 | E46: 5 | F46: Good To Firm | G46: 12 | H46: Jax Edge | I46: Mangan, Gina | J46: Mason, Christopher | K46: 3 | L46: 77 | M46: 6 | N46: 21 | O46: 3 | P46: 7.0877236 | Q46: 0.14108902 | R46: 7 | S46: =IF(AND(ISNUMBER(R46),R46>1,P46>0),R46/P46-1,"") -> -0.012376836 | T46: =IF(AND(ISNUMBER(P46),P46>0),P46*EXP('Read me'!$B$22),"") -> 8.6569651
A47: 4:02 | B47: Bath | C47: SW Hire Handicap | D47: Class 4 | E47: 5 | F47: Good To Firm | G47: 12 | H47: Toolatetonegotiate | I47: Wonnacott, Millie | J47: Hitchins, Daisy | K47: 10 | L47: 79 | M47: 4 | N47: 26 | O47: 4 | P47: 11.578193 | Q47: 0.086369265 | R47: 9.5 | S47: =IF(AND(ISNUMBER(R47),R47>1,P47>0),R47/P47-1,"") -> -0.17949198 | T47: =IF(AND(ISNUMBER(P47),P47>0),P47*EXP('Read me'!$B$22),"") -> 14.141637
A48: 4:02 | B48: Bath | C48: SW Hire Handicap | D48: Class 4 | E48: 5 | F48: Good To Firm | G48: 12 | H48: Coyy (IRE) | I48: Bishop, Charles | J48: Houghton, Eve Johnson | K48: 4 | L48: 73 | M48: 3 | N48: 39 | O48: 5 | P48: 14.27969 | Q48: 0.070029533 | R48: 11 | S48: =IF(AND(ISNUMBER(R48),R48>1,P48>0),R48/P48-1,"") -> -0.22967514 | T48: =IF(AND(ISNUMBER(P48),P48>0),P48*EXP('Read me'!$B$22),"") -> 17.441252
A49: 4:02 | B49: Bath | C49: SW Hire Handicap | D49: Class 4 | E49: 5 | F49: Good To Firm | G49: 12 | H49: Alondra | I49: ONeill, K T | J49: Dixon, Scott | K49: 6 | L49: 76 | M49: 4 | N49: 88 | O49: 6 | P49: 18.198025 | Q49: 0.054951017 | R49: 10 | S49: =IF(AND(ISNUMBER(R49),R49>1,P49>0),R49/P49-1,"") -> -0.45048983 | T49: =IF(AND(ISNUMBER(P49),P49>0),P49*EXP('Read me'!$B$22),"") -> 22.227118
A50: 4:02 | B50: Bath | C50: SW Hire Handicap | D50: Class 4 | E50: 5 | F50: Good To Firm | G50: 12 | H50: Forager | I50: Mitchell, Jack | J50: Pearce, Simon | K50: 7 | L50: 77 | M50: 4 | N50: 26 | O50: 7 | P50: 19.221198 | Q50: 0.052025894 | R50: 17 | S50: =IF(AND(ISNUMBER(R50),R50>1,P50>0),R50/P50-1,"") -> -0.1155598 | T50: =IF(AND(ISNUMBER(P50),P50>0),P50*EXP('Read me'!$B$22),"") -> 23.476824
A51: 4:02 | B51: Bath | C51: SW Hire Handicap | D51: Class 4 | E51: 5 | F51: Good To Firm | G51: 12 | H51: Carefree Dream | I51: Lewis, Ashley | J51: Moore, J S | K51: 9 | L51: 67 | M51: 3 | N51: 52 | O51: 8 | P51: 20.148845 | Q51: 0.049630637 | R51: 19 | S51: =IF(AND(ISNUMBER(R51),R51>1,P51>0),R51/P51-1,"") -> -0.057017898 | T51: =IF(AND(ISNUMBER(P51),P51>0),P51*EXP('Read me'!$B$22),"") -> 24.609855
